File: Acrylic.csv
"Total Time (s)","Cycle Elapsed Time (s)","Total Cycles","Elapsed Cycles","Step","Total Cycle Count(8800 (0,3) Waveform)","Position(8800 (0,3):Position) (mm)","Load(8800 (0,3):Load) (kN)","Extension mm from Extensometer (mm)",
0,0,1,1,1,1,-0.000803913268446922,-0.0558018684387207,0.00118255623512268,
0.041,0.041,1,1,1,1,-0.000313389918208122,-0.0533223152160645,-0.000553131142234802,
0.072,0.072,1,1,1,1,0.000853873980045319,-0.0525712966918945,-0.00578880350580215,
0.104,0.104,1,1,1,1,0.000299764269590378,-0.0500380992889404,-0.00181913388588428,
0.147,0.147,1,1,1,1,0.000118088954687119,-0.0583350658416748,4.76837191581726E-06,
0.188,0.188,1,1,1,1,0.00193484210371971,-0.0586867332458496,-0.000486373935413361,
0.229,0.229,1,1,1,1,0.00266154336333275,-0.0497877597808838,-0.00329017662191391,
0.27,0.27,1,1,1,1,0.00817538917064667,-0.0459432601928711,0.00793933923983574,
0.311,0.311,1,1,1,1,0.0149427946507931,-0.0374853610992432,0.0062990193007946,
0.351,0.351,1,1,1,1,0.0218373728513718,-0.0255763530731201,0.0173091900544167,
0.392,0.392,1,1,1,1,0.0277327368199825,-0.0142991542816162,0.0140714655235767,
0.433,0.433,1,1,1,1,0.0342548806250095,-0.00510811805725098,0.0248336809375763,
0.473,0.473,1,1,1,1,0.0427391178309917,0.00860691070556641,0.0403356580358982,
0.514,0.514,1,1,1,1,0.0505239050745964,0.0159859657287598,0.0408220319713116,
0.554,0.554,1,1,1,1,0.0546206834256649,0.0191569328308105,0.0449466736784935,
0.595,0.595,1,1,1,1,0.0651578516900539,0.028693675994873,0.0453710587790012,
0.635,0.635,1,1,1,1,0.068727771627903,0.0452280044555664,0.0537109412597656,
0.675,0.675,1,1,1,1,0.0771120874106884,0.0533223152160645,0.0455808671432972,
0.716,0.716,1,1,1,1,0.0822625825881958,0.0608205795288086,0.0603199047350883,
0.756,0.756,1,1,1,1,0.0840884195029735,0.0624179840087891,0.0822782574074268,
0.796,0.796,1,1,1,1,0.0905560607135296,0.0655412673950195,0.0731658986763,
0.837,0.837,1,1,1,1,0.0979502460300922,0.0732779502868652,0.0685501146617889,
0.877,0.877,1,1,1,1,0.101202234166861,0.0766634941101074,0.0769424492336273,
0.917,0.917,1,1,1,1,0.103273332756758,0.0900626182556152,0.0835037289897919,
0.957,0.957,1,1,1,1,0.107878801989555,0.0902414321899414,0.0855493605416775,
0.998,0.998,1,1,1,1,0.111648564773798,0.0946521759033203,0.0838947354868889,
1.038,1.038,1,1,1,1,0.114037595164776,0.094306468963623,0.0996065209495068,
1.078,1.078,1,1,1,1,0.118379635190964,0.100982189178467,0.0779867226831913,
1.118,1.118,1,1,1,1,0.119969294196367,0.106704235076904,0.0969791480238914,
1.159,1.159,1,1,1,1,0.124147826439142,0.106847286224365,0.0954723424984932,
1.199,1.199,1,1,1,1,0.127990259349346,0.115799903869629,0.0943899220736027,
1.239,1.239,1,1,1,1,0.129134813833237,0.113821029663086,0.10140419716177,
1.279,1.279,1,1,1,1,0.13264114741087,0.120854377746582,0.105676658398342,
1.32,1.32,1,1,1,1,0.136065727096796,0.127673149108887,0.113019951148701,
1.36,1.36,1,1,1,1,0.139535725611448,0.134730339050293,0.11532307478404,
1.4,1.4,1,1,1,1,0.14353258253932,0.134992599487305,0.106482513252115,
1.441,1.441,1,1,1,1,0.148156219303608,0.132179260253906,0.114173897152328,
1.481,1.481,1,1,1,1,0.149555119228363,0.140488147735596,0.113158233934259,
1.521,1.521,1,1,1,1,0.152380170375109,0.142741203308105,0.120139130419016,
1.562,1.562,1,1,1,1,0.155014462441206,0.153648853302002,0.132927903897238,
1.602,1.602,1,1,1,1,0.159347418701649,0.153934955596924,0.113954552044201,
1.642,1.642,1,1,1,1,0.164034641826153,0.161576271057129,0.121669777803993,
1.683,1.683,1,1,1,1,0.165551630705595,0.161218643188477,0.128417024064875,
1.723,1.723,1,1,1,1,0.169566655164957,0.167500972747803,0.138068208822489,
1.763,1.763,1,1,1,1,0.173463590669632,0.166010856628418,0.129194268687153,
1.804,1.804,1,1,1,1,0.176361311942339,0.173318386077881,0.125527390683889,
1.844,1.844,1,1,1,1,0.179159111791849,0.178825855255127,0.142622004002094,
1.884,1.884,1,1,1,1,0.182765366792679,0.186443328857422,0.145373354597521,
1.925,1.925,1,1,1,1,0.186871228909492,0.190055370330811,0.14152051008954,
1.965,1.965,1,1,1,1,0.190359394955635,0.193488597869873,0.149602900486851,
2.007,2.007,1,1,1,1,0.192684838986397,0.197029113769531,0.149998675355864,
2.05,2.05,1,1,1,1,0.198407611405849,0.197970867156982,0.154089938459635,
2.092,2.092,1,1,1,1,0.201296248912811,0.212979316711426,0.154237757989025,
2.135,2.135,1,1,1,1,0.205011509102583,0.21359920501709,0.162744533486843,
2.178,2.178,1,1,1,1,0.210516271144152,0.218701362609863,0.164289485987568,
2.22,2.22,1,1,1,1,0.212214935338497,0.218844413757324,0.155644427704191,
2.263,2.263,1,1,1,1,0.216865823400021,0.223195552825928,0.164356243194389,
2.305,2.305,1,1,1,1,0.220817261499166,0.234758853912354,0.174818051177692,
2.348,2.348,1,1,1,1,0.225286474245787,0.241732597351074,0.175862324627256,
2.39,2.39,1,1,1,1,0.230736733692884,0.243473052978516,0.188117040450907,
2.433,2.433,1,1,1,1,0.234052308189869,0.249803066253662,0.187501920473766,
2.475,2.475,1,1,1,1,0.238739531314373,0.24799108505249,0.183491719692564,
2.518,2.518,1,1,1,1,0.242282199954987,0.26237964630127,0.193548216063023,
2.561,2.561,1,1,1,1,0.247578035384417,0.265955924987793,0.195536627151918,
2.603,2.603,1,1,1,1,0.252456017589569,0.272285938262939,0.19945622886672,
2.646,2.646,1,1,1,1,0.254926801872253,0.278890132904053,0.205097212843132,
2.688,2.688,1,1,1,1,0.259868370437622,0.285255908966064,0.202536597124338,
2.731,2.731,1,1,1,1,0.264074153977633,0.284767150878906,0.196838392684936,
2.773,2.773,1,1,1,1,0.268552450489998,0.293004512786865,0.214023605069542,
2.816,2.816,1,1,1,1,0.270932397115231,0.303959846496582,0.220894829000235,
2.858,2.858,1,1,1,1,0.279316712898016,0.304651260375977,0.214362159475565,
2.901,2.901,1,1,1,1,0.28175116211772,0.312685966491699,0.235972420998049,
2.944,2.944,1,1,1,1,0.285820689171553,0.320839881896973,0.229454056589127,
2.986,2.986,1,1,1,1,0.289072677308321,0.324022769927979,0.230684296543407,
3.029,3.029,1,1,1,1,0.296203433418274,0.326848030090332,0.232095734630489,
3.071,3.071,1,1,1,1,0.301517436379194,0.332677364349365,0.236916558637381,
3.114,3.114,1,1,1,1,0.304378822588921,0.338375568389893,0.250740068821335,
3.156,3.156,1,1,1,1,0.308430182111263,0.345838069915771,0.238232629286146,
3.199,3.199,1,1,1,1,0.314661645412445,0.345849990844727,0.239439027380848,
3.241,3.241,1,1,1,1,0.317341356307268,0.348377227783203,0.254220980319881,
3.284,3.284,1,1,1,1,0.323145882618427,0.360429286956787,0.244979875547028,
3.327,3.327,1,1,1,1,0.326325200629234,0.36623477935791,0.270428676461744,
3.369,3.369,1,1,1,1,0.332602082759142,0.373852252960205,0.253524798020172,
3.412,3.412,1,1,1,1,0.336090248805284,0.375330448150635,0.2637529557796,
3.454,3.454,1,1,1,1,0.341013649839163,0.381636619567871,0.270094890427637,
3.497,3.497,1,1,1,1,0.346345820331573,0.386476516723633,0.275902767421102,
3.539,3.539,1,1,1,1,0.348407835155725,0.399041175842285,0.277514477128649,
3.582,3.582,1,1,1,1,0.352595451164246,0.398218631744385,0.281162281644249,
3.624,3.624,1,1,1,1,0.359181181329489,0.404012203216553,0.289735814348888,
3.667,3.667,1,1,1,1,0.364031912237406,0.413012504577637,0.289611836679077,
3.71,3.71,1,1,1,1,0.366420942628384,0.411868095397949,0.300197622332191,
3.752,3.752,1,1,1,1,0.371189919644594,0.422775745391846,0.283846875032854,
3.795,3.795,1,1,1,1,0.375813556408882,0.430107116699219,0.300607702316952,
3.837,3.837,1,1,1,1,0.382826223564148,0.430202484130859,0.299325010271597,
3.88,3.88,1,1,1,1,0.38379818649888,0.436294078826904,0.302591345033932,
3.922,3.922,1,1,1,1,0.38849449338913,0.448822975158691,0.307765028562593,
3.965,3.965,1,1,1,1,0.392945538604259,0.448095798492432,0.314207099020863,
4.008,4.008,1,1,1,1,0.395034804725647,0.455200672149658,0.313916228333998,
4.052,4.052,1,1,1,1,0.401829461503029,0.463223457336426,0.319576285798073,
4.095,4.095,1,1,1,1,0.404908858090639,0.474917888641357,0.326843284597778,
4.137,4.137,1,1,1,1,0.410177442222834,0.472092628479004,0.319962523923254,
4.18,4.18,1,1,1,1,0.413729194629192,0.475990772247314,0.329489731011057,
4.222,4.222,1,1,1,1,0.419542804706097,0.474178791046143,0.332107567192841,
4.265,4.265,1,1,1,1,0.424720551180839,0.484621524810791,0.323228858685589,
4.307,4.307,1,1,1,1,0.426183037465811,0.48830509185791,0.341386818941021,
4.35,4.35,1,1,1,1,0.432469003361463,0.491487979888916,0.345811868078899,
4.392,4.392,1,1,1,1,0.436647535604239,0.502991676330566,0.338149094410181,
4.435,4.435,1,1,1,1,0.439390832859278,0.506222248077393,0.345478082044792,
4.478,4.478,1,1,1,1,0.444005385857821,0.511586666107178,0.354299570089054,
4.52,4.52,1,1,1,1,0.449364807647467,0.518012046813965,0.357723261124611,
4.563,4.563,1,1,1,1,0.453643261313438,0.520753860473633,0.359296823856831,
4.605,4.605,1,1,1,1,0.456886165684462,0.525450706481934,0.362243677700806,
4.648,4.648,1,1,1,1,0.461709645295143,0.529301166534424,0.369372393714952,
4.69,4.69,1,1,1,1,0.466187941807508,0.540351867675781,0.371794726648188,
4.733,4.733,1,1,1,1,0.471465609705448,0.544071197509766,0.364084269260311,
4.775,4.775,1,1,1,1,0.475898487389088,0.546419620513916,0.373692538670683,
4.818,4.818,1,1,1,1,0.479640998876095,0.55314302444458,0.377497699459505,
4.861,4.861,1,1,1,1,0.484609818738699,0.555336475372314,0.390186337127495,
4.903,4.903,1,1,1,1,0.489169869142771,0.562512874603271,0.388393429287147,
4.946,4.946,1,1,1,1,0.49303955335021,0.571739673614502,0.392303494258118,
4.988,4.988,1,1,1,1,0.496264290189743,0.572586059570313,0.390749005013561,
5.031,5.031,1,1,1,1,0.502695596337318,0.576794147491455,0.400176076291132,
5.073,5.073,1,1,1,1,0.505102794259787,0.586986541748047,0.402169255751944,
5.116,5.116,1,1,1,1,0.508808970683813,0.588428974151611,0.410804777291489,
5.158,5.158,1,1,1,1,0.516566506630182,0.594782829284668,0.407915143910503,
5.201,5.201,1,1,1,1,0.518356008481979,0.601541996002197,0.419564276500845,
5.244,5.244,1,1,1,1,0.525395926934481,0.606262683868408,0.410943060077047,
5.286,5.286,1,1,1,1,0.528838674151897,0.611627101898193,0.412573843272257,
5.329,5.329,1,1,1,1,0.534070923221111,0.620532035827637,0.413899450664854,
5.371,5.371,1,1,1,1,0.535497074443102,0.627040863037109,0.424542456780958,
5.414,5.414,1,1,1,1,0.541156260502338,0.629830360412598,0.432763129963827,
5.456,5.456,1,1,1,1,0.544480918765068,0.630199909210205,0.431895286275148,
5.499,5.499,1,1,1,1,0.548350602972507,0.632929801940918,0.434923202441692,
5.541,5.541,1,1,1,1,0.551875104081631,0.635850429534912,0.442037613340092,
5.584,5.584,1,1,1,1,0.556934761601686,0.647974014282227,0.458264382969618,
5.627,5.627,1,1,1,1,0.559850650405884,0.652492046356201,0.45428279241991,
5.669,5.669,1,1,1,1,0.565428082573414,0.655555725097656,0.445055992762804,
5.712,5.712,1,1,1,1,0.570923760849237,0.661289691925049,0.449991257695675,
5.754,5.754,1,1,1,1,0.57469352363348,0.666177272796631,0.462985071166277,
5.797,5.797,1,1,1,1,0.579753181153536,0.665533542633057,0.462141069337177,
5.839,5.839,1,1,1,1,0.58359561406374,0.672066211700439,0.468893083969974,
5.882,5.882,1,1,1,1,0.587183701533079,0.675606727600098,0.465946230125999,
5.924,5.924,1,1,1,1,0.590372103309631,0.682151317596436,0.466890367765331,
5.967,5.967,1,1,1,1,0.595104745262861,0.690197944641113,0.475497279073381,
6.01,6.01,1,1,1,1,0.598892675578594,0.696361064910889,0.473938021456909,
6.052,6.052,1,1,1,1,0.604470107746124,0.696253776550293,0.480976138404655,
6.095,6.095,1,1,1,1,0.60870314258337,0.7049560546875,0.483388934594059,
6.137,6.137,1,1,1,1,0.611228429460525,0.699400901794434,0.482144389524031,
6.18,6.18,1,1,1,1,0.615279788982868,0.715279579162598,0.48456195408535,
6.222,6.222,1,1,1,1,0.617941332346201,0.718355178833008,0.505256688199997,
6.265,6.265,1,1,1,1,0.625707952058315,0.723612308502197,0.495476757400656,
6.307,6.307,1,1,1,1,0.628660175925493,0.726377964019775,0.494008098850584,
6.35,6.35,1,1,1,1,0.632856875699758,0.73624849319458,0.50203803715682,
6.393,6.393,1,1,1,1,0.636771978735924,0.73779821395874,0.515875852456522,
6.435,6.435,1,1,1,1,0.642821766722202,0.74455738067627,0.513024366050863,
6.478,6.478,1,1,1,1,0.648235691106319,0.754642486572266,0.503063237118721,
6.52,6.52,1,1,1,1,0.65106982601881,0.749874114990234,0.513157880464506,
6.563,6.563,1,1,1,1,0.656547336763143,0.761818885803223,0.520739591810656,
6.605,6.605,1,1,1,1,0.660898460555077,0.764095783233643,0.527348555285978,
6.648,6.648,1,1,1,1,0.664332124006748,0.764906406402588,0.527148283665514,
6.69,6.69,1,1,1,1,0.66945536788702,0.772786140441895,0.529699362640476,
6.733,6.733,1,1,1,1,0.673116125482321,0.773632526397705,0.541863479397726,
6.776,6.776,1,1,1,1,0.677930521327257,0.78432559967041,0.53680900516696,
6.818,6.818,1,1,1,1,0.681327849715948,0.789380073547363,0.545487442053747,
6.861,6.861,1,1,1,1,0.685969654011726,0.79725980758667,0.549931564679289,
6.903,6.903,1,1,1,1,0.690184521317482,0.80258846282959,0.542469062631035,
6.946,6.946,1,1,1,1,0.694908079504967,0.80493688583374,0.552258530174208,
6.988,6.988,1,1,1,1,0.699686140286922,0.811207294464111,0.55685047232914,
7.031,7.031,1,1,1,1,0.703919175124168,0.819802284240723,0.558018723448515,
7.073,7.073,1,1,1,1,0.708451974231005,0.819170475006104,0.55121902509656,
7.116,7.116,1,1,1,1,0.711640376007557,0.821053981781006,0.567321817056274,
7.159,7.159,1,1,1,1,0.715310217368603,0.829088687896729,0.568585435613966,
7.201,7.201,1,1,1,1,0.719952021664381,0.835752487182617,0.572295228964472,
7.244,7.244,1,1,1,1,0.723903459763527,0.841701030731201,0.577068369252205,
7.286,7.286,1,1,1,1,0.728136494600773,0.849258899688721,0.579128305919838,
7.329,7.329,1,1,1,1,0.732732880067825,0.854825973510742,0.576591532060623,
7.371,7.371,1,1,1,1,0.739463950484991,0.849068164825439,0.581278841653871,
7.414,7.414,1,1,1,1,0.740908269238472,0.862967967987061,0.590934794783401,
7.456,7.456,1,1,1,1,0.74692172216177,0.857222080230713,0.581913035118675,
7.499,7.499,1,1,1,1,0.749546930462122,0.86665153503418,0.59891704937048,
7.542,7.542,1,1,1,1,0.753089599102736,0.867128372192383,0.611510319600153,
7.584,7.584,1,1,1,1,0.757695068335533,0.876784324645996,0.608615917847252,
7.627,7.627,1,1,1,1,0.76284556351304,0.881671905517578,0.601415676254368,
7.669,7.669,1,1,1,1,0.765643363362551,0.882840156555176,0.608820957839632,
7.712,7.712,1,1,1,1,0.7683684930861,0.890421867370605,0.610418362431431,
7.754,7.754,1,1,1,1,0.774345610946417,0.894820690155029,0.616827054286289,
7.797,7.797,1,1,1,1,0.780749665796757,0.895404815673828,0.621223493192673,
7.839,7.839,1,1,1,1,0.781803382623196,0.907158851623535,0.627617879931784,
7.882,7.882,1,1,1,1,0.78759882516861,0.908827781677246,0.627079053905296,
7.925,7.925,1,1,1,1,0.790641886693239,0.910329818725586,0.6366968600595,
7.967,7.967,1,1,1,1,0.796128481203318,0.922727584838867,0.627670332022858,
8.01,8.01,1,1,1,1,0.799080705070496,0.92003345489502,0.641331717561674,
8.054,8.054,1,1,1,1,0.802832300323248,0.925958156585693,0.63173775326705,
8.098,8.098,1,1,1,1,0.807019916331768,0.935769081115723,0.642986342616463,
8.142,8.142,1,1,1,1,0.810907768070698,0.930798053741455,0.64122204500761,
8.184,8.184,1,1,1,1,0.818383707278967,0.941729545593262,0.649585769347954,
8.228,8.228,1,1,1,1,0.819219413727522,0.948679447174072,0.658474014599037,
8.272,8.272,1,1,1,1,0.82495126991272,0.951433181762695,0.660729454515219,
8.315,8.315,1,1,1,1,0.830419696891308,0.960886478424072,0.651578948808765,
8.359,8.359,1,1,1,1,0.835661029726267,0.95832347869873,0.660524414522839,
8.402,8.402,1,1,1,1,0.841238461893797,0.970315933227539,0.660343216390037,
8.445,8.445,1,1,1,1,0.844826549363136,0.974547863006592,0.666194008730745,
8.489,8.489,1,1,1,1,0.850431232827902,0.976717472076416,0.683369684371519,
8.533,8.533,1,1,1,1,0.85421007937789,0.983107089996338,0.667767571462965,
8.575,8.575,1,1,1,1,0.85980567907691,0.989627838134766,0.678801584076166,
8.619,8.619,1,1,1,1,0.862267379593849,0.989222526550293,0.694017458859539,
8.663,8.663,1,1,1,1,0.86536494371295,0.999855995178223,0.6954527388062,
8.706,8.706,1,1,1,1,0.873494914054871,1.00029706954956,0.685505914989805,
8.75,8.75,1,1,1,1,0.876510724282265,1.00655555725098,0.69633011923871,
8.793,8.793,1,1,1,1,0.882088156449795,1.01149082183838,0.689191866480732,
8.836,8.836,1,1,1,1,0.885712578982115,1.01391077041626,0.69743638152318,
8.88,8.88,1,1,1,1,0.890490639764071,1.02496147155762,0.70213322786026,
8.924,8.924,1,1,1,1,0.894760009664297,1.02264881134033,0.716099789201689,
8.967,8.967,1,1,1,1,0.897612312108278,1.02847814559937,0.720582058802557,
9.011,9.011,1,1,1,1,0.902644718331098,1.02932453155518,0.711135914037323,
9.054,9.054,1,1,1,1,0.909575631594658,1.03995800018311,0.712413837710762,
9.097,9.097,1,1,1,1,0.912110002237558,1.04848146438599,0.722751668024254,
9.141,9.141,1,1,1,1,0.916597382515669,1.04894638061523,0.732803396022797,
9.184,9.184,1,1,1,1,0.91944968495965,1.05212926864624,0.731577924440431,
9.227,9.227,1,1,1,1,0.925335965162516,1.05754137039185,0.731163076083755,
9.271,9.271,1,1,1,1,0.929641670125723,1.0603666305542,0.738229803262997,
9.315,9.315,1,1,1,1,0.934664992582798,1.07041597366333,0.729765943112421,
9.358,9.358,1,1,1,1,0.93783522682786,1.0739803314209,0.740385107368946,
9.402,9.402,1,1,1,1,0.943121978491545,1.07994079589844,0.744161657926273,
9.445,9.445,1,1,1,1,0.947127919185162,1.08158588409424,0.748910956354427,
9.488,9.488,1,1,1,1,0.950588833934069,1.08671188354492,0.749220900528955,
9.532,9.532,1,1,1,1,0.955921004426479,1.08782052993774,0.761194282409572,
9.575,9.575,1,1,1,1,0.958582547789812,1.09813213348389,0.76360231022706,
9.619,9.619,1,1,1,1,0.962788331329822,1.09826326370239,0.749106459602976,
9.663,9.663,1,1,1,1,0.967847988849878,1.10524892807007,0.772709900586271,
9.706,9.706,1,1,1,1,0.973034819090366,1.11122131347656,0.774574334005356,
9.749,9.749,1,1,1,1,0.976922670829296,1.11290216445923,0.771431976912832,
9.793,9.793,1,1,1,1,0.979566046661139,1.11484527587891,0.770559364852238,
9.836,9.836,1,1,1,1,0.982263925087452,1.12204551696777,0.778398568281841,
9.88,9.88,1,1,1,1,0.986978399509191,1.12869739532471,0.784092004349327,
9.924,9.924,1,1,1,1,0.990602822041511,1.12853050231934,0.796103533205271,
9.966,9.966,1,1,1,1,0.995907741236687,1.13204717636108,0.789599473912096,
10.011,10.011,1,1,1,1,1.00020436243415,1.13703012466431,0.783109719734669,
10.054,10.054,1,1,1,1,1.00415580053329,1.14368200302124,0.797667559193659,
10.097,10.097,1,1,1,1,1.00775297176838,1.15140676498413,0.797567423383427,
10.14,10.14,1,1,1,1,1.01228577087522,1.14868879318237,0.799408014942932,
10.184,10.184,1,1,1,1,1.01708199918866,1.14976167678833,0.808425006235743,
10.227,10.227,1,1,1,1,1.01949828087687,1.16024017333984,0.813069400481748,
10.271,10.271,1,1,1,1,1.02619301623106,1.16573572158813,0.812153873073912,
10.315,10.315,1,1,1,1,1.03095290948153,1.17326974868774,0.815582332481384,
10.357,10.357,1,1,1,1,1.03360536907911,1.17255449295044,0.817260799395752,
10.401,10.401,1,1,1,1,1.0355947137773,1.17306709289551,0.823297558241177,
10.445,10.445,1,1,1,1,1.03986408367753,1.1810302734375,0.827918110627604,
10.488,10.488,1,1,1,1,1.04360659516454,1.18316411972046,0.832662640683842,
10.532,10.532,1,1,1,1,1.04944745653868,1.18317604064941,0.823035297785807,
10.575,10.575,1,1,1,1,1.05331714074612,1.19842290878296,0.834474622011852,
10.618,10.618,1,1,1,1,1.05733216520548,1.19783878326416,0.843477308188915,
10.662,10.662,1,1,1,1,1.06239182272553,1.20099782943726,0.844950735110903,
10.706,10.706,1,1,1,1,1.06764223932624,1.20725631713867,0.842781125889206,
10.748,10.748,1,1,1,1,1.07068530085087,1.21238231658936,0.861845076808643,
10.792,10.792,1,1,1,1,1.07674417260289,1.21572017669678,0.858841002501678,
10.836,10.836,1,1,1,1,1.08353882938027,1.22376680374146,0.857415259298849,
10.879,10.879,1,1,1,1,1.08787178564072,1.23308897018433,0.862679541893911,
10.923,10.923,1,1,1,1,1.09373081454635,1.2325644493103,0.865058959479904,
10.966,10.966,1,1,1,1,1.09752782862782,1.23378038406372,0.870304168587303,
11.009,11.009,1,1,1,1,1.10242397836447,1.24787092208862,0.878810944085121,
11.053,11.053,1,1,1,1,1.10719295538068,1.24760866165161,0.87080961601038,
11.097,11.097,1,1,1,1,1.10982724744678,1.25539302825928,0.881838860251665,
11.14,11.14,1,1,1,1,1.11408753358126,1.25566720962524,0.879721703121042,
11.184,11.184,1,1,1,1,1.12153622149229,1.26408338546753,0.883464875074959,
11.227,11.227,1,1,1,1,1.12557849724889,1.26901865005493,0.891342225479889,
11.27,11.27,1,1,1,1,1.12684114068747,1.27103328704834,0.911860529833651,
11.314,11.314,1,1,1,1,1.13518003764153,1.27248764038086,0.897660318268347,
11.357,11.357,1,1,1,1,1.13765990568995,1.28160715103149,0.902152124613047,
11.4,11.4,1,1,1,1,1.14261964178681,1.28306150436401,0.909142557841635,
11.444,11.444,1,1,1,1,1.14727961361408,1.29073858261108,0.912785593985319,
11.488,11.488,1,1,1,1,1.15226660100818,1.29263401031494,0.908970896452665,
11.531,11.531,1,1,1,1,1.15697199166417,1.29767656326294,0.920863216010714,
11.575,11.575,1,1,1,1,1.15995146682858,1.30225419998169,0.920147960223341,
11.618,11.618,1,1,1,1,1.16522005096078,1.31051540374756,0.925374095843077,
11.661,11.661,1,1,1,1,1.16984368772507,1.31098031997681,0.920662944390249,
11.705,11.705,1,1,1,1,1.17473983746171,1.31828784942627,0.930485790536833,
11.748,11.748,1,1,1,1,1.17624774257541,1.32037401199341,0.94307429239459,
11.792,11.792,1,1,1,1,1.1811529760778,1.32383108139038,0.936093395909834,
11.836,11.836,1,1,1,1,1.18690299979448,1.32769346237183,0.936536854498005,
11.879,11.879,1,1,1,1,1.19073634893894,1.33010149002075,0.945282048591614,
11.922,11.922,1,1,1,1,1.19440619029999,1.33235454559326,0.95494277009306,
11.966,11.966,1,1,1,1,1.19812145048976,1.33861303329468,0.95263964645772,
12.009,12.009,1,1,1,1,1.20042872698903,1.34892463684082,0.961084433120632,
12.052,12.052,1,1,1,1,1.20859503239393,1.34539604187012,0.950684613972235,
12.096,12.096,1,1,1,1,1.20943982260823,1.35232210159302,0.966458388269758,
12.139,12.139,1,1,1,1,1.2171156046629,1.35538578033447,0.959663458289719,
12.183,12.183,1,1,1,1,1.22122146677971,1.35889053344727,0.969924994652557,
12.227,12.227,1,1,1,1,1.22383759131432,1.36579275131226,0.970950194614458,
12.27,12.27,1,1,1,1,1.22540908278823,1.37603282928467,0.982332298377514,
12.313,12.313,1,1,1,1,1.2310955201447,1.36619806289673,0.968308516573095,
12.357,12.357,1,1,1,1,1.2349561205864,1.37107372283936,0.976839133930492,
12.4,12.4,1,1,1,1,1.23908923400044,1.38061046600342,0.988774368835783,
12.444,12.444,1,1,1,1,1.2442488129437,1.38524770736694,0.983367035083246,
12.488,12.488,1,1,1,1,1.2471465342164,1.38616561889648,0.987057754946089,
12.53,12.53,1,1,1,1,1.25399569358826,1.38745307922363,0.98884589441452,
12.574,12.574,1,1,1,1,1.25601228958368,1.39114856719971,1.00546843891306,
12.618,12.618,1,1,1,1,1.26060867505074,1.39632225036621,0.996947358299494,
12.661,12.661,1,1,1,1,1.26620427474976,1.40652656555176,1.00018508283033,
12.704,12.704,1,1,1,1,1.26704906496406,1.39695405960083,1.00908763319716,
12.748,12.748,1,1,1,1,1.27190887963772,1.41029357910156,1.01466662833867,
12.791,12.791,1,1,1,1,1.2774772280395,1.41439437866211,1.01777083845587,
12.835,12.835,1,1,1,1,1.2820826972723,1.41901969909668,1.01573474364781,
12.879,12.879,1,1,1,1,1.28519842892289,1.42110586166382,1.01503379297619,
12.921,12.921,1,1,1,1,1.28694251194596,1.42571926116943,1.02571494606762,
12.965,12.965,1,1,1,1,1.29236552009583,1.42749547958374,1.0321903951293,
13.009,13.009,1,1,1,1,1.29819729770422,1.42611265182495,1.02448470611334,
13.052,13.052,1,1,1,1,1.30249391890168,1.43795013427734,1.02971561010499,
13.096,13.096,1,1,1,1,1.30597300118208,1.44212245941162,1.03144176073852,
13.139,13.139,1,1,1,1,1.30976093149781,1.44631862640381,1.03717334378133,
13.182,13.182,1,1,1,1,1.31418472541571,1.4492392539978,1.04105003014889,
13.226,13.226,1,1,1,1,1.31727320576906,1.44623517990112,1.04687698063002,
13.27,13.27,1,1,1,1,1.32263262755871,1.45233869552612,1.04442603746529,
13.312,13.312,1,1,1,1,1.32736526951194,1.45834684371948,1.04990966516848,
13.356,13.356,1,1,1,1,1.33096244074702,1.46654844284058,1.05719096908393,
13.4,13.4,1,1,1,1,1.33624010864496,1.46884918212891,1.05540759798741,
13.443,13.443,1,1,1,1,1.34149052524567,1.47373676300049,1.06945522165141,
13.487,13.487,1,1,1,1,1.349784003371,1.48768424987793,1.06470592322326,
13.53,13.53,1,1,1,1,1.35433497000933,1.48675441741943,1.0704470430099,
13.573,13.573,1,1,1,1,1.35658774391413,1.49459838867188,1.07631690883827,
13.617,13.617,1,1,1,1,1.36300996629596,1.49598121643066,1.07779987250409,
13.661,13.661,1,1,1,1,1.36806962381601,1.5031099319458,1.07752330693297,
13.704,13.704,1,1,1,1,1.3735380507946,1.50684118270874,1.08644969915938,
13.748,13.748,1,1,1,1,1.37727147851586,1.50940418243408,1.09043128970909,
13.791,13.791,1,1,1,1,1.38284891068339,1.50904655456543,1.08919628138289,
13.834,13.834,1,1,1,1,1.38777231171727,1.51513814926147,1.09910972659588,
13.878,13.878,1,1,1,1,1.3932679899931,1.53036117553711,1.09957225867171,
13.921,13.921,1,1,1,1,1.39499390548468,1.528000831604,1.10240467158971,
13.965,13.965,1,1,1,1,1.4006712590754,1.534104347229,1.10607154959297,
14.009,14.009,1,1,1,1,1.40633044513464,1.53758525848389,1.11479767019892,
14.052,14.052,1,1,1,1,1.41277991881371,1.54719352722168,1.11737259103346,
14.095,14.095,1,1,1,1,1.41556863489747,1.55035257339478,1.11596592131829,
14.139,14.139,1,1,1,1,1.42001059634686,1.54685974121094,1.12168796761727,
14.182,14.182,1,1,1,1,1.42457973051667,1.55398845672607,1.12907417571487,
14.225,14.225,1,1,1,1,1.4300754087925,1.55700445175171,1.12862118038287,
14.269,14.269,1,1,1,1,1.43293679500222,1.56401395797729,1.13271721185856,
14.312,14.312,1,1,1,1,1.43822354666591,1.56513452529907,1.12512596376858,
14.356,14.356,1,1,1,1,1.44259283798933,1.56543254852295,1.12819679528236,
14.4,14.4,1,1,1,1,1.44617184169292,1.57103538513184,1.13800056794128,
14.443,14.443,1,1,1,1,1.45041396029592,1.57216787338257,1.1467791406383,
14.486,14.486,1,1,1,1,1.45630024049878,1.57953500747681,1.15115173768511,
14.53,14.53,1,1,1,1,1.45909804034829,1.58047676086426,1.15813263416986,
14.573,14.573,1,1,1,1,1.46279513300657,1.58629417419434,1.15643509376783,
14.617,14.617,1,1,1,1,1.4674460210681,1.59174203872681,1.15799435138431,
14.661,14.661,1,1,1,1,1.47154279941916,1.59403085708618,1.1630583623589,
14.703,14.703,1,1,1,1,1.47745633091927,1.59455537796021,1.15426548454614,
14.747,14.747,1,1,1,1,1.48100808332562,1.59784555435181,1.16593369062414,
14.791,14.791,1,1,1,1,1.48581339540482,1.60188674926758,1.16508015205121,
14.834,14.834,1,1,1,1,1.48939239910841,1.60934925079346,1.16569527202835,
14.877,14.877,1,1,1,1,1.4913817438066,1.61342620849609,1.17699154509692,
14.921,14.921,1,1,1,1,1.49571470006704,1.61088705062866,1.17957600267529,
14.964,14.964,1,1,1,1,1.50046550955176,1.61927938461304,1.18428715412812,
15.008,15.008,1,1,1,1,1.50371749768853,1.62292718887329,1.19101532690134,
15.052,15.052,1,1,1,1,1.50627003586292,1.62293910980225,1.20205887625837,
15.094,15.094,1,1,1,1,1.50972186684608,1.62844657897949,1.19684227738247,
15.138,15.138,1,1,1,1,1.51642568596601,1.62917375564575,1.18829735490932,
15.182,15.182,1,1,1,1,1.52000468966961,1.636803150177,1.19014271484075,
15.225,15.225,1,1,1,1,1.52339293429255,1.63580179214478,1.21321209816947,
15.269,15.269,1,1,1,1,1.52682659774423,1.64531469345093,1.21103772057586,
15.312,15.312,1,1,1,1,1.53088704103231,1.64610147476196,1.21127137079973,
15.355,15.355,1,1,1,1,1.53457504992485,1.65191888809204,1.21496685903449,
15.399,15.399,1,1,1,1,1.53971646133661,1.65113210678101,1.21206292053776,
15.443,15.443,1,1,1,1,1.54368606696725,1.65579319000244,1.21872433610415,
15.485,15.485,1,1,1,1,1.54660195577145,1.65464878082275,1.21831902449131,
15.529,15.529,1,1,1,1,1.54993569779992,1.66460275650024,1.23637684893651,
15.573,15.573,1,1,1,1,1.55486818259954,1.65728330612183,1.23458394109616,
15.616,15.616,1,1,1,1,1.55973708103895,1.66610479354858,1.23554238385124,
15.66,15.66,1,1,1,1,1.56139032640457,1.66678428649902,1.23199948351779,
15.703,15.703,1,1,1,1,1.56816681565046,1.68102979660034,1.22561940189443,
15.746,15.746,1,1,1,1,1.57085561031103,1.68159008026123,1.24080189807439,
15.79,15.79,1,1,1,1,1.57462537309527,1.68269872665405,1.24178895106096,
15.834,15.834,1,1,1,1,1.58092950652242,1.6893744468689,1.24704369691219,
15.877,15.877,1,1,1,1,1.58176521297097,1.69246196746826,1.25236519997025,
15.921,15.921,1,1,1,1,1.58654327375293,1.694655418396,1.25596532076669,
15.964,15.964,1,1,1,1,1.5912032455802,1.69318914413452,1.25748166303592,
16.007,16.007,1,1,1,1,1.5951455999136,1.69950723648071,1.2572956965312,
16.05,16.05,1,1,1,1,1.59883360880613,1.70178413391113,1.26909264865093,
16.093,16.093,1,1,1,1,1.60316656506658,1.70867443084717,1.26905450167561,
16.135,16.135,1,1,1,1,1.60829889271259,1.70966386795044,1.26495847019992,
16.178,16.178,1,1,1,1,1.6118597288847,1.7085075378418,1.27360829685521,
16.221,16.221,1,1,1,1,1.61760975260139,1.71346664428711,1.28039369009142,
16.263,16.263,1,1,1,1,1.61980802391171,1.71620845794678,1.27807626134033,
16.306,16.306,1,1,1,1,1.62366862435341,1.7216682434082,1.28304967324853,
16.349,16.349,1,1,1,1,1.62891904095411,1.72883272171021,1.30010613959141,
16.391,16.391,1,1,1,1,1.63604071329832,1.7337441444397,1.28046044729824,
16.434,16.434,1,1,1,1,1.63704901129603,1.73138380050659,1.29346856588459,
16.477,16.477,1,1,1,1,1.64035550202727,1.73022747039795,1.31003865829206,
16.519,16.519,1,1,1,1,1.64774968734384,1.73959732055664,1.29330167286754,
16.562,16.562,1,1,1,1,1.6502568066895,1.74247026443481,1.30459317756419,
16.595,16.595,1,1,1,1,1.65553447458744,1.7539381980896,1.30229959067268,
16.626,16.626,1,1,1,1,1.67597294751406,-0.072324275970459,1.29680165785375,
16.669,16.669,1,1,1,1,1.68226799717545,-0.00762939453125,1.50505553290515,
16.711,16.711,1,1,1,1,1.690161789608,-0.00472664833068848,1.57466422613225,
16.754,16.754,1,1,1,1,1.70043552866578,-0.00303387641906738,1.45605574309821,
16.797,16.797,1,1,1,1,1.70696675623655,0.00206232070922852,1.5154124367063,
16.84,16.84,1,1,1,1,1.70744819582105,-0.00352859497070313,1.52725230417328,
16.882,16.882,1,1,1,1,1.70679416468739,-0.00497102737426758,1.53006564360361,
16.925,16.925,1,1,1,1,1.70534984593391,-0.0010073184967041,1.50620947890878,
16.968,16.968,1,1,1,1,1.70600387706757,0.00101327896118164,1.54459487283111,
17.01,17.01,1,1,1,1,1.70817489708066,-0.00362396240234375,1.53634558941674,
17.053,17.053,1,1,1,1,1.70881076068282,-0.000143051147460938,1.4995242214828,
17.096,17.096,1,1,1,1,1.70950112687945,0.000369548797607422,1.53911601349983,
17.138,17.138,1,1,1,1,1.71199007869363,0.00623464584350586,1.53361331230898,
17.181,17.181,1,1,1,1,1.71451536557078,-0.00287294387817383,1.51853572031116,
17.224,17.224,1,1,1,1,1.71594151679277,-0.00315308570861816,1.52814875809345,
17.266,17.266,1,1,1,1,1.72254541448951,-0.00297427177429199,1.52850161761522,
17.309,17.309,1,1,1,1,1.72444392153025,0.00203847885131836,1.54777060852704,
17.352,17.352,1,1,1,1,1.73083889261484,-0.00167489051818848,1.5453768858253,
17.394,17.394,1,1,1,1,1.73548978067636,0.00203847885131836,1.54909621591964,
17.437,17.437,1,1,1,1,1.74117621803284,0.00526905059814453,1.56496058928356,
17.48,17.48,1,1,1,1,1.74510040483475,0.00435113906860352,1.56561862460794,
17.522,17.522,1,1,1,1,1.74933343967199,0.00152587890625,1.56591426366672,
17.565,17.565,1,1,1,1,1.75667312239408,0.000739097595214844,1.57434951358581,
17.608,17.608,1,1,1,1,1.76079715204239,-0.0056147575378418,1.58000957104988,
17.65,17.65,1,1,1,1,1.76438523951173,-0.00349283218383789,1.58213626492434,
17.693,17.693,1,1,1,1,1.77068028917313,-0.00140666961669922,1.59088622738986,
17.736,17.736,1,1,1,1,1.77633039146662,0.000250339508056641,1.59570705139675,
17.779,17.779,1,1,1,1,1.78058159383535,-0.00496506690979004,1.59601222719936,
17.821,17.821,1,1,1,1,1.78452394816875,0.000321865081787109,1.60602103985066,
17.864,17.864,1,1,1,1,1.78856622392535,0.00110864639282227,1.62492763449688,
17.907,17.907,1,1,1,1,1.79581506898999,0.00514984130859375,1.61581050739384,
17.949,17.949,1,1,1,1,1.79770449226499,0.000250339508056641,1.62706863348708,
17.992,17.992,1,1,1,1,1.80439922761917,-0.00236630439758301,1.62299644387097,
18.035,18.035,1,1,1,1,1.81045809937119,-0.00258088111877441,1.62333022990508,
18.077,18.077,1,1,1,1,1.81427328098416,-0.00574588775634766,1.63604270943265,
18.12,18.12,1,1,1,1,1.81630804451108,-0.00212788581848145,1.65459167618518,
18.163,18.163,1,1,1,1,1.82411099928617,0.00118017196655273,1.63871776607742,
18.205,18.205,1,1,1,1,1.82642735955119,-0.00339150428771973,1.65678989563837,
18.248,18.248,1,1,1,1,1.83067856191993,-0.00309944152832031,1.65442955154004,
18.291,18.291,1,1,1,1,1.83630141291618,-0.00143647193908691,1.66298401075702,
18.333,18.333,1,1,1,1,1.83938080950379,-0.00438690185546875,1.66379940235462,
18.376,18.376,1,1,1,1,1.84334133136868,-0.00373125076293945,1.68514740342174,
18.419,18.419,1,1,1,1,1.85040850111842,0.000894069671630859,1.67492878240614,
18.461,18.461,1,1,1,1,1.85616760860085,-0.00285506248474121,1.67282593039126,
18.504,18.504,1,1,1,1,1.85961035581827,0.00352859497070313,1.68344032627587,
18.547,18.547,1,1,1,1,1.86172687323689,0.00222921371459961,1.69368755752296,
18.59,18.59,1,1,1,1,1.86647768272161,-0.00352859497070313,1.68973934557667,
18.632,18.632,1,1,1,1,1.87240938175321,-0.00163912773132324,1.6984320875792,
18.679,18.679,1,1,1,1,1.87359027130008,-0.00345706939697266,1.71050083689814,
18.722,18.722,1,1,1,1,1.87864084505439,-4.17232513427734E-05,1.70923244996853,
18.765,18.765,1,1,1,1,1.88272853963971,0.00278949737548828,1.70764458212056,
18.807,18.807,1,1,1,1,1.88728859004378,-0.0010371208190918,1.71606552692389,
18.85,18.85,1,1,1,1,1.89180322161913,-0.000357627868652344,1.71149265825663,
18.893,18.893,1,1,1,1,1.89735340248942,-0.000429153442382813,1.72161591183391,
18.936,18.936,1,1,1,1,1.90026929129362,0.000607967376708984,1.72482502613325,
18.978,18.978,1,1,1,1,1.90342135800719,0.000596046447753906,1.73047554685349,
19.021,19.021,1,1,1,1,1.90855368565321,-0.000762939453125,1.73173916541119,
19.064,19.064,1,1,1,1,1.91222352701426,-0.00227093696594238,1.74038422369456,
19.106,19.106,1,1,1,1,1.91616588134766,0.00112056732177734,1.7432595519598,
19.149,19.149,1,1,1,1,1.91894551366568,0.00894069671630859,1.74451840214558,
19.192,19.192,1,1,1,1,1.925385903579,0.00269412994384766,1.75401699900188,
19.234,19.234,1,1,1,1,1.9279202742219,0.00187158584594727,1.75913823043947,
19.277,19.277,1,1,1,1,1.93169003700614,-0.00152587890625,1.7534495627439,
19.323,19.323,1,1,1,1,1.93833026976585,-0.00153779983520508,1.76240933357372,
19.365,19.365,1,1,1,1,1.93949299178123,0.000238418579101563,1.77140725137887,
19.408,19.408,1,1,1,1,1.94369877532125,0.00362396240234375,1.77052987094636,
19.451,19.451,1,1,1,1,1.94784097250104,0.00387430191040039,1.77377713222103,
19.493,19.493,1,1,1,1,1.95187416449189,0.00333786010742188,1.7813636119391,
19.536,19.536,1,1,1,1,1.95547133572698,-0.00741481781005859,1.78450596903162,
19.579,19.579,1,1,1,1,1.95971345432997,-0.000798702239990234,1.78683770289845,
19.622,19.622,1,1,1,1,1.96477311185002,-0.00300407409667969,1.79712308112087,
19.664,19.664,1,1,1,1,1.9682885291934,-0.00480413436889648,1.79892075733314,
19.707,19.707,1,1,1,1,1.97273049064279,-0.00290870666503906,1.79983151636906,
19.75,19.75,1,1,1,1,1.97560096061826,-0.00126361846923828,1.80496228455048,
19.792,19.792,1,1,1,1,1.98268629789948,-0.00431537628173828,1.8035222362319,
19.835,19.835,1,1,1,1,1.98799121709466,0.00275373458862305,1.80039895262704,
19.878,19.878,1,1,1,1,1.98991697543263,-0.00324249267578125,1.81438935582805,
19.92,19.92,1,1,1,1,1.99137946171761,0.00482797622680664,1.83046353755627,
19.963,19.963,1,1,1,1,1.99718398802876,0.00566244125366211,1.82838929577289,
20.006,20.006,1,1,1,1,2.0029430955112,-0.00153779983520508,1.82430756941295,
20.048,20.048,1,1,1,1,2.0043510792017,0.00246763229370117,1.84807313504138,
20.091,20.091,1,1,1,1,2.01108214961886,0.00383853912353516,1.82967675619016,
20.134,20.134,1,1,1,1,2.01486099616885,-0.00211596488952637,1.8400288916194,
20.176,20.176,1,1,1,1,2.0188941881597,-0.00305771827697754,1.84705270345139,
20.219,20.219,1,1,1,1,2.02230060031414,-0.00224113464355469,1.8474770885519,
20.262,20.262,1,1,1,1,2.02656997021437,0.00243186950683594,1.85472024549203,
20.304,20.304,1,1,1,1,2.03054865961075,-0.00296831130981445,1.8604089131876,
20.347,20.347,1,1,1,1,2.03460001913309,0.00292062759399414,1.86208261173005,
20.39,20.39,1,1,1,1,2.03840611698031,0.00109672546386719,1.86402333909979,
20.432,20.432,1,1,1,1,2.04110399540663,-0.00372529029846191,1.8823243505127,
20.475,20.475,1,1,1,1,2.04546420296431,0.000166893005371094,1.88867105353265,
20.518,20.518,1,1,1,1,2.05289472334385,0.000548362731933594,1.87345041037736,
20.561,20.561,1,1,1,1,2.05474781155586,-0.00480413436889648,1.89110769158163,
20.603,20.603,1,1,1,1,2.05850849057436,-0.000166893005371094,1.89208043945246,
20.646,20.646,1,1,1,1,2.06747416736484,-0.00300407409667969,1.88541902388606,
20.689,20.689,1,1,1,1,2.06794652318358,-0.0066220760345459,1.90269006696515,
20.731,20.731,1,1,1,1,2.0758948182106,0.00412464141845703,1.89586652675362,
20.774,20.774,1,1,1,1,2.07614916365147,-0.000196695327758789,1.91282285728626,
20.817,20.817,1,1,1,1,2.07892879596949,0.00329017639160156,1.9231130038806,
20.859,20.859,1,1,1,1,2.08602321701646,-0.00374317169189453,1.90848840721478,
20.902,20.902,1,1,1,1,2.08977481226921,0.00377893447875977,1.9177485854753,
20.945,20.945,1,1,1,1,2.09541583079696,0.00377893447875977,1.91424383211718,
20.987,20.987,1,1,1,1,2.09851339491606,-0.00218749046325684,1.92786230230875,
21.03,21.03,1,1,1,1,2.10318245050907,-0.0011444091796875,1.93429483602319,
21.073,21.073,1,1,1,1,2.10692496199608,0.000989437103271484,1.93624033176484,
21.115,21.115,1,1,1,1,2.11222079742551,-0.00782608985900879,1.93817152239075,
21.158,21.158,1,1,1,1,2.11710786339641,0.000703334808349609,1.94409384031019,
21.201,21.201,1,1,1,1,2.12010550609231,-0.00208616256713867,1.94893373780475,
21.243,21.243,1,1,1,1,2.12339382929206,0.00327825546264648,1.95485605572419,
21.286,21.286,1,1,1,1,2.12658223106861,-0.00312924385070801,1.96516050743427,
21.329,21.329,1,1,1,1,2.13246851127148,-0.00488162040710449,1.95709242215271,
21.371,21.371,1,1,1,1,2.13697405908108,-0.00199675559997559,1.9660426562387,
21.414,21.414,1,1,1,1,2.14163403090835,0.00299215316772461,1.96506037162404,
21.457,21.457,1,1,1,1,2.14821976107359,0.00212192535400391,1.96910871938057,
21.5,21.5,1,1,1,1,2.15124465506673,-0.00342726707458496,1.97384848106489,
21.542,21.542,1,1,1,1,2.15307957574725,7.15255737304688E-05,1.98565973830037,
21.585,21.585,1,1,1,1,2.15773954757452,0.00116825103759766,1.98857321354094,
21.628,21.628,1,1,1,1,2.16271745120287,-0.00463724136352539,1.98247446586061,
21.67,21.67,1,1,1,1,2.16848564245105,-0.00502467155456543,1.99031843766212,
21.713,21.713,1,1,1,1,2.17204647862315,-0.000542402267456055,1.99042811021619,
21.756,21.756,1,1,1,1,2.17468985445499,0.00516176223754883,2.00270666789942,
21.798,21.798,1,1,1,1,2.17970409314632,0.00287294387817383,2.00887694115849,
21.841,21.841,1,1,1,1,2.18309233776927,-0.00128746032714844,2.01591505810623,
21.884,21.884,1,1,1,1,2.18872427253127,0.00102519989013672,2.01929106542263,
21.926,21.926,1,1,1,1,2.1922306061089,-0.0025331974029541,2.02196135369549,
21.969,21.969,1,1,1,1,2.19663623249531,-0.00293850898742676,2.02312960481486,
22.012,22.012,1,1,1,1,2.2003151576221,-0.00283718109130859,2.03329577373939,
22.054,22.054,1,1,1,1,2.20386691002846,0.0029444694519043,2.03674330663452,
22.097,22.097,1,1,1,1,2.20959876621365,-0.000143051147460938,2.04612269419293,
22.14,22.14,1,1,1,1,2.21293250824213,-0.0039517879486084,2.04362406730905,
22.182,22.182,1,1,1,1,2.21880970467925,-0.0018775463104248,2.05022349404054,
22.225,22.225,1,1,1,1,2.22158933699727,0.0052332878112793,2.05998435135221,
22.268,22.268,1,1,1,1,2.22713951786757,0.00183582305908203,2.05959811322703,
22.311,22.311,1,1,1,1,2.22820231845975,-0.00256896018981934,2.07024111934314,
22.353,22.353,1,1,1,1,2.23607794336081,-0.00119209289550781,2.06295981542768,
22.396,22.396,1,1,1,1,2.24041998338699,0.00587701797485352,2.07126155093312,
22.439,22.439,1,1,1,1,2.24539788701534,0.00532865524291992,2.07626357307281,
22.481,22.481,1,1,1,1,2.24629717982411,0.00634193420410156,2.07652583352818,
22.524,22.524,1,1,1,1,2.25086631399393,0.00489950180053711,2.08304896630902,
22.567,22.567,1,1,1,1,2.25635290850401,0.00282526016235352,2.08567157086272,
22.609,22.609,1,1,1,1,2.26099471279979,0.00411272048950195,2.09012999860401,
22.652,22.652,1,1,1,1,2.26649947484136,0.00448226928710938,2.09568038351402,
22.695,22.695,1,1,1,1,2.27169538884759,0.000846385955810547,2.10026755729704,
22.737,22.737,1,1,1,1,2.27176805897355,-0.00153779983520508,2.11062922947011,
22.78,22.78,1,1,1,1,2.27888973131776,-0.00255703926086426,2.11619868786778,
22.823,22.823,1,1,1,1,2.28451258231401,-0.00113248825073242,2.10825458025603,
22.865,22.865,1,1,1,1,2.28886370610595,-0.00498294830322266,2.11259379869943,
22.908,22.908,1,1,1,1,2.29314215977192,-0.00293850898742676,2.1174384645659,
22.951,22.951,1,1,1,1,2.29465006488562,-0.00300407409667969,2.13935867026291,
22.993,22.993,1,1,1,1,2.29948262826204,0.00100135803222656,2.1305228771029,
23.036,23.036,1,1,1,1,2.30328872610927,-0.000524520874023438,2.13201060914063,
23.079,23.079,1,1,1,1,2.31089183803797,-0.00012516975402832,2.13299766212721,
23.099,23.099,1,1,1,1,2.30968369719386,-0.00278949737548828,2.14035525999331,
23.105,23.105,1,1,1,1,2.31123702113628,-0.00170469284057617,2.13772311869578,