File: Aluminum.csv
"Total Time (s)","Cycle Elapsed Time (s)","Total Cycles","Elapsed Cycles","Step","Total Cycle Count(8800 (0,3) Waveform)","Position(8800 (0,3):Position) (mm)","Load(8800 (0,3):Load) (kN)","Extension mm from Extensometer (mm)",
0,0,1,1,1,1,0.000935627871751785,-0.00249743461608887,-0.00321388267126083,
0.143,0.143,1,1,1,1,0.00407861081957817,0.0249385833740234,0.00303268453845978,
0.308,0.308,1,1,1,1,0.0312118191003799,0.640177726745605,0.0340366387351036,
0.47,0.47,1,1,1,1,0.0472628331720829,0.924003124237061,0.0288152714872837,
0.632,0.632,1,1,1,1,0.0549476989924908,1.08679533004761,0.0581646006291389,
0.793,0.793,1,1,1,1,0.0713802312254906,1.41249895095825,0.0695848513675213,
0.954,0.954,1,1,1,1,0.0879308524131775,1.7247200012207,0.0744056753744125,
1.116,1.116,1,1,1,1,0.104862991762161,2.05402374267578,0.069279675564909,
1.277,1.277,1,1,1,1,0.121604372030497,2.37199068069458,0.0810003337339878,
1.439,1.439,1,1,1,1,0.13909970485568,2.71621942520142,0.0817441997528553,
1.6,1.6,1,1,1,1,0.154878205955029,2.99556255340576,0.0880050720783234,
1.761,1.761,1,1,1,1,0.174172124397755,3.33619117736816,0.0979280540351391,
1.923,1.923,1,1,1,1,0.193211697399616,3.69703769683838,0.0974655219593048,
2.088,2.088,1,1,1,1,0.206919099909067,3.97434234619141,0.113296516719818,
2.259,2.259,1,1,1,1,0.219600036889315,4.22366857528687,0.111665733524609,
2.429,2.429,1,1,1,1,0.243281414186954,4.61477041244507,0.110430725198412,
2.599,2.599,1,1,1,1,0.261194600236416,4.95063066482544,0.126986512490129,
2.769,2.769,1,1,1,1,0.275674122834206,5.22069931030273,0.134658822902679,
2.94,2.94,1,1,1,1,0.28901817471385,5.45699596405029,0.135908136344624,
3.11,3.11,1,1,1,1,0.310955468988419,5.89611530303955,0.14685631826334,
3.28,3.28,1,1,1,1,0.329777031612396,6.23552799224854,0.151801119940042,
3.45,3.45,1,1,1,1,0.345937050873041,6.50786161422729,0.157065402535105,
3.62,3.62,1,1,1,1,0.356619559389353,6.7347526550293,0.15823365365448,
3.791,3.791,1,1,1,1,0.375531959670782,7.06329345703125,0.163126003240108,
3.961,3.961,1,1,1,1,0.400957419991493,7.48887062072754,0.162673007908106,
4.132,4.132,1,1,1,1,0.416154560083151,7.78974294662476,0.17958642309351,
4.302,4.302,1,1,1,1,0.431833139759302,8.02427530288696,0.173769009356213,
4.472,4.472,1,1,1,1,0.443369522255659,8.22900533676147,0.181407941165352,
4.642,4.642,1,1,1,1,0.460792184954882,8.56306552886963,0.193700803964329,
4.813,4.813,1,1,1,1,0.484618902504444,8.9659571647644,0.200724615796328,
4.983,4.983,1,1,1,1,0.502750098931789,9.25211906433105,0.19913674794836,
5.153,5.153,1,1,1,1,0.514858758670092,9.47948694229126,0.22007943740263,
5.323,5.323,1,1,1,1,0.525841031455994,9.67930555343628,0.218734756522369,
5.494,5.494,1,1,1,1,0.545053196007013,9.99220609664917,0.226740852969027,
5.664,5.664,1,1,1,1,0.567099495470524,10.3395700454712,0.234961526151896,
5.834,5.834,1,1,1,1,0.581606269365549,10.6020569801331,0.242729204002762,
6.004,6.004,1,1,1,1,0.594804980993271,10.8282923698425,0.252413767363787,
6.174,6.174,1,1,1,1,0.613708297508955,11.1196637153625,0.252480524570608,
6.345,6.345,1,1,1,1,0.636490381997824,11.4966750144958,0.263595599506378,
6.515,6.515,1,1,1,1,0.653222678500414,11.775004863739,0.269570369516897,
6.685,6.685,1,1,1,1,0.669337278932333,11.9907379150391,0.279645939375019,
6.855,6.855,1,1,1,1,0.680255965358019,12.1955037117004,0.275230426980972,
7.026,7.026,1,1,1,1,0.700957867491245,12.4972820281982,0.295224210423994,
7.196,7.196,1,1,1,1,0.719098147684336,12.7979278564453,0.290756245938873,
7.366,7.366,1,1,1,1,0.734749476063251,13.0473494529724,0.284371395943594,
7.536,7.536,1,1,1,1,0.74857496752739,13.2617473602295,0.309090635955191,
7.706,7.706,1,1,1,1,0.770766607242823,13.6011123657227,0.322923682882976,
7.877,7.877,1,1,1,1,0.787725997889042,13.8896107673645,0.321140311786461,
8.049,8.049,1,1,1,1,0.806275047540665,14.1280770301819,0.32273771637826,
8.223,8.223,1,1,1,1,0.819255748790502,14.3419623374939,0.332789444376802,
8.397,8.397,1,1,1,1,0.836442233580351,14.6302580833435,0.33744337536664,
8.57,8.57,1,1,1,1,0.860196281003952,14.9649739265442,0.355458284464598,
8.744,8.744,1,1,1,1,0.879135932582617,15.2344584465027,0.371236827134037,
8.918,8.918,1,1,1,1,0.895604799878597,15.466833114624,0.365500475719309,
9.092,9.092,1,1,1,1,0.910402254277468,15.6832098960876,0.375418689304209,
9.266,9.266,1,1,1,1,0.923973400300741,15.8755660057068,0.390205410615158,
9.44,9.44,1,1,1,1,0.938434755367041,16.0883545875549,0.391573933354998,
9.613,9.613,1,1,1,1,0.957138229036331,16.3693785667419,0.412483244205856,
9.788,9.788,1,1,1,1,0.979447957706451,16.6442275047302,0.401411084617329,
9.961,9.961,1,1,1,1,0.994935778301954,16.8699145317078,0.421967535946417,
10.136,10.136,1,1,1,1,1.01241294359565,17.0815944671631,0.42977336077261,
10.309,10.309,1,1,1,1,1.02665628828406,17.2772645950317,0.433573753189516,
10.482,10.482,1,1,1,1,1.04710384497643,17.5334811210632,0.441980392877102,
10.656,10.656,1,1,1,1,1.06741514518261,17.7889466285706,0.450072320018244,
10.831,10.831,1,1,1,1,1.08335715406537,18.005096912384,0.453357728268242,
11.004,11.004,1,1,1,1,1.10234222447276,18.1982159614563,0.465025934346247,
11.178,11.178,1,1,1,1,1.11664007175565,18.3769345283508,0.481090579330635,
11.352,11.352,1,1,1,1,1.1322187300086,18.5396194458008,0.48957828134079,
11.525,11.525,1,1,1,1,1.14817890642285,18.7212347984314,0.473623308910465,
11.7,11.7,1,1,1,1,1.16951667215824,18.9406037330627,0.495352779730844,
11.873,11.873,1,1,1,1,1.19009140157104,19.1544890403748,0.494151150008058,
12.047,12.047,1,1,1,1,1.20578814877868,19.3037271499634,0.52954677473917,
12.221,12.221,1,1,1,1,1.22404651792645,19.4589734077454,0.52578452929759,
12.395,12.395,1,1,1,1,1.23997035927773,19.5966482162476,0.540084876673126,
12.569,12.569,1,1,1,1,1.25540367727876,19.7334289550781,0.545558967632484,
12.743,12.743,1,1,1,1,1.27339861721992,19.8611974716187,0.539970435747147,
12.916,12.916,1,1,1,1,1.2878145534575,19.9784874916077,0.557456055562448,
13.09,13.09,1,1,1,1,1.30689954528809,20.1012134552002,0.574021379597998,
13.264,13.264,1,1,1,1,1.32410419760942,20.2209234237671,0.593471568642616,
13.437,13.437,1,1,1,1,1.34392497446537,20.3317642211914,0.597033542463732,
13.612,13.612,1,1,1,1,1.36327339550257,20.4313397407532,0.604138416618299,
13.786,13.786,1,1,1,1,1.37967867643833,20.5063581466675,0.620355649503994,
13.959,13.959,1,1,1,1,1.39977196626663,20.5905556678772,0.62908177010994,
14.133,14.133,1,1,1,1,1.41429690769315,20.6388592720032,0.655274437043524,
14.307,14.307,1,1,1,1,1.43218284244537,20.7037568092346,0.676827478103018,
14.481,14.481,1,1,1,1,1.45105890766382,20.7550525665283,0.682783174625873,
14.655,14.655,1,1,1,1,1.46620154516101,20.8014130592346,0.69434647652173,
14.828,14.828,1,1,1,1,1.48514119673967,20.8470463752747,0.70802693554821,
15.002,15.002,1,1,1,1,1.50137388612628,20.8876729011536,0.715851833862066,
15.177,15.177,1,1,1,1,1.51989568448067,20.9185600280762,0.742259077531862,
15.35,15.35,1,1,1,1,1.53709125303626,20.9435939788818,0.754494719867849,
15.524,15.524,1,1,1,1,1.55432315665483,20.9789156913757,0.778350884562683,
15.698,15.698,1,1,1,1,1.57035600319505,21.0070133209229,0.796513613190031,
15.871,15.871,1,1,1,1,1.58942282749414,21.0345506668091,0.814728793908453,
16.044,16.044,1,1,1,1,1.60452912992835,21.0573673248291,0.813350734424782,
16.215,16.215,1,1,1,1,1.62395022109151,21.0724115371704,0.830965100281811,
16.385,16.385,1,1,1,1,1.64223584153652,21.0937142372131,0.841426908265114,
16.556,16.556,1,1,1,1,1.65696970957518,21.1148142814636,0.874352516343832,
16.727,16.727,1,1,1,1,1.6773900149703,21.143364906311,0.88463789456625,
16.897,16.897,1,1,1,1,1.69222380443215,21.1601614952087,0.887599053525972,
17.068,17.068,1,1,1,1,1.70769345749617,21.1728096008301,0.911431376361227,
17.239,17.239,1,1,1,1,1.72329936704636,21.1743831634521,0.93332774019866,
17.411,17.411,1,1,1,1,1.74129430698752,21.1959004402161,0.947122640151119,
17.582,17.582,1,1,1,1,1.75883505864143,21.2200045585632,0.954260892909098,
17.753,17.753,1,1,1,1,1.77694808753729,21.2340712547302,0.989131996729469,
17.923,17.923,1,1,1,1,1.79279017499685,21.2428689002991,1.00517279985428,
18.094,18.094,1,1,1,1,1.80833249818683,21.2556481361389,1.03162772724323,
18.265,18.265,1,1,1,1,1.82627293553352,21.2758183479309,1.02907187989635,
18.436,18.436,1,1,1,1,1.84324140994549,21.2838530540466,1.03688724146638,
18.606,18.606,1,1,1,1,1.86056415122151,21.3058233261108,1.05438716639743,
18.777,18.777,1,1,1,1,1.87702393475175,21.3206648826599,1.07602126977949,
18.948,18.948,1,1,1,1,1.89463735653162,21.3229537010193,1.10426910500879,
19.118,19.118,1,1,1,1,1.91315007112026,21.3411450386047,1.10647686120582,
19.289,19.289,1,1,1,1,1.93005495917201,21.3476538658142,1.14038475389919,
19.461,19.461,1,1,1,1,1.94609688947797,21.3580369949341,1.15631588446994,
19.632,19.632,1,1,1,1,1.963882902807,21.3682293891907,1.16836079192929,
19.803,19.803,1,1,1,1,1.98098763370514,21.3732481002808,1.18466862388139,
19.974,19.974,1,1,1,1,1.99753825489283,21.3980674743652,1.19006165251818,
20.144,20.144,1,1,1,1,2.01496091759205,21.400249004364,1.20358952364335,
20.315,20.315,1,1,1,1,2.03055774337649,21.40212059021,1.22614392280517,
20.486,20.486,1,1,1,1,2.04555504062176,21.4190721511841,1.24667176390276,
20.657,20.657,1,1,1,1,2.06710173296928,21.430516242981,1.25281819530225,
20.827,20.827,1,1,1,1,2.08298923925757,21.4397072792053,1.27062329603591,
20.998,20.998,1,1,1,1,2.09732342160344,21.441650390625,1.30885610205693,
21.169,21.169,1,1,1,1,2.11490050832033,21.4515686035156,1.33592138105111,
21.349,21.349,1,1,1,1,2.13444877220392,21.4722037315369,1.3244009945025,
21.519,21.519,1,1,1,1,2.14983667137623,21.4830994606018,1.34183416222672,
21.69,21.69,1,1,1,1,2.16976645342112,21.4985132217407,1.34301195008993,
21.861,21.861,1,1,1,1,2.18607181293368,21.4930057525635,1.38295660162873,
22.032,22.032,1,1,1,1,2.20248617763519,21.508264541626,1.39246950360079,
22.202,22.202,1,1,1,1,2.21935473062396,21.5175628662109,1.40602598495746,
22.373,22.373,1,1,1,1,2.23659571800828,21.5232729911804,1.43316278953037,
22.544,22.544,1,1,1,1,2.25172018797398,21.5312719345093,1.44325266450424,
22.718,22.718,1,1,1,1,2.27331229915023,21.5354800224304,1.46041880340118,
22.888,22.888,1,1,1,1,2.28908171648383,21.5508341789246,1.4780284008863,
23.059,23.059,1,1,1,1,2.30517814938426,21.5598702430725,1.48691664613738,
23.23,23.23,1,1,1,1,2.32240096923709,21.5643525123596,1.5142346488431,
23.4,23.4,1,1,1,1,2.33894250665903,21.5757846832275,1.51575099111233,
23.571,23.571,1,1,1,1,2.35595639989972,21.5813398361206,1.54167186084671,
23.742,23.742,1,1,1,1,2.37415118268728,21.5875744819641,1.55287276647696,
23.913,23.913,1,1,1,1,2.39234596547484,21.5947151184082,1.57887946690583,
24.083,24.083,1,1,1,1,2.40777019971013,21.6034412384033,1.59467231469102,
24.254,24.254,1,1,1,1,2.42445707738399,21.6113924980164,1.61018382853317,
24.425,24.425,1,1,1,1,2.44274269782901,21.615469455719,1.62856590226865,
24.596,24.596,1,1,1,1,2.45575973414183,21.6190576553345,1.66022789178967,
24.766,24.766,1,1,1,1,2.47576218631268,21.6302633285522,1.67069923651681,
24.937,24.937,1,1,1,1,2.49303042499423,21.642279624939,1.67127144114671,
25.108,25.108,1,1,1,1,2.51017149095535,21.650505065918,1.70154106606832,
25.278,25.278,1,1,1,1,2.52730347315073,21.6575622558594,1.71317589354291,
25.449,25.449,1,1,1,1,2.54385409433842,21.6601729393005,1.72605049771562,
25.62,25.62,1,1,1,1,2.56114958431721,21.6660261154175,1.74162400039268,
25.791,25.791,1,1,1,1,2.57775470809937,21.6708660125732,1.77230847367096,
25.961,25.961,1,1,1,1,2.59678519733548,21.6800451278687,1.78479207134657,
26.132,26.132,1,1,1,1,2.61220943157077,21.6890454292297,1.79751885598989,
26.303,26.303,1,1,1,1,2.62991369100809,21.6955780982971,1.81823743196411,
26.474,26.474,1,1,1,1,2.6463280557096,21.7067956924438,1.83948052884908,
26.646,26.646,1,1,1,1,2.66351454049945,21.7134237289429,1.84322846917491,
26.817,26.817,1,1,1,1,2.67970181105733,21.7262864112854,1.85958875321808,
26.987,26.987,1,1,1,1,2.69726981400847,21.7332124710083,1.87165750253701,
27.158,27.158,1,1,1,1,2.71410203193426,21.736204624176,1.89630521696987,
27.329,27.329,1,1,1,1,2.72940817721486,21.739387512207,1.92335142247639,
27.499,27.499,1,1,1,1,2.74948329951167,21.7481851577759,1.92287458528481,
27.67,27.67,1,1,1,1,2.76628826614022,21.7475295066834,1.95017828287477,
27.841,27.841,1,1,1,1,2.7801410089016,21.7468738555908,1.98201193378477,
28.013,28.013,1,1,1,1,2.79984369680285,21.7660903930664,1.98447241369333,
28.184,28.184,1,1,1,1,2.81767512896061,21.7715978622437,1.98815836518426,
28.355,28.355,1,1,1,1,2.83280868269205,21.7780709266663,2.00219168373251,
28.525,28.525,1,1,1,1,2.8505583609581,21.7846274375916,2.02180876579418,
28.698,28.698,1,1,1,1,2.86963426902294,21.7939734458923,2.05072894146361,
28.868,28.868,1,1,1,1,2.88580337204933,21.8119502067566,2.05070033123212,
29.039,29.039,1,1,1,1,2.89948352326155,21.8010306358337,2.07529082520199,
29.21,29.21,1,1,1,1,2.91593422302604,21.8026399612427,2.10323348462868,
29.381,29.381,1,1,1,1,2.93702672708631,21.8220353126526,2.10696235146685,
29.551,29.551,1,1,1,1,2.95295965220332,21.8231916427612,2.11779132408767,
29.722,29.722,1,1,1,1,2.96906516886949,21.8343734741211,2.13840976425166,
29.893,29.893,1,1,1,1,2.98847717626691,21.83997631073,2.15950980997915,
30.063,30.063,1,1,1,1,3.00279319108129,21.8386650085449,2.18379512814641,
30.234,30.234,1,1,1,1,3.02267755429745,21.8551993370056,2.19459549053574,
30.405,30.405,1,1,1,1,3.03954610728621,21.8533992767334,2.21607700601649,
30.576,30.576,1,1,1,1,3.05830408354998,21.8649983406067,2.22063556956801,
30.746,30.746,1,1,1,1,3.07336496715546,21.8686580657959,2.24770084856219,
30.917,30.917,1,1,1,1,3.0910328915298,21.8666315078735,2.26621643671131,
31.088,31.088,1,1,1,1,3.10748359129429,21.8793749809265,2.28136555428786,
31.259,31.259,1,1,1,1,3.12553303382993,21.8899965286255,2.29891316293807,
31.429,31.429,1,1,1,1,3.13857732143998,21.8841195106506,2.32538239544277,
31.6,31.6,1,1,1,1,3.15837993076444,21.8944430351257,2.32918755623159,
31.771,31.771,1,1,1,1,3.17529390258193,21.8946933746338,2.35420243530197,
31.942,31.942,1,1,1,1,3.19527818722129,21.9171524047852,2.35163228283935,
32.111,32.111,1,1,1,1,3.21044807601571,21.9138979911804,2.37708108375406,
32.282,32.282,1,1,1,1,3.22903346073031,21.9254374504089,2.39960210431247,
32.453,32.453,1,1,1,1,3.24424876835346,21.9237685203552,2.42680089772029,
32.624,32.624,1,1,1,1,3.2619166927278,21.9357252120972,2.43690507780991,
32.794,32.794,1,1,1,1,3.27940294178724,21.9402074813843,2.45187776562557,
32.965,32.965,1,1,1,1,3.29273790990114,21.9374179840088,2.47262972020321,
33.136,33.136,1,1,1,1,3.31038766674399,21.9415068626404,2.485952551336,
33.307,33.307,1,1,1,1,3.33045370527506,21.9660758972168,2.49644773792272,
33.477,33.477,1,1,1,1,3.34800354069471,21.965479850769,2.52013224122858,
33.648,33.648,1,1,1,1,3.36375479049683,21.9719648361206,2.54276293434105,
33.819,33.819,1,1,1,1,3.38041441687345,21.973979473114,2.54890459736862,
33.99,33.99,1,1,1,1,3.3963927608192,21.9727277755737,2.58001822411933,
34.16,34.16,1,1,1,1,3.41506898319125,21.9833731651306,2.58069056455946,
34.331,34.331,1,1,1,1,3.4338451269865,21.9953894615173,2.59877223086424,
34.502,34.502,1,1,1,1,3.4497144657433,22.0019221305847,2.61725920878186,
34.674,34.674,1,1,1,1,3.46825443162918,22.0019936561584,2.63667601922307,
34.845,34.845,1,1,1,1,3.48492314177155,22.0054984092712,2.65415687066646,
35.016,35.016,1,1,1,1,3.50131933894157,22.0133304595947,2.66068954019113,
35.186,35.186,1,1,1,1,3.51860574515462,22.0165252685547,2.69314307945018,
35.357,35.357,1,1,1,1,3.53253115804195,22.0100998878479,2.71005172626367,
35.528,35.528,1,1,1,1,3.55566750939488,22.041130065918,2.6972486476697,
35.699,35.699,1,1,1,1,3.57271773769855,22.0427751541138,2.72566337591605,
35.869,35.869,1,1,1,1,3.5852169993639,22.0348477363586,2.75088806335072,
36.04,36.04,1,1,1,1,3.60340269838572,22.0454096794128,2.77013798077488,
36.211,36.211,1,1,1,1,3.62028941890597,22.0527172088623,2.78305550029483,
36.382,36.382,1,1,1,1,3.63737598227262,22.0654249191284,2.79427071104083,
36.552,36.552,1,1,1,1,3.65642463904023,22.0768928527832,2.806892591502,
36.723,36.723,1,1,1,1,3.67507361011505,22.0789432525635,2.82831211814785,
36.894,36.894,1,1,1,1,3.68864475613832,22.0760822296143,2.85530587156329,
37.065,37.065,1,1,1,1,3.70720288955569,22.0845103263855,2.87114640306764,
37.235,37.235,1,1,1,1,3.7231539822042,22.0830678939819,2.88152238035645,
37.406,37.406,1,1,1,1,3.74173028315306,22.0936059951782,2.89950867922292,
37.577,37.577,1,1,1,1,3.75813556408882,22.0945358276367,2.91977902823706,
37.747,37.747,1,1,1,1,3.77405032167435,22.1013426780701,2.94011613445802,
37.918,37.918,1,1,1,1,3.78931104812622,22.0923662185669,2.96488782656069,
38.089,38.089,1,1,1,1,3.81049438984394,22.1116900444031,2.97169229328456,
38.26,38.26,1,1,1,1,3.82519192281961,22.1129179000854,2.99634000771742,
38.43,38.43,1,1,1,1,3.84345029196739,22.1246600151062,3.00337812466516,
38.601,38.601,1,1,1,1,3.86114546763897,22.1328139305115,3.01145097831864,
38.772,38.772,1,1,1,1,3.8772419005394,22.1312999725342,3.03029558412995,
38.943,38.943,1,1,1,1,3.89242995686531,22.1328139305115,3.04697058071957,
39.113,39.113,1,1,1,1,3.90791777746081,22.1347332000732,3.07293436580119,
39.284,39.284,1,1,1,1,3.93068169441819,22.1580266952515,3.07582876755409,
39.455,39.455,1,1,1,1,3.94765016883016,22.1582889556885,3.09858343833637,
39.625,39.625,1,1,1,1,3.96321065955162,22.162652015686,3.1139662061368,
39.796,39.796,1,1,1,1,3.97995203981996,22.1614122390747,3.13596270578446,
39.974,39.974,1,1,1,1,3.99887352386713,22.1585869789124,3.15553687249889,
40.145,40.145,1,1,1,1,4.01583291451335,22.1679925918579,3.17986510601339,
40.316,40.316,1,1,1,1,4.0346090583086,22.1771359443665,3.20213817123218,
40.486,40.486,1,1,1,1,4.04934292634726,22.1781611442566,3.20914767794843,
40.657,40.657,1,1,1,1,4.06657482996583,22.1822381019592,3.21992896685009,
40.828,40.828,1,1,1,1,4.08866654825807,22.1973896026611,3.23700927505255,
40.999,40.999,1,1,1,1,4.10165633327365,22.1926689147949,3.25030349595385,
41.169,41.169,1,1,1,1,4.11787085512877,22.1954107284546,3.27280067465267,
41.34,41.34,1,1,1,1,4.13373111011982,22.1948742866516,3.28979038378873,
41.511,41.511,1,1,1,1,4.15237099742889,22.2035884857178,3.3044340539422,
41.682,41.682,1,1,1,1,4.16843109526634,22.2087264060974,3.30470585114141,
41.852,41.852,1,1,1,1,4.18426409896016,22.2141265869141,3.34009193912868,
42.023,42.023,1,1,1,1,4.20140516492128,22.2212314605713,3.34644817889247,
42.194,42.194,1,1,1,1,4.21730175497532,22.228741645813,3.36614632327671,
42.364,42.364,1,1,1,1,4.23345269047022,22.2264051437378,3.39417481339788,
42.535,42.535,1,1,1,1,4.25309179201126,22.2400188446045,3.40595746040187,
42.714,42.714,1,1,1,1,4.27200419229269,22.2482085227966,3.41343903593779,
42.885,42.885,1,1,1,1,4.28229609888196,22.2341537475586,3.45437074046316,
43.055,43.055,1,1,1,1,4.30307067114115,22.2559809684753,3.45563435902085,
43.226,43.226,1,1,1,1,4.31982113517523,22.2543358802795,3.48287606777592,
43.397,43.397,1,1,1,1,4.33886979194283,22.269606590271,3.48991895309558,
43.568,43.568,1,1,1,1,4.35599269037247,22.2682237625122,3.50820089102082,
43.738,43.738,1,1,1,1,4.37298841608167,22.2766399383545,3.51861024691305,
43.909,43.909,1,1,1,1,4.39060183786154,22.2749471664429,3.54193235395331,
44.08,44.08,1,1,1,1,4.41065879262686,22.2915172576904,3.54802156488981,
44.25,44.25,1,1,1,1,4.4245660379827,22.2834229469299,3.56730486091738,
44.421,44.421,1,1,1,1,4.44108940787315,22.2868919372559,3.59188581814341,
44.592,44.592,1,1,1,1,4.45928419066072,22.2863078117371,3.60950495237236,
44.763,44.763,1,1,1,1,4.47602557092905,22.2928285598755,3.62391020393004,
44.933,44.933,1,1,1,1,4.49621878218055,22.3066210746765,3.63453413655848,
45.104,45.104,1,1,1,1,4.51117066059709,22.3028659820557,3.66196181181827,
45.275,45.275,1,1,1,1,4.52771219801903,22.3034977912903,3.67182757331209,
45.446,45.446,1,1,1,1,4.54389946857691,22.3155856132507,3.69593169334655,
45.616,45.616,1,1,1,1,4.56084977545738,22.3200917243958,3.72158076588173,
45.787,45.787,1,1,1,1,4.57735497781634,22.3218083381653,3.72621085501199,
45.958,45.958,1,1,1,1,4.59602211642265,22.3308444023132,3.7339022389122,
46.128,46.128,1,1,1,1,4.61245464865565,22.3297476768494,3.74840762628012,
46.299,46.299,1,1,1,1,4.63047683989406,22.3419547080994,3.77496745785122,
46.47,46.47,1,1,1,1,4.64685486953258,22.3329186439514,3.80627658785048,
46.647,46.647,1,1,1,1,4.66611245291233,22.346019744873,3.81040122955766,
46.817,46.817,1,1,1,1,4.68223613711,22.3466873168945,3.82656124198036,
46.988,46.988,1,1,1,1,4.69540759744048,22.3489165306091,3.84548691011424,
47.159,47.159,1,1,1,1,4.71526470935941,22.3505139350891,3.86768368138237,
47.33,47.33,1,1,1,1,4.73251478050947,22.3579525947571,3.86867550274086,
47.5,47.5,1,1,1,1,4.75316218004823,22.3661661148071,3.88277081012402,
47.671,47.671,1,1,1,1,4.76475306513905,22.3626136779785,3.91366032339468,
47.842,47.842,1,1,1,1,4.78084041427374,22.3708271980286,3.9345887077332,
48.02,48.02,1,1,1,1,4.80075202878714,22.3802924156189,3.94855526907463,
48.191,48.191,1,1,1,1,4.81961901023984,22.3890900611877,3.95247487078943,
48.361,48.361,1,1,1,1,4.83391685752273,22.3904728889465,3.98118046972265,
48.532,48.532,1,1,1,1,4.84923208656907,22.3809242248535,4.01200322578649,
48.703,48.703,1,1,1,1,4.86896202576756,22.3910808563232,4.00875596451182,
48.874,48.874,1,1,1,1,4.8838321502924,22.3902821540833,4.03269795990114,
49.044,49.044,1,1,1,1,4.90308973367214,22.4077820777893,4.04346971205897,
49.215,49.215,1,1,1,1,4.91854121920466,22.3972082138062,4.07677678989096,
49.391,49.391,1,1,1,1,4.93937937782407,22.4114656448364,4.07317666909451,
49.561,49.561,1,1,1,1,4.95418591598868,22.4093675613403,4.10167245966344,
49.732,49.732,1,1,1,1,4.97009158980846,22.4129199981689,4.11987333526611,
49.903,49.903,1,1,1,1,4.99213788927197,22.4197149276733,4.1271355656939,
50.077,50.077,1,1,1,1,5.00995115389824,22.4249124526978,4.15101557224832,
50.247,50.247,1,1,1,1,5.02487578101754,22.417950630188,4.17321711188836,
50.418,50.418,1,1,1,1,5.04216218723059,22.4301218986511,4.18725519880853,
50.589,50.589,1,1,1,1,5.06061131545901,22.4288582801819,4.2036154828517,
50.76,50.76,1,1,1,1,5.07694392626882,22.4398493766785,4.21430617268696,
50.93,50.93,1,1,1,1,5.09443017532825,22.4425315856934,4.23588782397795,
51.101,51.101,1,1,1,1,5.10979990696907,22.4371790885925,4.24857646164594,
51.272,51.272,1,1,1,1,5.12522414120436,22.4469542503357,4.25941020263867,
51.442,51.442,1,1,1,1,5.14398211746812,22.4501490592957,4.27332908026094,
51.613,51.613,1,1,1,1,5.16039648216963,22.4623799324036,4.30516749954286,
51.784,51.784,1,1,1,1,5.17722870009541,22.4649429321289,4.31345016156063,
51.955,51.955,1,1,1,1,5.1976399217248,22.475802898407,4.32039767944198,
52.125,52.125,1,1,1,1,5.21380902475119,22.4746942520142,4.34044868334799,
52.296,52.296,1,1,1,1,5.23233082310557,22.4895119667053,4.35838253012338,
52.467,52.467,1,1,1,1,5.24764605215192,22.4854707717896,4.3793109144619,
52.644,52.644,1,1,1,1,5.26582266740799,22.4926710128784,4.41086323142886,
52.814,52.814,1,1,1,1,5.28222794834375,22.4862456321716,4.4194367641335,
52.985,52.985,1,1,1,1,5.29882398836017,22.4895477294922,4.43807632995243,
53.156,53.156,1,1,1,1,5.31937146647573,22.4932312965393,4.45439846702027,
53.331,53.331,1,1,1,1,5.33524988899827,22.4821925163269,4.46856053161025,
53.502,53.502,1,1,1,1,5.34893912397623,22.5005388259888,4.48614151886387,
53.672,53.672,1,1,1,1,5.36893249238133,22.5000858306885,4.49537785526481,
53.843,53.843,1,1,1,1,5.38499259021878,22.5005626678467,4.52302964400463,
54.014,54.014,1,1,1,1,5.39958111800551,22.4937438964844,4.54525025713234,
54.184,54.184,1,1,1,1,5.41505077106953,22.4985003471375,4.55007584951115,
54.355,54.355,1,1,1,1,5.43601610240936,22.509765625,4.5745423658112,
54.526,54.526,1,1,1,1,5.45324800602794,22.5140810012817,4.58758863137288,
54.697,54.697,1,1,1,1,5.47439501268268,22.5222706794739,4.59716829055176,
54.867,54.867,1,1,1,1,5.48930147227049,22.5320339202881,4.60934194405284,
55.038,55.038,1,1,1,1,5.50208233067393,22.526490688324,4.63344129571538,
55.209,55.209,1,1,1,1,5.52099473095536,22.5284814834595,4.65453180469904,
55.38,55.38,1,1,1,1,5.54201456488967,22.551691532135,4.65825113479338,
55.55,55.55,1,1,1,1,5.55558571091294,22.5470662117004,4.67966589306731,
55.721,55.721,1,1,1,1,5.57133696071505,22.5454449653625,4.70562967814894,
55.892,55.892,1,1,1,1,5.58826001629829,22.5491762161255,4.71264872160902,
56.069,56.069,1,1,1,1,5.6057190140605,22.5504517555237,4.73676714675922,
56.239,56.239,1,1,1,1,5.62211521123052,22.5548267364502,4.76015601100631,
56.41,56.41,1,1,1,1,5.63923810966015,22.5615739822388,4.77147612593446,
56.581,56.581,1,1,1,1,5.65817776123881,22.5615382194519,4.78983435781035,
56.759,56.759,1,1,1,1,5.67523707330823,22.5586652755737,4.79733977520585,
56.93,56.93,1,1,1,1,5.69364078270793,22.5657224655151,4.82630763459444,
57.101,57.101,1,1,1,1,5.70595836905837,22.555947303772,4.84398398928637,
57.272,57.272,1,1,1,1,5.7270236218214,22.5751042366028,4.8517707406249,
57.442,57.442,1,1,1,1,5.7433744001627,22.5739598274231,4.86624274938941,
57.613,57.613,1,1,1,1,5.76107865960002,22.5791215896606,4.89025150198555,
57.784,57.784,1,1,1,1,5.77422286863327,22.5746750831604,4.9124244313941,
57.955,57.955,1,1,1,1,5.79639634081721,22.5890755653381,4.92601429135418,
58.125,58.125,1,1,1,1,5.80948604725599,22.5806951522827,4.94315658839154,
58.296,58.296,1,1,1,1,5.82833486117721,22.5854873657227,4.95889221571374,
58.467,58.467,1,1,1,1,5.84988155352473,22.5943207740784,4.97817074336939,
58.639,58.639,1,1,1,1,5.86486976700425,22.5949645042419,4.98645340538716,
58.809,58.809,1,1,1,1,5.88218342451453,22.5971579551697,5.00660931347532,
58.98,58.98,1,1,1,1,5.89934265800714,22.6040720939636,5.01701866936755,
59.151,59.151,1,1,1,1,5.91563893375397,22.5989103317261,5.04470383671079,
59.322,59.322,1,1,1,1,5.93065439853072,22.6022124290466,5.0564340316237,
59.492,59.492,1,1,1,1,5.95081127471924,22.6116418838501,5.0693086357964,
59.663,59.663,1,1,1,1,5.96555422652364,22.6041674613953,5.09795701426663,
59.834,59.834,1,1,1,1,5.98409419240951,22.6126432418823,5.11227166675792,
60.005,60.005,1,1,1,1,5.99985452597737,22.6239204406738,5.1199535139143,
60.175,60.175,1,1,1,1,6.02134671573043,22.6315021514893,5.12653863553004,
60.346,60.346,1,1,1,1,6.03410940660238,22.6218223571777,5.16601598662109,
60.517,60.517,1,1,1,1,6.04792581430078,22.6269006729126,5.16901052418423,
60.698,60.698,1,1,1,1,6.068164444381,22.6333022117615,5.19039667222667,
60.869,60.869,1,1,1,1,6.08623205444813,22.630512714386,5.20644701209531,
61.04,61.04,1,1,1,1,6.10464484761357,22.6440668106079,5.23184336091895,
61.211,61.211,1,1,1,1,6.11559986910224,22.6263761520386,5.24549044134202,
61.391,61.391,1,1,1,1,6.13851821007729,22.6432204246521,5.26425875320268,
61.561,61.561,1,1,1,1,6.1527615547657,22.6373195648193,5.28305090692291,
61.732,61.732,1,1,1,1,6.17472610033751,22.6513266563416,5.28596915053539,
61.903,61.903,1,1,1,1,6.19035017741918,22.645115852356,5.31858004606767,
62.073,62.073,1,1,1,1,6.20748215961456,22.6588845252991,5.32713450528464,
62.244,62.244,1,1,1,1,6.22551343461871,22.6508975028992,5.35653628651757,
62.415,62.415,1,1,1,1,6.24188238049149,22.649097442627,5.36059417101793,
62.586,62.586,1,1,1,1,6.25383661621213,22.6496934890747,5.38270987996349,
62.756,62.756,1,1,1,1,6.27621901500821,22.6620197296143,5.3937152823452,
62.927,62.927,1,1,1,1,6.28906345977187,22.6563453674316,5.41547813176899,
63.098,63.098,1,1,1,1,6.30744900164008,22.6549029350281,5.43362178690867,
63.269,63.269,1,1,1,1,6.3276876317203,22.6746082305908,5.43900051042972,
63.439,63.439,1,1,1,1,6.34020506091714,22.6716756820679,5.4616359719141,
63.61,63.61,1,1,1,1,6.36171541820169,22.6754546165466,5.48618831890864,
63.781,63.781,1,1,1,1,6.37963768801689,22.688353061676,5.50155201322141,
63.955,63.955,1,1,1,1,6.39630639815926,22.675633430481,5.51238098584223,
64.123,64.123,1,1,1,1,6.41116743891835,22.6878523826599,5.52493610909657,
64.292,64.292,1,1,1,1,6.42685510236025,22.6794600486755,5.55371800198045,
64.46,64.46,1,1,1,1,6.44558582732677,22.6829290390015,5.56676903591404,
64.632,64.632,1,1,1,1,6.46315383027792,22.6909399032593,5.57968655543399,
64.801,64.801,1,1,1,1,6.48642643811703,22.6993203163147,5.58788338675728,
64.969,64.969,1,1,1,1,6.49857143291831,22.6892113685608,5.60864964645066,
65.138,65.138,1,1,1,1,6.51426818012595,22.6970314979553,5.62537232675943,
65.307,65.307,1,1,1,1,6.53112764934897,22.6903557777405,5.64840833148475,
65.476,65.476,1,1,1,1,6.54860481464267,22.6962447166443,5.6624130398015,
65.644,65.644,1,1,1,1,6.56736279090643,22.7054357528687,5.6724504626843,
65.813,65.813,1,1,1,1,6.58102477458715,22.7034449577332,5.69734136408486,
65.986,65.986,1,1,1,1,6.59923772490621,22.7025508880615,5.70840875530148,
66.155,66.155,1,1,1,1,6.61327214298248,22.7020978927612,5.73233644557505,
66.323,66.323,1,1,1,1,6.63042229270935,22.7073907852173,5.74496309440813,
66.492,66.492,1,1,1,1,6.64452029714584,22.697639465332,5.77776949318895,
66.662,66.662,1,1,1,1,6.66580356028676,22.7185487747192,5.77284853337183,
66.831,66.831,1,1,1,1,6.67971988940835,22.7156639099121,5.79834024963379,
67,67,1,1,1,1,6.69911372927427,22.7300047874451,5.8089260352869,
67.168,67.168,1,1,1,1,6.71582785824537,22.7313756942749,5.83565752824697,
67.337,67.337,1,1,1,1,6.73436782413125,22.7283477783203,5.85127871464319,
67.506,67.506,1,1,1,1,6.75156339268684,22.7321267127991,5.86175482774224,
67.674,67.674,1,1,1,1,6.7692949034214,22.7291822433472,5.87658446440043,
67.843,67.843,1,1,1,1,6.78788937190175,22.7364182472229,5.8958391501965,
68.012,68.012,1,1,1,1,6.79641902793646,22.7257132530212,5.92740577227922,
68.18,68.18,1,1,1,1,6.81970071954131,22.7304697036743,5.93121093306804,
68.349,68.349,1,1,1,1,6.83486152456999,22.7343916893005,5.94478648791237,
68.518,68.518,1,1,1,1,6.85281104568243,22.7336287498474,5.96640628617868,
68.691,68.691,1,1,1,1,6.87066064537168,22.7386951446533,5.9740690598474,
68.86,68.86,1,1,1,1,6.89243443186283,22.7536559104919,5.98859352070298,
69.028,69.028,1,1,1,1,6.90222673133612,22.7390885353088,6.0121445095952,
69.197,69.197,1,1,1,1,6.91909528432488,22.7429628372192,6.0247759268002,
69.366,69.366,1,1,1,1,6.92990496556163,22.7353930473328,6.05800194230962,
69.534,69.534,1,1,1,1,6.95646589660048,22.7510333061218,6.06011909944024,
69.703,69.703,1,1,1,1,6.97007337768674,22.7458715438843,6.07608837698631,
69.872,69.872,1,1,1,1,6.98743245402575,22.7506637573242,6.08750385935278,
70.045,70.045,1,1,1,1,7.00448268232942,22.7532267570496,6.10859913670835,
70.213,70.213,1,1,1,1,7.01912571271062,22.7552533149719,6.12028164790211,
70.382,70.382,1,1,1,1,7.03633036503196,22.7615356445313,6.14264531218729,
70.551,70.551,1,1,1,1,7.05464323677421,22.7616429328918,6.15684552375259,
70.719,70.719,1,1,1,1,7.07163896248341,22.7661728858948,6.17062135021739,
70.888,70.888,1,1,1,1,7.08728120709658,22.7652430534363,6.19545026278305,
71.057,71.057,1,1,1,1,7.10436777046323,22.769296169281,6.20719953118362,
71.225,71.225,1,1,1,1,7.1247971596241,22.7726101875305,6.22134252228594,
71.394,71.394,1,1,1,1,7.14099351394772,22.7848172187805,6.23638673568034,
71.563,71.563,1,1,1,1,7.15728978969455,22.7784156799316,6.25613733215566,
71.732,71.732,1,1,1,1,7.1735315628469,22.7776408195496,6.27023263953881,
71.9,71.9,1,1,1,1,7.19233495793939,22.7812886238098,6.28168626888061,
72.069,72.069,1,1,1,1,7.20707790974379,22.7770447731018,6.31091162035265,
72.238,72.238,1,1,1,1,7.22753455020189,22.7962493896484,6.32403417986498,
72.406,72.406,1,1,1,1,7.24263176887035,22.7857232093811,6.34386583866286,
72.575,72.575,1,1,1,1,7.26211644639373,22.7836847305298,6.35374590527243,
72.744,72.744,1,1,1,1,7.27358924252987,22.7789163589478,6.37990996197452,
72.912,72.912,1,1,1,1,7.29693452049494,22.7904081344604,6.38356730323396,
73.081,73.081,1,1,1,1,7.31094168727398,22.7794051170349,6.40883490601587,
73.25,73.25,1,1,1,1,7.32402230994701,22.7775931358337,6.42591044584641,
73.418,73.418,1,1,1,1,7.34513298153877,22.7898836135864,6.44033477089176,
73.587,73.587,1,1,1,1,7.36071163979173,22.7842211723328,6.46210238868747,
73.756,73.756,1,1,1,1,7.37549092665911,22.788667678833,6.47538230447302,
73.925,73.925,1,1,1,1,7.39394913865328,22.7909445762634,6.48855731607642,
74.093,74.093,1,1,1,1,7.41289787399769,22.7988481521606,6.50093600956988,
74.262,74.262,1,1,1,1,7.42596941290498,22.7936148643494,6.52432964218888,
74.43,74.43,1,1,1,1,7.44171157894134,22.7952718734741,6.53754280076761,
74.599,74.599,1,1,1,1,7.4609509947896,22.7988719940186,6.55370281319032,
74.768,74.768,1,1,1,1,7.47535784726143,22.8068828582764,6.57634781141853,
74.936,74.936,1,1,1,1,7.4918448820889,22.7982997894287,6.58955620162535,
75.105,75.105,1,1,1,1,7.50499817488789,22.7953553199768,6.61253498588767,
75.274,75.274,1,1,1,1,7.52833436908722,22.8055238723755,6.62628697049289,
75.442,75.442,1,1,1,1,7.5381266685605,22.7964401245117,6.64209412339382,
75.611,75.611,1,1,1,1,7.56200788870454,22.8097081184387,6.65549801684918,
75.78,75.78,1,1,1,1,7.57966672931313,22.809112071991,6.67266892411804,
75.948,75.948,1,1,1,1,7.58944994502068,22.8001594543457,6.69252442477551,
76.117,76.117,1,1,1,1,7.60964315627217,22.8087306022644,6.71023892644277,
76.286,76.286,1,1,1,1,7.62975461363196,22.8090882301331,6.72527360309334,
76.454,76.454,1,1,1,1,7.6441432985723,22.8092789649963,6.73587846223412,
76.625,76.625,1,1,1,1,7.65725117254257,22.8053331375122,6.76118898036327,
76.793,76.793,1,1,1,1,7.67748980262279,22.8164792060852,6.77413987848663,
76.962,76.962,1,1,1,1,7.69212374923825,22.8134155273438,6.78877401189628,
77.131,77.131,1,1,1,1,7.71097256315946,22.8240251541138,6.80262136393981,
77.299,77.299,1,1,1,1,7.72796828886866,22.8194236755371,6.81748914757333,
77.468,77.468,1,1,1,1,7.74654458981752,22.8267908096313,6.83336305768108,
77.637,77.637,1,1,1,1,7.76229583961964,22.8206157684326,6.85382890994377,
77.805,77.805,1,1,1,1,7.77821968097091,22.8145360946655,6.87818098531785,
77.977,77.977,1,1,1,1,7.79179991075993,22.8176474571228,6.88887167515311,
78.146,78.146,1,1,1,1,7.81410963943005,22.8245377540588,6.90296221416435,
78.314,78.314,1,1,1,1,7.83320371502638,22.82794713974,6.91586542856855,
78.483,78.483,1,1,1,1,7.846584101969,22.8226661682129,6.93272162329097,
78.652,78.652,1,1,1,1,7.87105576688647,22.8321433067322,6.94125224064836,
78.82,78.82,1,1,1,1,7.88324618051648,22.8271722793579,6.96546603323688,
78.989,78.989,1,1,1,1,7.89769845181704,22.8255033493042,6.98676635058484,
79.158,79.158,1,1,1,1,7.91828226499557,22.8373169898987,7.00164367096219,
79.326,79.326,1,1,1,1,7.93271636876464,22.835648059845,7.01540042393932,
79.495,79.495,1,1,1,1,7.94180921827555,22.8196859359741,7.04470683773394,
79.664,79.664,1,1,1,1,7.9659357000947,22.8339910507202,7.05019046543713,
79.832,79.832,1,1,1,1,7.97652737095356,22.8213548660278,7.07480480126657,
80.003,80.003,1,1,1,1,8.00159856441021,22.8273510932922,7.08295394887071,
80.171,80.171,1,1,1,1,8.0168229557991,22.8335857391357,7.10493614340262,
80.34,80.34,1,1,1,1,8.03164766149521,22.8275656700134,7.11944629914246,
80.509,80.509,1,1,1,1,8.04741707882881,22.8270769119263,7.13322212560725,
80.677,80.677,1,1,1,1,8.0690364413023,22.8376388549805,7.15277721883402,
80.846,80.846,1,1,1,1,8.09096465181112,22.8466868400574,7.16014435344396,
81.015,81.015,1,1,1,1,8.10136556358933,22.840678691864,7.18332817769866,
81.183,81.183,1,1,1,1,8.1180524412632,22.8306412696838,7.19391396335177,
81.352,81.352,1,1,1,1,8.13547510396242,22.8403806686401,7.22320607203064,
81.521,81.521,1,1,1,1,8.15225281929374,22.8405952453613,7.23185589868593,
81.689,81.689,1,1,1,1,8.16804948792458,22.8368401527405,7.24502614191742,
81.858,81.858,1,1,1,1,8.18628060577512,22.8367328643799,7.2650676090796,
82.027,82.027,1,1,1,1,8.19913413430452,22.8340864181519,7.2937684396409,
82.195,82.195,1,1,1,1,8.22227048565745,22.8441596031189,7.29858926364779,
82.364,82.364,1,1,1,1,8.243317570889,22.8464841842651,7.30924657487965,
82.533,82.533,1,1,1,1,8.25333696450591,22.8333115577698,7.33353666141882,
82.701,82.701,1,1,1,1,8.26987850192785,22.8403806686401,7.34530500330706,
82.87,82.87,1,1,1,1,8.28371307715774,22.8324055671692,7.3742585575799,
83.039,83.039,1,1,1,1,8.30486008381247,22.838294506073,7.37842611463432,
83.207,83.207,1,1,1,1,8.32181039069295,22.8430867195129,7.39878229434295,
83.376,83.376,1,1,1,1,8.33763431062102,22.83935546875,7.42014460052581,
83.534,83.534,1,1,1,1,8.35294953966737,22.8429555892944,7.42926172762885,
83.703,83.703,1,1,1,1,8.37149858931899,22.8394508361816,7.44832091017637,
83.872,83.872,1,1,1,1,8.38805829427242,22.8439092636108,7.45647482615242,
84.042,84.042,1,1,1,1,8.40264682205915,22.8457808494568,7.48764567336612,
84.21,84.21,1,1,1,1,8.42432068712711,22.8443741798401,7.48745017011757,
84.379,84.379,1,1,1,1,8.43712879682779,22.8452086448669,7.51654200717597,
84.548,84.548,1,1,1,1,8.46048315855861,22.8497982025146,7.52408080317488,
84.716,84.716,1,1,1,1,8.47713370116949,22.8413581848145,7.54161887508125,
84.885,84.885,1,1,1,1,8.48786162851453,22.8334307670593,7.56496482398109,
85.054,85.054,1,1,1,1,8.51109790129065,22.8428244590759,7.57465415571403,
85.222,85.222,1,1,1,1,8.5234154876411,22.8390574455261,7.59480529543028,
85.391,85.391,1,1,1,1,8.54508935270905,22.8411793708801,7.61061721670313,
85.56,85.56,1,1,1,1,8.55556293461323,22.8357434272766,7.62931877135696,
85.728,85.728,1,1,1,1,8.5731763563931,22.8355407714844,7.64804893624229,
85.897,85.897,1,1,1,1,8.58984506653547,22.8367805480957,7.66243988268423,
86.066,86.066,1,1,1,1,8.60891189083457,22.8336095809937,7.67717415190411,
86.234,86.234,1,1,1,1,8.62953203907609,22.8429317474365,7.68664413852892,
86.403,86.403,1,1,1,1,8.64085041119456,22.8317975997925,7.719379011731,
86.572,86.572,1,1,1,1,8.65581137337685,22.8341221809387,7.72678429331627,
86.741,86.741,1,1,1,1,8.67393348603844,22.8326916694641,7.7435260471127,
86.909,86.909,1,1,1,1,8.69328190707564,22.8276610374451,7.7682166768928,
87.078,87.078,1,1,1,1,8.70259276696443,22.8230118751526,7.78309876564207,
87.247,87.247,1,1,1,1,8.72469356902242,22.8256344795227,7.79220635600128,
87.415,87.415,1,1,1,1,8.73837372023463,22.8186368942261,7.81398827891273,
87.584,87.584,1,1,1,1,8.75967515090704,22.8261590003967,7.83184106336556,
87.753,87.753,1,1,1,1,8.775717081213,22.8276371955872,7.84242684901867,
87.921,87.921,1,1,1,1,8.78866144739986,22.8148460388184,7.87408407016778,
88.09,88.09,1,1,1,1,8.809508689785,22.8254199028015,7.88075025410609,
88.259,88.259,1,1,1,1,8.82299808191657,22.8180646896362,7.90107782358322,
88.427,88.427,1,1,1,1,8.84264626722336,22.8188157081604,7.91403825845041,
88.605,88.605,1,1,1,1,8.86673641397953,22.8242993354797,7.92119081632414,
88.774,88.774,1,1,1,1,8.87824554517865,22.8154897689819,7.94815119113617,
88.942,88.942,1,1,1,1,8.89501417674422,22.8153347969055,7.9735141613564,
89.111,89.111,1,1,1,1,8.91730573788285,22.8293776512146,7.98107679921489,
89.28,89.28,1,1,1,1,8.92865136129856,22.8103518486023,7.99733694744782,
89.448,89.448,1,1,1,1,8.94422093578577,22.8081703186035,8.01652487603707,
89.617,89.617,1,1,1,1,8.95573006698489,22.7935075759888,8.03937491425767,
89.786,89.786,1,1,1,1,8.9792842715621,22.8122353553772,8.05217799285164,
89.96,89.96,1,1,1,1,8.99598931676745,22.8017091751099,8.0713993000443,
90.129,90.129,1,1,1,1,9.01274886456728,22.80513048172,8.08136042897644,
90.298,90.298,1,1,1,1,9.03115257396698,22.7959036827087,8.09845504229464,
90.466,90.466,1,1,1,1,9.05163646572232,22.802722454071,8.11510619702468,
90.635,90.635,1,1,1,1,9.06825067327022,22.8009700775146,8.12797603282547,
90.804,90.804,1,1,1,1,9.08062276221514,22.7825284004211,8.15303382724309,
90.972,90.972,1,1,1,1,9.09486610690355,22.782301902771,8.1666952127819,
91.141,91.141,1,1,1,1,9.11432353312969,22.7853775024414,8.18416175910954,
91.31,91.31,1,1,1,1,9.13080148419142,22.776985168457,8.20568142156563,
91.478,91.478,1,1,1,1,9.14587145156264,22.7691531181335,8.21925697640996,
91.647,91.647,1,1,1,1,9.16518353753686,22.772216796875,8.2330471079905,
91.816,91.816,1,1,1,1,9.17739211869836,22.7597594261169,8.25434742533846,
91.984,91.984,1,1,1,1,9.20024687331319,22.7612495422363,8.26864300434208,
92.153,92.153,1,1,1,1,9.21677932696939,22.7600574493408,8.28507481396398,
92.322,92.322,1,1,1,1,9.23651834993362,22.7591395378113,8.30282746260657,
92.491,92.491,1,1,1,1,9.24943546482325,22.7504134178162,8.31535874400134,
92.665,92.665,1,1,1,1,9.26713972426057,22.7400541305542,8.33859978871903,
92.834,92.834,1,1,1,1,9.27904854115248,22.7303981781006,8.36096345300422,
93.003,93.003,1,1,1,1,9.30060431726575,22.7322816848755,8.37556420781045,
93.171,93.171,1,1,1,1,9.31778171828985,22.7308869361877,8.38702260552416,
93.34,93.34,1,1,1,1,9.33838369899988,22.7321267127991,8.398643127883,
93.509,93.509,1,1,1,1,9.34775814524889,22.7098822593689,8.42329561068778,
93.677,93.677,1,1,1,1,9.37376496657729,22.7190852165222,8.43165933502812,
93.846,93.846,1,1,1,1,9.38700909703374,22.7131128311157,8.45556795181403,
94.015,94.015,1,1,1,1,9.40622126158476,22.7060198783875,8.47040712521605,
94.183,94.183,1,1,1,1,9.41866602065563,22.6930260658264,8.49190294581256,
94.352,94.352,1,1,1,1,9.4377873475492,22.6914763450623,8.50061952967467,
94.521,94.521,1,1,1,1,9.45782613478303,22.687828540802,8.52397024694643,
94.698,94.698,1,1,1,1,9.47704738309979,22.6756811141968,8.53661596926718,
94.867,94.867,1,1,1,1,9.48860193312764,22.6715087890625,8.56255114411731,
95.036,95.036,1,1,1,1,9.50701472629309,22.6536870002747,8.57246935770221,
95.204,95.204,1,1,1,1,9.52180309692621,22.6522088050842,8.59513819779,
95.376,95.376,1,1,1,1,9.53603735784888,22.6432681083679,8.61136973579144,
95.545,95.545,1,1,1,1,9.5576022177279,22.6351022720337,8.63296569219818,
95.713,95.713,1,1,1,1,9.57223616434336,22.6266622543335,8.63948882497902,
95.882,95.882,1,1,1,1,9.59331050087213,22.6238250732422,8.66327823246703,
96.051,96.051,1,1,1,1,9.60654554756284,22.61563539505,8.68086398809256,
96.219,96.219,1,1,1,1,9.62300533109307,22.5982427597046,8.70071948875003,
96.388,96.388,1,1,1,1,9.64039165872931,22.5834250450134,8.7090927498342,
96.557,96.557,1,1,1,1,9.66128431994319,22.5844502449036,8.72850002353158,
96.725,96.725,1,1,1,1,9.67345656604171,22.5642919540405,8.74781192979064,
96.894,96.894,1,1,1,1,9.69142425468564,22.5555777549744,8.76462044079389,
97.063,97.063,1,1,1,1,9.71731298705935,22.5531220436096,8.77189697633743,
97.231,97.231,1,1,1,1,9.72506143923998,22.5192666053772,8.79812779024634,
97.4,97.4,1,1,1,1,9.74534548814893,22.5237607955933,8.81246628459721,
97.569,97.569,1,1,1,1,9.75889846664071,22.5010514259338,8.83109154530039,
97.737,97.737,1,1,1,1,9.78236183356047,22.4953770637512,8.84159150025902,
97.911,97.911,1,1,1,1,9.79179986616969,22.4684596061707,8.86647286491575,
98.079,98.079,1,1,1,1,9.81152072160244,22.4581360816956,8.88612332558083,
98.248,98.248,1,1,1,1,9.82659977273941,22.429347038269,8.90434327467117,
98.417,98.417,1,1,1,1,9.84032534278035,22.4161267280579,8.92466130740447,
98.585,98.585,1,1,1,1,9.85957384239435,22.4022269248962,8.93950048080649,
98.754,98.754,1,1,1,1,9.87852257773876,22.3863482475281,8.94974294368167,
98.923,98.923,1,1,1,1,9.895445633322,22.3723530769348,8.97621694455829,
99.091,99.091,1,1,1,1,9.91094253768325,22.337543964386,8.99625841172046,
99.265,99.265,1,1,1,1,9.92913732047081,22.3231911659241,9.00986734516821,
99.433,99.433,1,1,1,1,9.94953945833445,22.3074674606323,9.01922289086704,
99.602,99.602,1,1,1,1,9.96458217440843,22.294294834137,9.04041353566093,
99.771,99.771,1,1,1,1,9.98137805727124,22.2645998001099,9.05758444292979,
99.939,99.939,1,1,1,1,9.99251475407481,22.2346782684326,9.08062044765511,
100.108,100.108,1,1,1,1,10.0131349023163,22.2092628479004,9.09626070753899,
100.277,100.277,1,1,1,1,10.0310117533028,22.1819639205933,9.10909716473637,
100.445,100.445,1,1,1,1,10.0442831350565,22.1508383750916,9.13181845691524,
100.617,100.617,1,1,1,1,10.0683187792182,22.136926651001,9.14351527322473,
100.786,100.786,1,1,1,1,10.0811632239819,22.0988988876343,9.16166846510825,
100.954,100.954,1,1,1,1,10.0986040542126,22.068452835083,9.17846267099576,
101.123,101.123,1,1,1,1,10.1140373722136,22.033417224884,9.20318191100736,
101.292,101.292,1,1,1,1,10.1313601134896,22.0113277435303,9.22061507873158,
101.46,101.46,1,1,1,1,10.1542057843387,21.975564956665,9.23081939463143,
101.629,101.629,1,1,1,1,10.1666596271753,21.9276547431946,9.25304954450297,
101.798,101.798,1,1,1,1,10.1776964025557,21.8797445297241,9.27288597167277,
101.969,101.969,1,1,1,1,10.2005511571705,21.834933757782,9.28824489761362,
102.138,102.138,1,1,1,1,10.214721831733,21.8024134635925,9.30463379188828,
102.307,102.307,1,1,1,1,10.2292195218623,21.7612981796265,9.32740753615823,
102.475,102.475,1,1,1,1,10.2502302720308,21.7144370079041,9.34241837094922,
102.644,102.644,1,1,1,1,10.2589325196147,21.6521143913269,9.3658072351963,
102.799,102.799,1,1,1,1,10.3696091214538,-2.90064811706543,9.25609176578526,
102.962,102.962,1,1,1,1,10.2958761949003,-0.0170350074768066,9.45634908113384,
103.131,103.131,1,1,1,1,10.3156152178645,0.0251293182373047,9.45598668486824,
103.299,103.299,1,1,1,1,10.3333013097703,0.019383430480957,9.42244118844046,
103.468,103.468,1,1,1,1,10.3461639220655,0.0178933143615723,9.42239827309322,
103.637,103.637,1,1,1,1,10.3634139932156,0.0195741653442383,9.47727269710045,
103.805,103.805,1,1,1,1,10.3740329153717,0.0223517417907715,9.47993344862947,
103.974,103.974,1,1,1,1,10.3985499991179,0.017392635345459,9.49794358935552,
104.143,104.143,1,1,1,1,10.4161361696005,0.0189065933227539,9.52685899665303,
104.311,104.311,1,1,1,1,10.4290078656614,0.026237964630127,9.54271860164504,
104.48,104.48,1,1,1,1,10.4472298997462,0.0188231468200684,9.55745287086491,
104.649,104.649,1,1,1,1,10.4723192607343,0.020444393157959,9.56723280166426,
104.817,104.817,1,1,1,1,10.4830744393766,0.0208616256713867,9.59482736994109,
104.986,104.986,1,1,1,1,10.5042759486258,0.0234246253967285,9.60044451205792,
105.155,105.155,1,1,1,1,10.5167297914624,0.0182390213012695,9.62161131499224,
105.323,105.323,1,1,1,1,10.5332168262899,0.0243782997131348,9.6354682037796,
105.492,105.492,1,1,1,1,10.5534282050729,0.0246763229370117,9.65048380694251,
105.661,105.661,1,1,1,1,10.5652552680731,0.0189065933227539,9.67133112895846,
105.829,105.829,1,1,1,1,10.5820148158729,0.0191569328308105,9.68773909672079,
105.998,105.998,1,1,1,1,10.5994647298694,0.0257134437561035,9.70670768020191,
106.167,106.167,1,1,1,1,10.6201484644711,0.0187277793884277,9.721203530826,
106.335,106.335,1,1,1,1,10.6353637720942,0.0228166580200195,9.74399158021169,
106.504,106.504,1,1,1,1,10.6502248128533,0.0221610069274902,9.76061412471022,
106.62,0.0600000000000023,1,1,1,1,10.6625151479065,0.0211954116821289,9.77259704333467,
106.789,0.228999999999999,1,1,1,1,10.6815456371427,0.0227928161621094,9.78696414791703,
106.947,0.387,1,1,1,1,10.6991953939855,0.0248432159423828,9.79816505354728,
107.115,0.555000000000007,1,1,1,1,10.7105773524642,0.0213861465454102,9.81984684064851,
107.284,0.724000000000004,1,1,1,1,10.7311975007057,0.0226259231567383,9.83367035083246,
107.453,0.893000000000001,1,1,1,1,10.7445597201169,0.0269889831542969,9.85138485249972,
107.621,1.06100000000001,1,1,1,1,10.7666060195804,0.0279784202575684,9.86601421753745,
107.79,1.23,1,1,1,1,10.7788509358048,0.0225543975830078,9.88585541307916,
107.959,1.399,1,1,1,1,10.7974817393482,0.0223517417907715,9.90541050630593,
108.128,1.568,1,1,1,1,10.8169755006373,0.0246882438659668,9.91826126861906,
108.296,1.736,1,1,1,1,10.8314005206406,0.0207901000976563,9.93938038783421,
108.465,1.905,1,1,1,1,10.8472062730372,0.027918815612793,9.95596478535743,
108.634,2.074,1,1,1,1,10.8595147756219,0.0229597091674805,9.97120450200038,
108.802,2.242,1,1,1,1,10.8788086940646,0.0236272811889648,9.99040673570538,
108.971,2.411,1,1,1,1,10.8995469312608,0.0258445739746094,10.0067002625417,
109.14,2.58,1,1,1,1,10.9113104079008,0.0276327133178711,10.0217969280272,
109.308,2.748,1,1,1,1,10.9318942210793,0.024569034576416,10.0379855506814,
109.477,2.917,1,1,1,1,10.9446569119513,0.0222921371459961,10.0586612113084,
109.646,3.086,1,1,1,1,10.9690286554456,0.0278353691101074,10.0673777951705,
109.727,3.167,1,1,1,1,10.9701459586322,0.0286102294921875,10.0795800589031,