File: Copper.csv
"Total Time (s)","Cycle Elapsed Time (s)","Total Cycles","Elapsed Cycles","Step","Total Cycle Count(8800 (0,3) Waveform)","Position(8800 (0,3):Position) (mm)","Load(8800 (0,3):Load) (kN)","Extension mm from Extensometer (mm)",
0,0,1,1,1,1,-0.000926544106006622,-0.0226259231567383,0.00650405929317474,
0.079,0.079,1,1,1,1,-0.000417853224277496,-0.0035703182220459,-0.00186204923312664,
0.194,0.194,1,1,1,1,0.0393417894423008,1.16927623748779,0.0184106839669704,
0.307,0.307,1,1,1,1,0.0589990585148334,1.75353288650513,0.0136852273983955,
0.419,0.419,1,1,1,1,0.0760492868185043,2.18422412872314,0.0358629251788616,
0.53,0.53,1,1,1,1,0.0960063201606274,2.73998975753784,0.0383424785750866,
0.641,0.641,1,1,1,1,0.118061703389883,3.36623191833496,0.0521564520152092,
0.752,0.752,1,1,1,1,0.141043630725145,3.98443937301636,0.0625038190725326,
0.863,0.863,1,1,1,1,0.163980139231682,4.56784963607788,0.0735473684295654,
0.974,0.974,1,1,1,1,0.18588109844327,5.10290861129761,0.0770425850438595,
1.084,1.084,1,1,1,1,0.21012566921711,5.66666126251221,0.093050009565258,
1.195,1.195,1,1,1,1,0.230891157710552,6.18623495101929,0.109372146633101,
1.306,1.306,1,1,1,1,0.253809498685598,6.69753551483154,0.113554008803272,
1.417,1.417,1,1,1,1,0.275574201411009,7.20961093902588,0.122771271716547,
1.527,1.527,1,1,1,1,0.300890656542778,7.70509243011475,0.128321656626558,
1.638,1.638,1,1,1,1,0.321783317756653,8.11084508895874,0.142726908184242,
1.749,1.749,1,1,1,1,0.344719826263189,8.55132341384888,0.163626682291269,
1.86,1.86,1,1,1,1,0.367002303636074,8.92786979675293,0.173625958198738,
1.971,1.971,1,1,1,1,0.38851266092062,9.30650234222412,0.171937954540539,
2.087,2.087,1,1,1,1,0.410023018205166,9.66566801071167,0.173678410289812,
2.204,2.204,1,1,1,1,0.435920834344625,9.97308492660522,0.210909858208513,
2.321,2.321,1,1,1,1,0.458875510382652,10.2764129638672,0.218729988150454,
2.438,2.438,1,1,1,1,0.485881545943022,10.5521202087402,0.224156395390654,
2.555,2.555,1,1,1,1,0.508327531099319,10.7789993286133,0.252132433420753,
2.672,2.672,1,1,1,1,0.533625818699598,10.9795451164246,0.266089458018351,
2.789,2.789,1,1,1,1,0.557570625203848,11.1371040344238,0.275855083701944,
2.906,2.906,1,1,1,1,0.583750038081407,11.2823724746704,0.296211263410568,
3.023,3.023,1,1,1,1,0.606722881650925,11.394989490509,0.326085113463163,
3.14,3.14,1,1,1,1,0.630922033596039,11.4906072616577,0.339756035745811,
3.257,3.257,1,1,1,1,0.655339195919037,11.5735292434692,0.365700747339773,
3.374,3.374,1,1,1,1,0.678411960911751,11.6276860237122,0.377101924590492,
3.491,3.491,1,1,1,1,0.703219725161791,11.6796374320984,0.411109953094101,
3.608,3.608,1,1,1,1,0.725929139524698,11.7201924324036,0.431976348597717,
3.725,3.725,1,1,1,1,0.747811931204796,11.7439866065979,0.439777405051994,
3.843,3.843,1,1,1,1,0.771811240303516,11.7737054824829,0.472421679187679,
3.96,3.96,1,1,1,1,0.793930209892988,11.7985606193542,0.498881374948549,
4.076,4.076,1,1,1,1,0.817030226182938,11.8206143379211,0.493774448626709,
4.193,4.193,1,1,1,1,0.842728199476004,11.8439555168152,0.545468368566084,
4.31,4.31,1,1,1,1,0.86596447225213,11.855137348175,0.558528939243507,
4.427,4.427,1,1,1,1,0.888755640506744,11.865770816803,0.571198503423834,
4.544,4.544,1,1,1,1,0.912246258723736,11.8780851364136,0.591931384513807,
4.661,4.661,1,1,1,1,0.935237269824743,11.8847012519836,0.641365096165085,
4.778,4.778,1,1,1,1,0.955966423255205,11.9067549705505,0.641512915694475,
4.895,4.895,1,1,1,1,0.979547879129648,11.903965473175,0.667958306339598,
5.012,5.012,1,1,1,1,1.00332917785048,11.9140982627869,0.686335611703157,
5.129,5.129,1,1,1,1,1.02649278050065,11.9257211685181,0.720782330423021,
5.246,5.246,1,1,1,1,1.04981989093423,11.9316101074219,0.735564283362055,
5.363,5.363,1,1,1,1,1.07547244539857,11.9354128837585,0.756440215609503,
5.48,5.48,1,1,1,1,1.09744607473612,11.9456171989441,0.792694147285461,
5.597,5.597,1,1,1,1,1.12148171889782,11.9527578353882,0.79962736005106,
5.714,5.714,1,1,1,1,1.14607147276998,11.9634747505188,0.826864300434208,
5.831,5.831,1,1,1,1,1.16742740603685,11.9588255882263,0.843424856097841,
5.948,5.948,1,1,1,1,1.1891194386363,11.965024471283,0.87221151735363,
6.065,6.065,1,1,1,1,1.21322775292397,11.9734287261963,0.902681413895702,
6.182,6.182,1,1,1,1,1.23565557054877,11.9786262512207,0.928225582248735,
6.299,6.299,1,1,1,1,1.25925519395471,11.9865536689758,0.942821568683052,
6.416,6.416,1,1,1,1,1.28312733033299,11.9831442832947,0.960578985697556,
6.534,6.534,1,1,1,1,1.30543705900311,11.9878768920898,0.988860199530268,
6.651,6.651,1,1,1,1,1.32746519093513,11.9982838630676,1.01546771482053,
6.768,6.768,1,1,1,1,1.3512919084847,11.998462677002,1.02941520267429,
6.885,6.885,1,1,1,1,1.37614509156346,12.0057344436646,1.05367191061006,
7.002,7.002,1,1,1,1,1.39882725462914,12.0124697685242,1.08521469083319,
7.119,7.119,1,1,1,1,1.42514292399287,12.0108366012573,1.09648235367026,
7.236,7.236,1,1,1,1,1.44786142212152,12.0195031166077,1.12864502224245,
7.353,7.353,1,1,1,1,1.47088876828551,12.017822265625,1.15680225840535,
7.47,7.47,1,1,1,1,1.49406145470142,12.026584148407,1.1761093962925,
7.587,7.587,1,1,1,1,1.51688895801902,12.0314121246338,1.20199211905155,
7.704,7.704,1,1,1,1,1.54268685273528,12.0253443717957,1.22073182068071,
7.821,7.821,1,1,1,1,1.56412453989387,12.0278477668762,1.24719151644158,
7.938,7.938,1,1,1,1,1.58755157175064,12.0345234870911,1.25531205381422,
8.056,8.056,1,1,1,1,1.61185064511895,12.034797668457,1.29264363754315,
8.174,8.174,1,1,1,1,1.63584087045193,12.0393037796021,1.30174645953045,
8.293,8.293,1,1,1,1,1.65846853092313,12.0438575744629,1.33469114109683,
8.413,8.413,1,1,1,1,1.68240425366163,12.0430588722229,1.36967191747127,
8.533,8.533,1,1,1,1,1.70807497565746,12.0451927185059,1.39897356289396,
8.652,8.652,1,1,1,1,1.73115682441592,12.0457530021667,1.42090330533481,
8.772,8.772,1,1,1,1,1.75167705123425,12.050986289978,1.44527922256846,
8.891,8.891,1,1,1,1,1.77980947374701,12.0659708976746,1.45070086143675,
9.011,9.011,1,1,1,1,1.8030366627574,12.0634436607361,1.48559103874478,
9.13,9.13,1,1,1,1,1.82522830247283,12.0625615119934,1.5117026433558,
9.249,9.249,1,1,1,1,1.84914585767984,12.0565891265869,1.52462969961958,
9.369,9.369,1,1,1,1,1.87498008745909,12.0693564414978,1.54879580848894,
9.488,9.488,1,1,1,1,1.89742607261538,12.073814868927,1.57845985017724,
9.608,9.608,1,1,1,1,1.92334205628634,12.0737552642822,1.60404693387752,
9.727,9.727,1,1,1,1,1.94643298881054,12.0736002922058,1.62413608475885,
9.847,9.847,1,1,1,1,1.9690333979845,12.081241607666,1.65457260269752,
9.966,9.966,1,1,1,1,1.99402283754945,12.0861172676086,1.67082798255854,
10.086,10.086,1,1,1,1,2.01790405769348,12.0932936668396,1.69025432974358,
10.206,10.206,1,1,1,1,2.04197603691816,12.0810031890869,1.72249806063833,
10.325,10.325,1,1,1,1,2.06389516366124,12.0848655700684,1.7419339445672,
10.445,10.445,1,1,1,1,2.09003824147582,12.091326713562,1.75641549007554,
10.565,10.565,1,1,1,1,2.11299291751385,12.0954036712646,1.79463399098082,
10.684,10.684,1,1,1,1,2.13753725255728,12.0917320251465,1.8110276536274,
10.803,10.803,1,1,1,1,2.16179090709686,12.09956407547,1.8232680643353,
10.923,10.923,1,1,1,1,2.18430956237912,12.0969414710999,1.87061322908745,
11.042,11.042,1,1,1,1,2.20721881958842,12.0983123779297,1.89423097518649,
11.162,11.162,1,1,1,1,2.23260794484615,12.1044754981995,1.90490259153409,
11.281,11.281,1,1,1,1,2.25503576247096,12.1095061302185,1.93491472437224,
11.4,11.4,1,1,1,1,2.28000703450441,12.1087789535522,1.94843305875359,
11.52,11.52,1,1,1,1,2.3029344592452,12.106728553772,1.97513117311025,
11.639,11.639,1,1,1,1,2.32627973721027,12.1141195297241,2.01059355504818,
11.759,11.759,1,1,1,1,2.35178695142269,12.1124267578125,2.02918543714795,
11.879,11.879,1,1,1,1,2.3747779625237,12.1225118637085,2.0506049637938,
11.998,11.998,1,1,1,1,2.40171132795811,12.1235370635986,2.06502452046723,
12.118,12.118,1,1,1,1,2.42225880607367,12.1218919754028,2.09862246898608,
12.238,12.238,1,1,1,1,2.44721191057563,12.1181845664978,2.11922183566241,
12.357,12.357,1,1,1,1,2.46966697949767,12.1193289756775,2.14299693803468,
12.477,12.477,1,1,1,1,2.4925217341125,12.1204257011414,2.16740146549983,
12.596,12.596,1,1,1,1,2.51850130414367,12.1225357055664,2.20180050050054,
12.715,12.715,1,1,1,1,2.5413560587585,12.1286869049072,2.21834675104842,
12.835,12.835,1,1,1,1,2.56713578594327,12.1287107467651,2.24323765244899,
12.954,12.954,1,1,1,1,2.59108967621326,12.1323823928833,2.26813332222147,
13.074,13.074,1,1,1,1,2.61517073920369,12.1359825134277,2.28938595585027,
13.193,13.193,1,1,1,1,2.6377802321434,12.1354818344116,2.31888787289343,
13.312,13.312,1,1,1,1,2.66239723731279,12.1370434761047,2.33592049737673,
13.432,13.432,1,1,1,1,2.68779544633627,12.1400475502014,2.36033932995763,
13.552,13.552,1,1,1,1,2.7133662469089,12.1451735496521,2.37584607542787,
13.671,13.671,1,1,1,1,2.73484935289621,12.1443390846252,2.40900056535854,
13.791,13.791,1,1,1,1,2.75772227504253,12.1401190757751,2.42483632849097,
13.911,13.911,1,1,1,1,2.78005925500989,12.1386885643005,2.4632503326448,
14.03,14.03,1,1,1,1,2.80504869457483,12.1436953544617,2.47910040089297,
14.15,14.15,1,1,1,1,2.82805787320733,12.1391534805298,2.50609415430841,
14.269,14.269,1,1,1,1,2.85311089913249,12.1540784835815,2.52385157132292,
14.389,14.389,1,1,1,1,2.87742814003229,12.1463656425476,2.54514235192704,
14.508,14.508,1,1,1,1,2.90258108738065,12.1594905853271,2.5680400738668,
14.628,14.628,1,1,1,1,2.92926919113994,12.1537566184998,2.59276885062222,
14.747,14.747,1,1,1,1,2.94751847652197,12.1566653251648,2.62364882714906,
14.866,14.866,1,1,1,1,2.97376147575974,12.1604681015015,2.63587970111313,
14.986,14.986,1,1,1,1,2.99734293163419,12.1612787246704,2.66690749716935,
15.105,15.105,1,1,1,1,3.02235962249637,12.1572494506836,2.6916410422967,
15.225,15.225,1,1,1,1,3.04255283374786,12.156617641449,2.72563476568456,
15.344,15.344,1,1,1,1,3.06771486486197,12.1626257896423,2.74523754263048,
15.464,15.464,1,1,1,1,3.09232278626561,12.15660572052,2.76978035288119,
15.584,15.584,1,1,1,1,3.11455984480977,12.1607542037964,2.78805752243452,
15.703,15.703,1,1,1,1,3.13860457273722,12.1602535247803,2.80416508276615,
15.823,15.823,1,1,1,1,3.16299448376298,12.1615529060364,2.83720990014276,
15.943,15.943,1,1,1,1,3.18790216943622,12.1657609939575,2.86937256871495,
16.068,16.068,1,1,1,1,3.21504446148276,12.1743083000183,2.88417359514165,
16.186,16.186,1,1,1,1,3.23504691365361,12.1688723564148,2.91116258018517,
16.303,16.303,1,1,1,1,3.26103556745052,12.1742010116577,2.93332120447798,
16.42,16.42,1,1,1,1,3.2842809239924,12.1809959411621,2.96463987122107,
16.538,16.538,1,1,1,1,3.30738094028234,12.1748447418213,2.97719976284733,
16.655,16.655,1,1,1,1,3.32884587873816,12.1712446212769,3.01317712895217,
16.772,16.772,1,1,1,1,3.35488903512955,12.1749639511108,3.02499792293148,
16.89,16.89,1,1,1,1,3.38118653696179,12.1747851371765,3.04308435760818,
17.007,17.007,1,1,1,1,3.40104364888072,12.1738195419312,3.07261011651092,
17.125,17.125,1,1,1,1,3.42364405805469,12.1769666671753,3.09433958733129,
17.242,17.242,1,1,1,1,3.4497144657433,12.1831059455872,3.10266993306823,
17.365,17.365,1,1,1,1,3.47220586972833,12.1790885925293,3.13685915970464,
17.483,17.483,1,1,1,1,3.49673203724027,12.1767997741699,3.16124461368213,
17.6,17.6,1,1,1,1,3.52263893714547,12.1871113777161,3.17969821299634,
17.718,17.718,1,1,1,1,3.54243246270418,12.1789216995239,3.21298144896874,
17.835,17.835,1,1,1,1,3.56919323658943,12.1821761131287,3.23266528823724,
17.952,17.952,1,1,1,1,3.59048558349609,12.1809959411621,3.25436614882612,
18.07,18.07,1,1,1,1,3.61691934181452,12.1868968009949,3.27800773678474,
18.187,18.187,1,1,1,1,3.63624051155448,12.1811151504517,3.31227802574372,
18.304,18.304,1,1,1,1,3.65737843444347,12.1846675872803,3.34550880962505,
18.422,18.422,1,1,1,1,3.68325808305144,12.188982963562,3.35915112167621,
18.539,18.539,1,1,1,1,3.70771158043742,12.190580368042,3.37923550418563,
18.658,18.658,1,1,1,1,3.73112044476271,12.1901750564575,3.40624356271682,
18.775,18.775,1,1,1,1,3.75393886431456,12.1913313865662,3.42302346348858,
18.893,18.893,1,1,1,1,3.78020003108382,12.1917724609375,3.44890141787572,
19.01,19.01,1,1,1,1,3.80227358184457,12.1901750564575,3.47511792666888,
19.128,19.128,1,1,1,1,3.82783529865146,12.2002482414246,3.48826909641271,
19.245,19.245,1,1,1,1,3.84849178195596,12.19402551651,3.52347398626718,
19.362,19.362,1,1,1,1,3.8699203853488,12.1885180473328,3.54260469439344,
19.48,19.48,1,1,1,1,3.89680833195448,12.2029781341553,3.56343294292173,
19.597,19.597,1,1,1,1,3.91985384564996,12.2030138969421,3.58628298114233,
19.715,19.715,1,1,1,1,3.9410826061964,12.193775177002,3.60947157376895,
19.832,19.832,1,1,1,1,3.96658073664308,12.2027397155762,3.63475825003853,
19.949,19.949,1,1,1,1,3.98788216731548,12.1915817260742,3.66509463216696,
20.067,20.067,1,1,1,1,4.01219032444954,12.1948599815369,3.67555167177835,
20.184,20.184,1,1,1,1,4.03700717246532,12.1977567672729,3.70276953867383,
20.301,20.301,1,1,1,1,4.05982559201717,12.2036695480347,3.72467067088318,
20.419,20.419,1,1,1,1,4.08205356679559,12.1998190879822,3.76159694299927,
20.536,20.536,1,1,1,1,4.11002248152494,12.2019529342651,3.77859618887916,
20.655,20.655,1,1,1,1,4.12848977728486,12.2017502784729,3.79739787934322,
20.772,20.772,1,1,1,1,4.15458743627071,12.2021198272705,3.82092025800395,
20.89,20.89,1,1,1,1,4.17863216419816,12.209153175354,3.85240104939218,
21.007,21.007,1,1,1,1,4.20263147329688,12.1980547904968,3.87881306143389,
21.125,21.125,1,1,1,1,4.22466868899465,12.202513217926,3.89896420115013,
21.242,21.242,1,1,1,1,4.24336307889819,12.1982097625732,3.92982987256122,
21.359,21.359,1,1,1,1,4.26901563336253,12.1988534927368,3.95211724289575,
21.477,21.477,1,1,1,1,4.29488619820475,12.2010946273804,3.96442917918239,
21.594,21.594,1,1,1,1,4.3172413457036,12.2045516967773,4.00577096369252,
21.711,21.711,1,1,1,1,4.34308465924859,12.2057437896729,4.01645688515587,
21.829,21.829,1,1,1,1,4.36549430934191,12.2027993202209,4.03452901471682,
21.946,21.946,1,1,1,1,4.38963895869255,12.2128963470459,4.06751661163044,
22.064,22.064,1,1,1,1,4.41550043976903,12.2151374816895,4.07634763641853,
22.181,22.181,1,1,1,1,4.43805543011427,12.2128963470459,4.1006043443543,
22.298,22.298,1,1,1,1,4.46005631074905,12.2068762779236,4.13375406591306,
22.416,22.416,1,1,1,1,4.48797980664969,12.215793132782,4.13909941083069,
22.533,22.533,1,1,1,1,4.50668328031898,12.2022032737732,4.17511015553894,
22.65,22.65,1,1,1,1,4.53080067837238,12.2100830078125,4.20280962799792,
22.768,22.768,1,1,1,1,4.55019451823831,12.2036099433899,4.23034220743985,
22.885,22.885,1,1,1,1,4.57677361680865,12.2076272964478,4.24936324301205,
23.003,23.003,1,1,1,1,4.60349805563092,12.217903137207,4.25687342877946,
23.12,23.12,1,1,1,1,4.62408186880946,12.2097373008728,4.28812056994381,
23.237,23.237,1,1,1,1,4.64693662342429,12.2144341468811,4.31087524072609,
23.355,23.355,1,1,1,1,4.66714800220728,12.2081637382507,4.35041934902396,
23.472,23.472,1,1,1,1,4.69384518973231,12.2173428535461,4.36731845909362,
23.589,23.589,1,1,1,1,4.7168725358963,12.209951877594,4.38483745751233,
23.707,23.707,1,1,1,1,4.74049941059947,12.212598323822,4.41917927205005,
23.824,23.824,1,1,1,1,4.76395369375348,12.2169494628906,4.44135696983051,
23.942,23.942,1,1,1,1,4.79013310663104,12.2162103652954,4.44859535839872,
24.06,24.06,1,1,1,1,4.81231566258073,12.2105956077576,4.47753460755582,
24.178,24.178,1,1,1,1,4.83613329636455,12.2204899787903,4.50794251526299,
24.295,24.295,1,1,1,1,4.85939682043791,12.2170805931091,4.53101189859171,
24.413,24.413,1,1,1,1,4.88376856393218,12.2200846672058,4.54935582535186,
24.53,24.53,1,1,1,1,4.90740452240109,12.2158527374268,4.57532914717731,
24.647,24.647,1,1,1,1,4.92951440822482,12.2140765190125,4.60454973027744,
24.765,24.765,1,1,1,1,4.94958044675589,12.2083187103271,4.62780508011088,
24.882,24.882,1,1,1,1,4.97604145637155,12.2169733047485,4.64232477259455,
25,25,1,1,1,1,4.9938728885293,12.2113108634949,4.67715772943959,
25.117,25.117,1,1,1,1,5.02569331993461,12.2179627418518,4.69036135127449,
25.234,25.234,1,1,1,1,5.04599553637505,12.2097373008728,4.71634420984378,
25.352,25.352,1,1,1,1,5.06934989810586,12.2099876403809,4.73938021456909,
25.469,25.469,1,1,1,1,5.09328562084436,12.2173547744751,4.75821528363657,
25.586,25.586,1,1,1,1,5.12001914343238,12.2202038764954,4.78736434115796,
25.704,25.704,1,1,1,1,5.14096630724072,12.216591835022,4.8076346901721,
25.821,25.821,1,1,1,1,5.1638301456213,12.2194647789001,4.83375106315503,
25.939,25.939,1,1,1,1,5.18890133907795,12.2191905975342,4.85756431250262,
26.056,26.056,1,1,1,1,5.21175609369278,12.2197151184082,4.87877403078418,
26.173,26.173,1,1,1,1,5.23703621376157,12.2231125831604,4.89695583289919,
26.291,26.291,1,1,1,1,5.25821955547929,12.2182488441467,4.9275878540864,
26.408,26.408,1,1,1,1,5.28232786976695,12.2204065322876,4.94790111844778,
26.525,26.525,1,1,1,1,5.30224856804609,12.2173070907593,4.97230087754102,
26.643,26.643,1,1,1,1,5.32829172443748,12.2168779373169,4.99435459765167,
26.76,26.76,1,1,1,1,5.35100113880038,12.2156620025635,5.02026593064222,
26.878,26.878,1,1,1,1,5.374255579108,12.2191429138184,5.04054581640019,
26.995,26.995,1,1,1,1,5.39827305573821,12.2125029563904,5.06431138202863,
27.112,27.112,1,1,1,1,5.42623288670182,12.2240424156189,5.07291352496476,
27.23,27.23,1,1,1,1,5.44584473694563,12.2215151786804,5.11501348060951,
27.347,27.347,1,1,1,1,5.46888116687536,12.2186303138733,5.13628518772597,
27.464,27.464,1,1,1,1,5.49455188887119,12.222957611084,5.1503423481338,
27.582,27.582,1,1,1,1,5.5164165130198,12.2194528579712,5.18811262207899,
27.699,27.699,1,1,1,1,5.53849914754629,12.2148394584656,5.20422971915445,
27.817,27.817,1,1,1,1,5.55871052632928,12.2163891792297,5.23202455905175,
27.934,27.934,1,1,1,1,5.58685203260779,12.221097946167,5.25631941396284,
28.051,28.051,1,1,1,1,5.61100576572418,12.2247099876404,5.27750529038482,
28.169,28.169,1,1,1,1,5.62887353294492,12.2087478637695,5.30112780485578,
28.286,28.286,1,1,1,1,5.65700595545769,12.2204661369324,5.31973399207129,
28.403,28.403,1,1,1,1,5.68182280347347,12.2245192527771,5.34315623492179,
28.521,28.521,1,1,1,1,5.70460488796234,12.2165560722351,5.36807097818193,
28.638,28.638,1,1,1,1,5.72665118742585,12.2240662574768,5.39982356676936,
28.745,28.745,1,1,1,1,5.74906992128491,12.2150421142578,5.40749587718191,
28.862,28.862,1,1,1,1,5.77142506878376,12.2155070304871,5.44006385736694,
28.98,28.98,1,1,1,1,5.79628733562827,12.2186422348022,5.46763935215611,
29.097,29.097,1,1,1,1,5.81744342604876,12.2150182723999,5.49197235404253,
29.214,29.214,1,1,1,1,5.84137914878726,12.2195243835449,5.51378765555739,
29.332,29.332,1,1,1,1,5.86844877070785,12.2145056724548,5.52736321040172,
29.449,29.449,1,1,1,1,5.88845122287869,12.218177318573,5.54862061240244,
29.567,29.567,1,1,1,1,5.91315906570554,12.2208714485168,5.57069817437267,
29.684,29.684,1,1,1,1,5.93618641186953,12.2205138206482,5.59492150370502,
29.801,29.801,1,1,1,1,5.95965886255503,12.2204422950745,5.62378922728338,
29.919,29.919,1,1,1,1,5.9823410256207,12.2149229049683,5.64831296404643,
30.044,30.044,1,1,1,1,6.0062767483592,12.2185587882996,5.67778150248618,
30.161,30.161,1,1,1,1,6.03216548073292,12.2175931930542,5.68733731980548,
30.278,30.278,1,1,1,1,6.05684607226253,12.2242450714111,5.70788423439074,
30.396,30.396,1,1,1,1,6.07990066972375,12.2169017791748,5.73545019243607,
30.513,30.513,1,1,1,1,6.10305518860817,12.2162461280823,5.76415102299738,
30.631,30.631,1,1,1,1,6.12374800697565,12.2145652770996,5.79954187935657,
30.748,30.748,1,1,1,1,6.14933697507978,12.2210025787354,5.81842940051513,
30.865,30.865,1,1,1,1,6.17056573562622,12.2176170349121,5.83669226495271,
30.983,30.983,1,1,1,1,6.19705399653912,12.2190952301025,5.85261862715154,
31.1,31.1,1,1,1,1,6.2201812641263,12.2201442718506,5.88463347619433,
31.217,31.217,1,1,1,1,6.24225481488705,12.2170686721802,5.91550391597734,
31.335,31.335,1,1,1,1,6.26727150574922,12.2182846069336,5.93019050147805,
31.452,31.452,1,1,1,1,6.28780081633329,12.2070789337158,5.95339816759233,
31.57,31.57,1,1,1,1,6.31425274218321,12.2185349464417,5.97123664692941,
31.687,31.687,1,1,1,1,6.33911500902772,12.2197270393372,5.99833053615508,
31.804,31.804,1,1,1,1,6.35772764503956,12.2114300727844,6.02501434539599,
31.922,31.922,1,1,1,1,6.38093666651845,12.2183442115784,6.04880375288401,
32.041,32.041,1,1,1,1,6.40940518836379,12.2164845466614,6.06927914189053,
32.159,32.159,1,1,1,1,6.42978915869594,12.2113347053528,6.09693093063035,
32.276,32.276,1,1,1,1,6.45557796964645,12.2125148773193,6.11796421915102,
32.394,32.394,1,1,1,1,6.48379214605093,12.2265338897705,6.13416237854905,
32.511,32.511,1,1,1,1,6.49782656412721,12.2114658355713,6.17578549700222,
32.629,32.629,1,1,1,1,6.52537762563229,12.2203707695007,6.18588490871992,
32.746,32.746,1,1,1,1,6.54972211782932,12.2154951095581,6.20288892297173,
32.863,32.863,1,1,1,1,6.57368509186506,12.2161865234375,6.23674913194594,
32.98,32.98,1,1,1,1,6.59847468858361,12.2175812721252,6.25261827368178,
33.098,33.098,1,1,1,1,6.6196307790041,12.2238278388977,6.28145261865673,
33.215,33.215,1,1,1,1,6.64180425118804,12.2122526168823,6.31244226773763,
33.333,33.333,1,1,1,1,6.66831976339817,12.2150897979736,6.32884546712804,
33.45,33.45,1,1,1,1,6.68896716293693,12.2116804122925,6.35083243003187,
33.568,33.568,1,1,1,1,6.71194909027219,12.2194409370422,6.37724444207358,
33.685,33.685,1,1,1,1,6.73402264103293,12.2099876403809,6.39704272226806,
33.802,33.802,1,1,1,1,6.75822179297805,12.2106671333313,6.41362711979127,
33.919,33.919,1,1,1,1,6.78255720140934,12.218976020813,6.4398627020721,
34.037,34.037,1,1,1,1,6.80925438893437,12.2116804122925,6.47149131298971,
34.154,34.154,1,1,1,1,6.83011979885101,12.2188210487366,6.49620578462939,
34.272,34.272,1,1,1,1,6.85187541781068,12.2094392776489,6.51581332994723,
34.389,34.389,1,1,1,1,6.87741896708608,12.2081995010376,6.53099105775528,
34.507,34.507,1,1,1,1,6.89979228211641,12.214982509613,6.55450389967217,
34.624,34.624,1,1,1,1,6.9254539203465,12.2191429138184,6.57997177407455,
34.741,34.741,1,1,1,1,6.94701878022551,12.2066736221313,6.60630749216561,
34.858,34.858,1,1,1,1,6.97017329910994,12.2098326683044,6.63527058318229,
34.976,34.976,1,1,1,1,6.99599844512343,12.21022605896,6.65436314433322,
35.093,35.093,1,1,1,1,7.01771772902012,12.2066378593445,6.67332219107051,
35.211,35.211,1,1,1,1,7.04290701143145,12.2099876403809,6.70294808578348,
35.333,35.333,1,1,1,1,7.06647029977441,12.212061882019,6.72895001784043,
35.45,35.45,1,1,1,1,7.08942497581243,12.2161269187927,6.75139474444818,
35.568,35.568,1,1,1,1,7.11561347245574,12.2112631797791,6.77119302464266,
35.685,35.685,1,1,1,1,7.13464396169186,12.2085928916931,6.80173444676347,
35.802,35.802,1,1,1,1,7.16189525892734,12.2063636779785,6.82548093890424,
35.919,35.919,1,1,1,1,7.18368721294999,12.2124433517456,6.84397268519378,
36.046,36.046,1,1,1,1,7.20952144272923,12.2077107429504,6.8654732741622,
36.163,36.163,1,1,1,1,7.23657289711833,12.2117519378662,6.88550043620863,
36.281,36.281,1,1,1,1,7.25643000903726,12.2033953666687,6.91095400549526,
36.398,36.398,1,1,1,1,7.27728633518815,12.2035026550293,6.94355059591179,
36.516,36.516,1,1,1,1,7.30199417801499,12.203574180603,6.96206618406091,
36.633,36.633,1,1,1,1,7.32578456050157,12.2086644172668,6.98236514330654,
36.751,36.751,1,1,1,1,7.35397148560882,12.2087597846985,7.00077582727351,
36.868,36.868,1,1,1,1,7.37377409493327,12.2074723243713,7.03250934237327,
36.985,36.985,1,1,1,1,7.39661068201661,12.2063159942627,7.05523540292406,
37.102,37.102,1,1,1,1,7.41733075168133,12.2036814689636,7.08113719917078,
37.22,37.22,1,1,1,1,7.44443670866489,12.2052431106567,7.10506965781627,
37.337,37.337,1,1,1,1,7.46661018084884,12.2074604034424,7.13120033591495,
37.455,37.455,1,1,1,1,7.48991912375092,12.2029542922974,7.15050747380209,
37.572,37.572,1,1,1,1,7.51200175827742,12.2008800506592,7.17546990078139,
37.69,37.69,1,1,1,1,7.53311242986918,12.1958255767822,7.20085194448929,
37.807,37.807,1,1,1,1,7.56237123933434,12.2028231620789,7.21752217270698,
37.924,37.924,1,1,1,1,7.58175599543452,12.192165851593,7.25723794239383,
38.044,38.044,1,1,1,1,7.60744488496184,12.1960043907166,7.26863911964455,
38.162,38.162,1,1,1,1,7.62740191830397,12.1953368186951,7.29823163575411,
38.279,38.279,1,1,1,1,7.65552525705099,12.1984958648682,7.31449178398704,
38.397,38.397,1,1,1,1,7.67603640010357,12.1960520744324,7.34182409180851,
38.514,38.514,1,1,1,1,7.70187062988281,12.1966481208801,7.3584609414228,
38.632,38.632,1,1,1,1,7.72621512207985,12.196946144104,7.38083414245181,
38.749,38.749,1,1,1,1,7.7474257150948,12.193751335144,7.40906290419345,
38.866,38.866,1,1,1,1,7.77469517986178,12.2010231018066,7.43079237501383,
38.983,38.983,1,1,1,1,7.79640537999272,12.1910691261292,7.44811110181208,
39.101,39.101,1,1,1,1,7.82223052600622,12.1980786323547,7.47760825048332,
39.218,39.218,1,1,1,1,7.84343203525543,12.1942043304443,7.50193171562591,
39.342,39.342,1,1,1,1,7.86234443553686,12.1869325637817,7.52976947087045,
39.459,39.459,1,1,1,1,7.89766211675405,12.1997475624084,7.54403643964257,
39.577,39.577,1,1,1,1,7.9134406178534,12.1936917304993,7.57640891657906,
39.694,39.694,1,1,1,1,7.93392450960874,12.1917486190796,7.60000758919043,
39.811,39.811,1,1,1,1,7.96183892174363,12.1972918510437,7.61522823234572,
39.928,39.928,1,1,1,1,7.98278608555198,12.1997117996216,7.64189296809897,
40.046,40.046,1,1,1,1,8.00769377122521,12.1900677680969,7.66383224728365,
40.163,40.163,1,1,1,1,8.03330090686083,12.1965646743774,7.69340092153363,
40.281,40.281,1,1,1,1,8.05384838497639,12.1873736381531,7.71836811688485,
40.398,40.398,1,1,1,1,8.0797371173501,12.1902465820313,7.73665959155393,
40.516,40.516,1,1,1,1,8.10767878078222,12.1935129165649,7.75809819168744,
40.633,40.633,1,1,1,1,8.12817175630331,12.1910691261292,7.77981812576399,
40.75,40.75,1,1,1,1,8.14963669475913,12.1878743171692,7.80307347559743,
40.868,40.868,1,1,1,1,8.17934969251156,12.1911883354187,7.82155568514314,
40.985,40.985,1,1,1,1,8.1909224100709,12.1840715408325,7.86161477760792,
41.102,41.102,1,1,1,1,8.22132577401996,12.1865153312683,7.87788446258469,
41.22,41.22,1,1,1,1,8.24151898527145,12.1820092201233,7.89959009154549,
41.337,41.337,1,1,1,1,8.26797999488711,12.1826410293579,7.92572553801608,
41.455,41.455,1,1,1,1,8.28855472429991,12.1835112571716,7.94940527295003,
41.572,41.572,1,1,1,1,8.30955639070272,12.1818542480469,7.9712539530683,
41.689,41.689,1,1,1,1,8.33704386584759,12.1894598007202,7.9915719858016,
41.807,41.807,1,1,1,1,8.36496736174822,12.1835112571716,8.01281031431465,
41.924,41.924,1,1,1,1,8.38334381985068,12.188994884491,8.03926524170361,
42.041,42.041,1,1,1,1,8.40689802442789,12.1798038482666,8.06165274784837,
42.159,42.159,1,1,1,1,8.42353039950728,12.1751666069031,8.09305247691402,
42.276,42.276,1,1,1,1,8.45639546397328,12.1882319450378,8.10699996476779,
42.394,42.394,1,1,1,1,8.47400888575315,12.1780395507813,8.13762721758308,
42.511,42.511,1,1,1,1,8.49995212072134,12.1769547462463,8.16263732828154,
42.628,42.628,1,1,1,1,8.52682189979553,12.1803998947144,8.18214950616107,
42.746,42.746,1,1,1,1,8.55152065885663,12.1811151504517,8.19812832045097,
42.863,42.863,1,1,1,1,8.57147769219875,12.1798634529114,8.23053894436278,
42.98,42.98,1,1,1,1,8.59630362398028,12.174928188324,8.24901161716466,
43.098,43.098,1,1,1,1,8.61892220068574,12.1802568435669,8.27967701695528,
43.215,43.215,1,1,1,1,8.64166795011163,12.1733427047729,8.30029068874736,
43.333,43.333,1,1,1,1,8.66719333185553,12.175726890564,8.3217388256247,
43.45,43.45,1,1,1,1,8.6905386098206,12.1755361557007,8.34507523778071,
43.568,43.568,1,1,1,1,8.71970658162832,12.1742725372314,8.36308537850675,
43.685,43.685,1,1,1,1,8.73791953194737,12.1747732162476,8.3922201309124,
43.802,43.802,1,1,1,1,8.7552422732234,12.1676564216614,8.4245687659893,
43.919,43.919,1,1,1,1,8.78357453858256,12.1682286262512,8.44316541646099,
44.037,44.037,1,1,1,1,8.80668363863826,12.1710419654846,8.4636980259305,
44.154,44.154,1,1,1,1,8.83206368013024,12.1763348579407,8.48671018879623,
44.272,44.272,1,1,1,1,8.85335602703691,12.1666550636292,8.5125356910923,
44.389,44.389,1,1,1,1,8.87290429092049,12.1611356735229,8.53881895709228,
44.507,44.507,1,1,1,1,8.8999375777781,12.1626853942871,8.56070101581397,
44.624,44.624,1,1,1,1,8.92718887501359,12.1613144874573,8.58164370526824,
44.741,44.741,1,1,1,1,8.95112459775209,12.1662497520447,8.60132754453673,
44.858,44.858,1,1,1,1,8.9745788809061,12.1679782867432,8.62748683286691,
44.976,44.976,1,1,1,1,8.99528986680508,12.1609926223755,8.65419925233931,
45.093,45.093,1,1,1,1,9.02494836196303,12.1630907058716,8.66631568537741,
45.211,45.211,1,1,1,1,9.04408785638809,12.1659874916077,8.69976581436686,
45.328,45.328,1,1,1,1,9.06564363250136,12.1609926223755,8.71947826386685,
45.446,45.446,1,1,1,1,9.08846205205321,12.1565937995911,8.74188961187119,
45.563,45.563,1,1,1,1,9.11545900384784,12.160336971283,8.76599373190565,
45.68,45.68,1,1,1,1,9.13643341895342,12.1578931808472,8.79455151130948,
45.797,45.797,1,1,1,1,9.16281267467737,12.1611475944519,8.80535187369881,
45.915,45.915,1,1,1,1,9.18419585924148,12.1603965759277,8.83556904652934,
46.032,46.032,1,1,1,1,9.20527019577026,12.1585845947266,8.85833325405545,
46.15,46.15,1,1,1,1,9.23129518463016,12.1528029441833,8.88259949873505,
46.267,46.267,1,1,1,1,9.25829213642478,12.1554255485535,8.89791550932865,
46.385,46.385,1,1,1,1,9.2779675730288,12.1530055999756,8.93056455183625,
46.502,46.502,1,1,1,1,9.30546413193941,12.1557474136353,8.94916120230794,
46.619,46.619,1,1,1,1,9.3227596219182,12.1495127677917,8.97485795856228,
46.736,46.736,1,1,1,1,9.34400654999614,12.1414661407471,9.00250021055827,
46.854,46.854,1,1,1,1,9.36855996880531,12.1528744697571,9.03003755837211,
46.971,46.971,1,1,1,1,9.38448381015658,12.1465563774109,9.05165735663843,
47.089,47.089,1,1,1,1,9.41764863889217,12.1470332145691,9.07124582846861,
47.206,47.206,1,1,1,1,9.44115742464065,12.1515512466431,9.09176413282237,
47.324,47.324,1,1,1,1,9.46324005916715,12.1465682983398,9.12147585822983,
47.441,47.441,1,1,1,1,9.49154507322907,12.1478676795959,9.13983409010572,
47.558,47.558,1,1,1,1,9.51095708062649,12.1441841125488,9.16335646876645,
47.675,47.675,1,1,1,1,9.53572850981354,12.1391415596008,9.18264930153785,
47.793,47.793,1,1,1,1,9.55717528073788,12.1386528015137,9.20530383650989,
47.91,47.91,1,1,1,1,9.57860388413072,12.1356129646301,9.24021785567751,
48.028,48.028,1,1,1,1,9.60597327032089,12.1411442756653,9.25984447448301,
48.145,48.145,1,1,1,1,9.62605747638345,12.1391415596008,9.28943222222066,
48.263,48.263,1,1,1,1,9.65206429771185,12.136447429657,9.3019253566401,
48.38,48.38,1,1,1,1,9.68020580399036,12.1409177780151,9.32626312689843,
48.497,48.497,1,1,1,1,9.6997631516397,12.1373534202576,9.35504025141039,
48.614,48.614,1,1,1,1,9.72253615236282,12.1341705322266,9.37703198268614,
48.732,48.732,1,1,1,1,9.74553624722958,12.1381282806396,9.40006321903953,
48.849,48.849,1,1,1,1,9.77777453185916,12.1372103691101,9.41967076435738,
48.967,48.967,1,1,1,1,9.7926264888525,12.1299862861633,9.45079869622383,
49.084,49.084,1,1,1,1,9.81529956815243,12.1317744255066,9.4714695884789,
49.202,49.202,1,1,1,1,9.83906269934177,12.1289134025574,9.49584550571256,
49.327,49.327,1,1,1,1,9.86824883868098,12.1333360671997,9.51500005569839,
49.444,49.444,1,1,1,1,9.89285676008463,12.1259570121765,9.53951902408953,
49.561,49.561,1,1,1,1,9.91939043982625,12.1294736862183,9.56132002048864,
49.678,49.678,1,1,1,1,9.93428781564832,12.1252059936523,9.59026403801765,
49.796,49.796,1,1,1,1,9.95193757249117,12.110698223114,9.61916514019942,
49.913,49.913,1,1,1,1,9.98383975778818,12.1184468269348,9.63527746890297,
50.038,50.038,1,1,1,1,10.0078118155897,12.1202111244202,9.65963908102088,
50.156,50.156,1,1,1,1,10.032074553895,12.1208310127258,9.68156882346172,
50.273,50.273,1,1,1,1,10.0544842039883,12.1112942695618,9.7081811071239,
50.391,50.391,1,1,1,1,10.0797279889941,12.1166944503784,9.73346778339348,
50.508,50.508,1,1,1,1,10.1004662261903,12.1159791946411,9.75607463464637,
50.625,50.625,1,1,1,1,10.1325137517393,12.1212005615234,9.76859161092539,
50.742,50.742,1,1,1,1,10.1492097131789,12.1165752410889,9.80225631665106,
50.86,50.86,1,1,1,1,10.1716193632722,12.1115207672119,9.82449123489451,
50.977,50.977,1,1,1,1,10.1934113172948,12.1023058891296,9.84454223880052,
51.095,51.095,1,1,1,1,10.2191092905879,12.1089696884155,9.87083027317243,
51.212,51.212,1,1,1,1,10.2424364010215,12.1048092842102,9.89468166949534,
51.33,51.33,1,1,1,1,10.264873302412,12.1091723442078,9.91480896735201,
51.447,51.447,1,1,1,1,10.2893540510952,12.1025204658508,9.9378688139369,
51.564,51.564,1,1,1,1,10.3135622868061,12.1029376983643,9.9626786530149,
51.681,51.681,1,1,1,1,10.3364533764839,12.0994329452515,9.986916287463,
51.799,51.799,1,1,1,1,10.3583543356955,12.1008038520813,10.010987028894,
51.916,51.916,1,1,1,1,10.3831257648826,12.0980858802795,10.0378758781273,
52.041,52.041,1,1,1,1,10.4075247596741,12.0982766151428,10.0592286475664,
52.159,52.159,1,1,1,1,10.4322053512037,12.0943307876587,10.0836427117753,
52.276,52.276,1,1,1,1,10.4556868856549,12.0986938476563,10.1051719109753,
52.394,52.394,1,1,1,1,10.4801040479779,12.0913624763489,10.1330764234266,
52.511,52.511,1,1,1,1,10.501132965678,12.0917916297913,10.1532275631429,
52.628,52.628,1,1,1,1,10.5255410442352,12.0944619178772,10.1767880887789,
52.745,52.745,1,1,1,1,10.5480506157517,12.0875716209412,10.2016217697165,
52.863,52.863,1,1,1,1,10.5721770975709,12.0859742164612,10.2217872145485,
52.98,52.98,1,1,1,1,10.5955314593017,12.085223197937,10.2441699523213,
53.098,53.098,1,1,1,1,10.6246903473437,12.085497379303,10.2643783125006,
53.215,53.215,1,1,1,1,10.642358271718,12.0795965194702,10.2946097904469,
53.333,53.333,1,1,1,1,10.6684922657669,12.0786190032959,10.317259557047,
53.45,53.45,1,1,1,1,10.693654296881,12.0708703994751,10.3353602968394,
53.567,53.567,1,1,1,1,10.7144742879689,12.0711207389832,10.3645951850553,
53.684,53.684,1,1,1,1,10.7347401693463,12.0714068412781,10.3858716605437,
53.802,53.802,1,1,1,1,10.7603473049819,12.0737075805664,10.4093272819976,
53.919,53.919,1,1,1,1,10.7833292323172,12.0657324790955,10.4320008904573,
54.037,54.037,1,1,1,1,10.8083550069451,12.0591640472412,10.4577453304308,
54.154,54.154,1,1,1,1,10.8305920654893,12.066912651062,10.48021866727,
54.272,54.272,1,1,1,1,10.8538919246256,12.0578646659851,10.5067212783782,
54.389,54.389,1,1,1,1,10.8788541128933,12.0553970336914,10.5295951584583,
54.506,54.506,1,1,1,1,10.8984568793714,12.0566129684448,10.5587346792359,
54.623,54.623,1,1,1,1,10.9238187533319,12.0543241500854,10.5780608906107,
54.741,54.741,1,1,1,1,10.9497619883001,12.0535969734192,10.5988271503041,
54.858,54.858,1,1,1,1,10.9707000683427,12.0475649833679,10.6231077000994,
54.976,54.976,1,1,1,1,10.9977878577948,12.0467901229858,10.644770413713,
55.093,55.093,1,1,1,1,11.019025702107,12.0385885238647,10.6703527290413,
55.211,55.211,1,1,1,1,11.0433611105382,12.0426774024963,10.6906326147993,
55.328,55.328,1,1,1,1,11.0574046123803,12.0378971099854,10.7239969130943,
55.445,55.445,1,1,1,1,11.0889797821105,12.0319247245789,10.7421882519531,
55.563,55.563,1,1,1,1,11.1173120474696,12.0362997055054,10.7619531535442,
55.68,55.68,1,1,1,1,11.1363425367057,12.0259881019592,10.7852228084934,
55.797,55.797,1,1,1,1,11.1560270570755,12.0236277580261,10.8140237748649,
55.915,55.915,1,1,1,1,11.1852222801805,12.0263576507568,10.834184451325,
56.038,56.038,1,1,1,1,11.2088854899466,12.0136618614197,10.8574922532495,
56.156,56.156,1,1,1,1,11.2264262416005,12.0169639587402,10.8858592977767,
56.273,56.273,1,1,1,1,11.2550764387608,12.0179414749146,10.9074647909273,
56.391,56.391,1,1,1,1,11.2698284743309,12.0111346244812,10.933366587174,
56.508,56.508,1,1,1,1,11.3018941674113,12.0148777961731,10.9518821753231,
56.625,56.625,1,1,1,1,11.3300810925186,12.0055794715881,10.9743555121624,
56.742,56.742,1,1,1,1,11.3501380472839,12.004816532135,10.998221213601,
56.86,56.86,1,1,1,1,11.3697589812934,11.9966626167297,11.0242708293771,
56.977,56.977,1,1,1,1,11.3964925038815,11.9952440261841,11.0469492062088,
57.095,57.095,1,1,1,1,11.4185842221737,11.9883060455322,11.068235218441,
57.212,57.212,1,1,1,1,11.4482608848631,11.9923949241638,11.0899456157737,
57.33,57.33,1,1,1,1,11.4659288092375,11.9831204414368,11.1187894974925,
57.447,57.447,1,1,1,1,11.4894194274545,11.9806885719299,11.1442144565476,
57.564,57.564,1,1,1,1,11.5143997832537,11.9842410087585,11.1632307237479,
57.681,57.681,1,1,1,1,11.5448939848602,11.9746804237366,11.1834152420675,
57.799,57.799,1,1,1,1,11.5618806268036,11.962890625,11.2088402011227,
57.916,57.916,1,1,1,1,11.580511430347,11.960780620575,11.2389429330272,
58.034,58.034,1,1,1,1,11.6075356334388,11.9573950767517,11.2547930012754,
58.151,58.151,1,1,1,1,11.6358588150322,11.9590044021606,11.279850795693,
58.269,58.269,1,1,1,1,11.6534449855149,11.9483113288879,11.3032396599401,
58.386,58.386,1,1,1,1,11.6773988757849,11.9447827339172,11.3293178859477,
58.503,58.503,1,1,1,1,11.707584229356,11.9434595108032,11.3446911170043,
58.62,58.62,1,1,1,1,11.7253974939823,11.9312763214111,11.3772495604455,
58.738,58.738,1,1,1,1,11.7558462767601,11.9354367256165,11.391325794341,
58.855,58.855,1,1,1,1,11.7714431025445,11.9208097457886,11.4220579513384,
58.973,58.973,1,1,1,1,11.800620158118,11.9154691696167,11.4428861998667,
59.09,59.09,1,1,1,1,11.8175795487642,11.9110465049744,11.4689405840147,
59.208,59.208,1,1,1,1,11.8331400394857,11.8993759155273,11.4994820061356,
59.325,59.325,1,1,1,1,11.8641883508027,11.9016528129578,11.5167244389832,
59.442,59.442,1,1,1,1,11.887915146929,11.8898868560791,11.5405424567027,
59.559,59.559,1,1,1,1,11.9033484649301,11.8863701820374,11.5713318341631,
59.677,59.677,1,1,1,1,11.9384390520036,11.8813037872314,11.5896757609232,
59.794,59.794,1,1,1,1,11.9517831038833,11.8730187416077,11.6155537153104,
59.922,59.922,1,1,1,1,11.9857745553017,11.8677020072937,11.636701444757,
60.04,60.04,1,1,1,1,12.007648263216,11.8610620498657,11.6604145582944,
60.157,60.157,1,1,1,1,12.0330101371765,11.8440389633179,11.6844090057748,
60.275,60.275,1,1,1,1,12.0597345759988,11.8502855300903,11.7065294830923,
60.392,60.392,1,1,1,1,12.0812085982203,11.8344187736511,11.7314728365839,
60.509,60.509,1,1,1,1,12.1041905255556,11.8254065513611,11.7544849994496,
60.626,60.626,1,1,1,1,12.12734504444,11.8195772171021,11.7789276738901,
60.744,60.744,1,1,1,1,12.1497365270019,11.8121743202209,11.8029030478828,
60.861,60.861,1,1,1,1,12.1702022512257,11.8020415306091,11.8270119362892,
60.979,60.979,1,1,1,1,12.1889874787867,11.785888671875,11.8548783017653,
61.096,61.096,1,1,1,1,12.2201357115269,11.7848873138428,11.870528098393,
61.214,61.214,1,1,1,1,12.2434264868975,11.7740988731384,11.8992146238385,
61.337,61.337,1,1,1,1,12.2704961088181,11.7674708366394,11.9218739271825,
61.455,61.455,1,1,1,1,12.2922517277777,11.7491364479065,11.9423064008418,
61.572,61.572,1,1,1,1,12.3178770309448,11.7436528205872,11.9676789078058,
61.689,61.689,1,1,1,1,12.3362534890473,11.7324590682983,11.9979580694713,
61.806,61.806,1,1,1,1,12.3627599174917,11.7189645767212,12.0177849598972,
61.924,61.924,1,1,1,1,12.3858690175474,11.710262298584,12.0401057088352,
62.044,62.044,1,1,1,1,12.4102770961046,11.6956353187561,12.0618542531432,
62.162,62.162,1,1,1,1,12.4337313792586,11.6850733757019,12.0875033256784,
62.279,62.279,1,1,1,1,12.4519352458119,11.6674780845642,12.1118744745401,
62.397,62.397,1,1,1,1,12.4822386883378,11.6577506065369,12.1345147043964,
62.514,62.514,1,1,1,1,12.5102802731931,11.6498827934265,12.1550568506098,
62.631,62.631,1,1,1,1,12.5187100078046,11.6237282752991,12.18676652385,
62.748,62.748,1,1,1,1,12.5516568261623,11.6166591644287,12.2057064970996,
62.866,62.866,1,1,1,1,12.5801707668364,11.6012573242188,12.2281989074265,
62.983,62.983,1,1,1,1,12.5981838743091,11.5846395492554,12.2531327241743,
63.101,63.101,1,1,1,1,12.6316030484855,11.5698575973511,12.2731694229646,
63.218,63.218,1,1,1,1,12.6398874428451,11.5511178970337,12.3039349585654,
63.336,63.336,1,1,1,1,12.6703362256229,11.5329623222351,12.3229846043691,
63.453,63.453,1,1,1,1,12.6920645932853,11.5126013755798,12.3468073904605,
63.57,63.57,1,1,1,1,12.7159185621321,11.4974856376648,12.371536167216,
63.687,63.687,1,1,1,1,12.7346765383959,11.4689707756042,12.3981675243658,
63.805,63.805,1,1,1,1,12.7640625205815,11.4584565162659,12.4180277933952,
63.925,63.925,1,1,1,1,12.7845191610396,11.4328145980835,12.4440774091713,
64.042,64.042,1,1,1,1,12.811452526474,11.4159941673279,12.4659213209177,
64.158,64.158,1,1,1,1,12.8333534856856,11.3958477973938,12.4922665757525,
64.274,64.274,1,1,1,1,12.8620763529718,11.3717079162598,12.5111684020268,
64.39,64.39,1,1,1,1,12.8812794337571,11.3480925559998,12.5380238726567,
64.506,64.506,1,1,1,1,12.9034710734725,11.3184213638306,12.5624379368657,
64.622,64.622,1,1,1,1,12.9249450956941,11.2898707389832,12.5852832067144,
64.738,64.738,1,1,1,1,12.9514969429672,11.2674832344055,12.6065263035994,
64.854,64.854,1,1,1,1,12.9739429281235,11.2398147583008,12.6325377724001,
64.969,64.969,1,1,1,1,12.9928734959364,11.2082481384277,12.6588019649125,
65.085,65.085,1,1,1,1,13.0163368628562,11.1831903457642,12.6781949334941,
65.201,65.201,1,1,1,1,13.0413808050156,11.1514687538147,12.7053412748108,
65.317,65.317,1,1,1,1,13.0599934410274,11.1218333244324,12.7262267438021,
65.433,65.433,1,1,1,1,13.0920227990448,11.0920667648315,12.7503404005804,
65.549,65.549,1,1,1,1,13.1111077908754,11.0564708709717,12.7754268052295,
65.665,65.665,1,1,1,1,13.1429373060465,11.0278487205505,12.7933177366577,
65.781,65.781,1,1,1,1,13.1640025588095,10.9849333763123,12.8173503311134,
65.897,65.897,1,1,1,1,13.1817159020126,10.9434843063354,12.8471431188434,
66.013,66.013,1,1,1,1,13.197458068049,10.9046578407288,12.8709039160999,
66.129,66.129,1,1,1,1,13.2235012244403,10.8669877052307,12.8942641701155,
66.245,66.245,1,1,1,1,13.2483271562219,10.8329653739929,12.9118451573691,
66.361,66.361,1,1,1,1,13.2708912303329,10.7868313789368,12.9368457313238,
66.477,66.477,1,1,1,1,13.2961895179331,10.7470512390137,12.9609689248459,
66.596,66.596,1,1,1,1,13.3195166283667,10.6962323188782,12.9842958002581,
66.712,66.712,1,1,1,1,13.3317978796542,10.6493592262268,13.0194625431372,
66.828,66.828,1,1,1,1,13.3694591724336,10.6047987937927,13.0379161424514,
66.944,66.944,1,1,1,1,13.3902428284585,10.5494022369385,13.056465109204,
67.06,67.06,1,1,1,1,13.4087010404527,10.4915022850037,13.0851564030214,
67.176,67.176,1,1,1,1,13.43396299299,10.4457259178162,13.1033286683926,
67.293,67.293,1,1,1,1,13.4592431130588,10.3936791419983,13.126474345672,
67.409,67.409,1,1,1,1,13.4850319240093,10.340428352356,13.1506976750043,
67.525,67.525,1,1,1,1,13.5043349262178,10.2821946144104,13.1769618675167,
67.641,67.641,1,1,1,1,13.5213034006298,10.2178335189819,13.204751939042,
67.757,67.757,1,1,1,1,13.550880141896,10.1563096046448,13.2271203716991,
67.873,67.873,1,1,1,1,13.5769414658189,10.0866913795471,13.2510385252289,
67.989,67.989,1,1,1,1,13.6069723953724,10.0229620933533,13.274198507624,
68.105,68.105,1,1,1,1,13.6241861314595,9.92774963378906,13.3018550647357,
68.221,68.221,1,1,1,1,13.6352501581371,9.85777378082275,13.3153352521418,
68.337,68.337,1,1,1,1,13.6471680587947,9.84147787094116,13.3369455136642,
68.453,68.453,1,1,1,1,13.6783344590664,9.77364778518677,13.3669433413867,
68.569,68.569,1,1,1,1,13.7116718793511,9.67222452163696,13.3945140678039,
68.685,68.685,1,1,1,1,13.73402702685,9.55904722213745,13.4265622954501,
68.801,68.801,1,1,1,1,13.7629497369826,9.46519374847412,13.4490499374051,
68.917,68.917,1,1,1,1,13.7804269022763,9.37552452087402,13.4692344557248,
69.033,69.033,1,1,1,1,13.8053255041838,9.28350687026978,13.4938774017857,
69.149,69.149,1,1,1,1,13.8244831661403,9.17917490005493,13.5232124258118,
69.265,69.265,1,1,1,1,13.8537056405425,9.07055139541626,13.5441646520099,
69.381,69.381,1,1,1,1,13.8772325938225,8.90451669692993,13.5726222956035,
69.497,69.497,1,1,1,1,13.9044657235265,8.05531740188599,13.6090192784369,
69.613,69.613,1,1,1,1,13.9310266545653,5.5930495262146,13.6888132140762,
69.729,69.729,1,1,1,1,13.9427447123766,4.66803312301636,13.7097654402743,
69.844,69.844,1,1,1,1,13.9759912950039,3.87076139450073,13.7445030296811,
69.96,69.96,1,1,1,1,13.9928507642269,3.2748818397522,13.7801752199833,
70.076,70.076,1,1,1,1,14.0164503876328,2.75503396987915,13.817120565587,
70.192,70.192,1,1,1,1,14.0417486752331,2.43984460830688,13.8465318835638,
70.308,70.308,1,1,1,1,14.0558830147326,2.19781398773193,13.8790188014263,
70.424,70.424,1,1,1,1,14.0753949435532,2.0639181137085,13.9035520749331,
70.54,70.54,1,1,1,1,14.1078239872634,1.92484855651855,13.9246044369415,
70.656,70.656,1,1,1,1,14.1274903401017,1.76354646682739,13.9509783020079,
70.772,70.772,1,1,1,1,14.1549778152466,1.62414312362671,13.9740619904523,
70.888,70.888,1,1,1,1,14.1732634356916,1.45413875579834,14.0053520469639,
71.004,71.004,1,1,1,1,14.1968358078003,1.29477977752686,14.0356884290924,
71.12,71.12,1,1,1,1,14.2239417647839,1.11756324768066,14.0630874941206,
71.236,71.236,1,1,1,1,14.2415551865637,0.947630405426025,14.0924368232625,
71.355,71.355,1,1,1,1,14.2686066409528,0.742578506469727,14.1245899550909,
71.471,71.471,1,1,1,1,14.2915068143964,0.658285617828369,14.1482506165371,
71.587,71.587,1,1,1,1,14.3184855986595,0.574982166290283,14.1731558230535,
71.703,71.703,1,1,1,1,14.33543590554,0.50969123840332,14.2008696006282,
71.819,71.819,1,1,1,1,14.3609976223469,0.442540645599365,14.2262611810799,
71.938,71.938,1,1,1,1,14.3777390026152,0.319755077362061,14.2602024523767,
72.054,72.054,1,1,1,1,14.4161179128885,0.232326984405518,14.2837534412689,
72.17,72.17,1,1,1,1,14.4318691626906,0.183403491973877,14.3109236244452,
72.286,72.286,1,1,1,1,14.4573854606688,0.13725757598877,14.340730717291,
72.402,72.402,1,1,1,1,14.4823113138735,0.0959515571594238,14.3801460795472,
72.518,72.518,1,1,1,1,14.5096897838295,0.0874996185302734,14.3887529908552,
72.634,72.634,1,1,1,1,14.5207538105071,0.0914335250854492,14.4140062885214,
72.75,72.75,1,1,1,1,14.549449426496,0.0943541526794434,14.4419823265515,
72.866,72.866,1,1,1,1,14.5745024524212,0.0862360000610352,14.4683991069651,
72.982,72.982,1,1,1,1,14.6002276770115,0.0934004783630371,14.4966374054506,
73.097,73.097,1,1,1,1,14.622809918654,0.0912189483642578,14.5222387942666,
73.213,73.213,1,1,1,1,14.6497614516199,0.0944018363952637,14.5425615953718,
73.329,73.329,1,1,1,1,14.6702271758437,0.0930547714233398,14.5630274476345,
73.445,73.445,1,1,1,1,14.693172768116,0.0957012176513672,14.5848713593809,
73.561,73.561,1,1,1,1,14.7071435998321,0.0917553901672363,14.6104775165688,
73.677,73.677,1,1,1,1,14.7362934041083,0.087285041809082,14.6327172031842,
73.793,73.793,1,1,1,1,14.7598385249197,0.0934481620788574,14.654532504699,
73.909,73.909,1,1,1,1,14.7959555775225,0.0930905342102051,14.6744261523318,
74.025,74.025,1,1,1,1,14.8057660445273,0.0929474830627441,14.7012005606391,
74.141,74.141,1,1,1,1,14.8315548554778,0.0939369201660156,14.7255049522941,
74.257,74.257,1,1,1,1,14.855145395118,0.0997066497802734,14.7502957178844,
74.373,74.373,1,1,1,1,14.8715688435853,0.0960230827331543,14.7773514601347,
74.489,74.489,1,1,1,1,14.9018450348139,0.0958681106567383,14.7961293087392,
74.605,74.605,1,1,1,1,14.9274430866837,0.0966787338256836,14.8201905134264,
74.721,74.721,1,1,1,1,14.9475908791065,0.0915288925170898,14.8425398725959,
74.837,74.837,1,1,1,1,14.9754780399442,0.0908732414245605,14.8612318905059,
74.953,74.953,1,1,1,1,15.0023387352526,0.0951051712036133,14.8822174953074,
75.069,75.069,1,1,1,1,15.0112589932144,0.0936746597290039,14.9126730867337,
75.185,75.185,1,1,1,1,15.0385012066841,0.0908136367797852,14.9312792739492,
75.301,75.301,1,1,1,1,15.0627639449894,0.0954985618591309,14.9584685306132,
75.417,75.417,1,1,1,1,15.0889251903355,0.0961184501647949,14.9787102693959,
75.533,75.533,1,1,1,1,15.1089458100379,0.0935673713684082,15.0007830629942,
75.649,75.649,1,1,1,1,15.1306196751058,0.0934720039367676,15.0240145709681,
75.765,75.765,1,1,1,1,15.1545372303128,0.094139575958252,15.0480042500765,
75.881,75.881,1,1,1,1,15.1858943896651,0.0959396362304688,15.0663004931175,
75.997,75.997,1,1,1,1,15.1983118974388,0.0908493995666504,15.0945101813715,
76.113,76.113,1,1,1,1,15.2216844267011,0.0903010368347168,15.1176940056262,
76.228,76.228,1,1,1,1,15.247636745435,0.0975608825683594,15.1398049461998,
76.344,76.344,1,1,1,1,15.2651774970889,0.0899434089660645,15.1650630122379,
76.46,76.46,1,1,1,1,15.2931282442868,0.097048282623291,15.1858054300717,
76.579,76.579,1,1,1,1,15.318998809129,0.0999212265014648,15.2118741193355,
76.695,76.695,1,1,1,1,15.3369574140072,0.100052356719971,15.2349911863834,
76.811,76.811,1,1,1,1,15.363091408056,0.0925779342651367,15.2558480451432,
76.927,76.927,1,1,1,1,15.3842747497737,0.0937223434448242,15.2805625167829,
77.043,77.043,1,1,1,1,15.408183221215,0.102460384368896,15.3041325791627,
77.159,77.159,1,1,1,1,15.4321552790165,0.0957369804382324,15.323148846363,
77.275,77.275,1,1,1,1,15.456517938745,0.0918745994567871,15.3470288529174,
77.391,77.391,1,1,1,1,15.4783189765334,0.0960350036621094,15.3735457691413,
77.507,77.507,1,1,1,1,15.5029087304056,0.0889897346496582,15.3937445925767,
77.623,77.623,1,1,1,1,15.5201860528529,0.0916600227355957,15.4199420278822,
77.739,77.739,1,1,1,1,15.5469559105039,0.090634822845459,15.4417334875375,
77.855,77.855,1,1,1,1,15.5686297755718,0.0971555709838867,15.4661046363992,
77.971,77.971,1,1,1,1,15.6002503641307,0.0936388969421387,15.4869853370186,
78.087,78.087,1,1,1,1,15.6176094404697,0.0944375991821289,15.5109082589202,
78.203,78.203,1,1,1,1,15.6401916821122,0.0942468643188477,15.532160892549,
78.296,78.296,1,1,1,1,15.6275743314922,0.0982880592346191,15.5206166641408,