File: Steel.csv
"Total Time (s)","Cycle Elapsed Time (s)","Total Cycles","Elapsed Cycles","Step","Total Cycle Count(8800 (0,3) Waveform)","Position(8800 (0,3):Position) (mm)","Load(8800 (0,3):Load) (kN)","Extension mm from Extensometer (mm)",
0,0,1,1,1,1,0.00128081097006798,-0.014263391494751,-0.00029563905878067,
0.15,0.15,1,1,1,1,0.00374251148700714,0.0945568084716797,0.000762939506530762,
0.334,0.334,1,1,1,1,0.0493975181221962,2.01373100280762,0.0266361255217552,
0.517,0.517,1,1,1,1,0.0702810955703258,2.70935297012329,0.0286722203298092,
0.698,0.698,1,1,1,1,0.0974597226798534,3.80934476852417,0.0419378309996128,
0.88,0.88,1,1,1,1,0.124438506942987,4.83143329620361,0.0539445914836407,
1.062,1.062,1,1,1,1,0.152798023599386,5.89121580123901,0.0572252313617229,
1.243,1.243,1,1,1,1,0.179222698152065,6.79943561553955,0.07415772003479,
1.425,1.425,1,1,1,1,0.206982686269283,7.77713060379028,0.0775146538635254,
1.606,1.606,1,1,1,1,0.23551479447484,8.74323844909668,0.0848150312666416,
1.787,1.787,1,1,1,1,0.263093107277155,9.6193790435791,0.0951051778609753,
1.969,1.969,1,1,1,1,0.289054509776831,10.4695320129395,0.11669159752388,
2.159,2.159,1,1,1,1,0.321220124280453,11.3862156867981,0.121312149910307,
2.35,2.35,1,1,1,1,0.349270792901516,12.2021079063416,0.131840715100431,
2.542,2.542,1,1,1,1,0.377103451144695,12.9268765449524,0.142335901687145,
2.733,2.733,1,1,1,1,0.406680192410946,13.5931134223938,0.144262323941135,
2.925,2.925,1,1,1,1,0.433232039684057,14.1576766967773,0.171589863390684,
3.116,3.116,1,1,1,1,0.46348097961545,14.6214127540588,0.188174260913897,
3.308,3.308,1,1,1,1,0.494520207166672,14.9853229522705,0.196824087569189,
3.499,3.499,1,1,1,1,0.520817708998919,15.2818083763123,0.225625053940725,
3.691,3.691,1,1,1,1,0.552765313124657,15.5129194259644,0.233311669469023,
3.882,3.882,1,1,1,1,0.581860614806414,15.7048940658569,0.259938258246946,
4.073,4.073,1,1,1,1,0.610610733389854,15.8748149871826,0.29213907379446,
4.265,4.265,1,1,1,1,0.638852161091566,16.0158157348633,0.326161407413816,
4.456,4.456,1,1,1,1,0.670336493164301,16.1594390869141,0.330400490046978,
4.648,4.648,1,1,1,1,0.70012216104269,16.268527507782,0.367350604022646,
4.842,4.842,1,1,1,1,0.728390840041637,16.3636207580566,0.39719107547183,
5.033,5.033,1,1,1,1,0.757658733272552,16.4674401283264,0.416154890581036,
5.225,5.225,1,1,1,1,0.786027333694696,16.5526390075684,0.440535576186609,
5.416,5.416,1,1,1,1,0.815449650943279,16.6351318359375,0.470647844834995,
5.608,5.608,1,1,1,1,0.843545738393068,16.708517074585,0.515332258058119,
5.799,5.799,1,1,1,1,0.871687244671583,16.7877554893494,0.506691968146658,
5.991,5.991,1,1,1,1,0.900410111957788,16.856849193573,0.541210212445259,
6.182,6.182,1,1,1,1,0.92699829429388,16.9263482093811,0.577344934823322,
6.374,6.374,1,1,1,1,0.958019354313612,16.9892430305481,0.599236530288839,
6.565,6.565,1,1,1,1,0.986024604105949,17.0508742332459,0.610508961497831,
6.757,6.757,1,1,1,1,1.01549234018326,17.1130299568176,0.64863209496479,
6.948,6.948,1,1,1,1,1.0439608620286,17.1693682670593,0.675344514437199,
7.14,7.14,1,1,1,1,1.07080338980556,17.2238945960999,0.71047787871294,
7.331,7.331,1,1,1,1,1.09944450320005,17.2774791717529,0.718531658878755,
7.523,7.523,1,1,1,1,1.12877598279119,17.3250436782837,0.756106429575396,
7.714,7.714,1,1,1,1,1.15647238454819,17.3779368400574,0.785574968015146,
7.906,7.906,1,1,1,1,1.18485006873608,17.429518699646,0.808610972740459,
8.099,8.099,1,1,1,1,1.21337309317589,17.4765467643738,0.833683072273827,
8.293,8.293,1,1,1,1,1.24220496565104,17.524516582489,0.869412483039045,
8.489,8.489,1,1,1,1,1.27090058164,17.5793170928955,0.906000200749111,
8.684,8.684,1,1,1,1,1.29908750674725,17.6181197166443,0.930924480753088,
8.88,8.88,1,1,1,1,1.33008131546974,17.674994468689,0.940938061776304,
9.075,9.075,1,1,1,1,1.3590766957283,17.7167057991028,0.973448821498346,
9.271,9.271,1,1,1,1,1.38634616049528,17.7474737167358,1.00805289649143,
9.466,9.466,1,1,1,1,1.41838460227847,17.8033947944641,1.03361613833213,
9.663,9.663,1,1,1,1,1.44462760151625,17.8468704223633,1.07103832112746,
9.858,9.858,1,1,1,1,1.47732007443309,17.8938031196594,1.07731826694059,
10.054,10.054,1,1,1,1,1.50431702622771,17.9364442825317,1.10946186202512,
10.249,10.249,1,1,1,1,1.53562876675129,17.985463142395,1.12281807176132,
10.445,10.445,1,1,1,1,1.56565061253905,18.0258274078369,1.16590508039265,
10.64,10.64,1,1,1,1,1.59473683045506,18.0604577064514,1.18238934210563,
10.836,10.836,1,1,1,1,1.62452249833345,18.0954456329346,1.21077546012049,
11.031,11.031,1,1,1,1,1.65132869104743,18.1258678436279,1.23978623485632,
11.227,11.227,1,1,1,1,1.68370323216319,18.1792140007019,1.26625069898911,
11.422,11.422,1,1,1,1,1.71219900530577,18.2151675224304,1.3035107571393,
11.618,11.618,1,1,1,1,1.73961381032467,18.2473182678223,1.33804807492557,
11.814,11.814,1,1,1,1,1.77291489554644,18.28693151474,1.35507593103695,
12.009,12.009,1,1,1,1,1.80180127061605,18.3241367340088,1.37647638419514,
12.205,12.205,1,1,1,1,1.8297883528769,18.3605074882507,1.41255865448213,
12.4,12.4,1,1,1,1,1.85771184877753,18.3858752250671,1.44482622723646,
12.596,12.596,1,1,1,1,1.88616220309138,18.4114336967468,1.48142348169036,
12.791,12.791,1,1,1,1,1.91674724235535,18.4607744216919,1.5016032316381,
12.987,12.987,1,1,1,1,1.94715060630441,18.4934496879578,1.52537356563845,
13.182,13.182,1,1,1,1,1.97750855142474,18.5214519500732,1.5457392820909,
13.378,13.378,1,1,1,1,2.00852052767873,18.5593605041504,1.58176910028682,
13.573,13.573,1,1,1,1,2.03479986197948,18.5915112495422,1.60779964257526,
13.77,13.77,1,1,1,1,2.06802827707529,18.624484539032,1.62508022239819,
13.965,13.965,1,1,1,1,2.09434394643903,18.6471581459045,1.66185867498488,
14.161,14.161,1,1,1,1,2.12297597606778,18.6824321746826,1.68558609363799,
14.356,14.356,1,1,1,1,2.15476915617585,18.7180757522583,1.71255123682194,
14.552,14.552,1,1,1,1,2.18302875140905,18.7477350234985,1.74798500852838,
14.747,14.747,1,1,1,1,2.21144277065992,18.7758326530457,1.7614365857029,
14.943,14.943,1,1,1,1,2.2427545111835,18.806529045105,1.79372323194489,
15.138,15.138,1,1,1,1,2.27127753562331,18.8374996185303,1.81006921087232,
15.334,15.334,1,1,1,1,2.29967338734269,18.8619017601013,1.85105813586068,
15.529,15.529,1,1,1,1,2.33083978761435,18.883204460144,1.87867654599709,
15.725,15.725,1,1,1,1,2.35916296920776,18.9068794250488,1.9098807718142,
15.921,15.921,1,1,1,1,2.38625984242558,18.9319014549255,1.93644537175722,
16.114,16.114,1,1,1,1,2.41762608554363,18.971586227417,1.95881380441432,
16.306,16.306,1,1,1,1,2.44298795950413,18.9977407455444,1.99720396670856,
16.498,16.498,1,1,1,1,2.47498098245859,19.0220952033997,2.00834288350391,
16.69,16.69,1,1,1,1,2.50578403210044,19.0527081489563,2.03968539210658,
16.882,16.882,1,1,1,1,2.53372569553256,19.0757393836975,2.05859675512471,
17.074,17.074,1,1,1,1,2.56148568364978,19.0952777862549,2.09194674830394,
17.266,17.266,1,1,1,1,2.58906399645209,19.1082239151001,2.12468162150602,
17.458,17.458,1,1,1,1,2.6178867851615,19.1450834274292,2.15196624560833,
17.65,17.65,1,1,1,1,2.64644614466429,19.1606998443604,2.16876045149584,
17.843,17.843,1,1,1,1,2.67565045153499,19.1904306411743,2.2001029600985,
18.035,18.035,1,1,1,1,2.70357394743562,19.2176103591919,2.22740665768847,
18.227,18.227,1,1,1,1,2.73276917054057,19.2461490631104,2.25447193668265,
18.419,18.419,1,1,1,1,2.76526180061102,19.275975227356,2.26935879380383,
18.611,18.611,1,1,1,1,2.79503838472366,19.2926526069641,2.30595127988582,
18.803,18.803,1,1,1,1,2.81970080872178,19.2981958389282,2.34895245782266,
18.995,18.995,1,1,1,1,2.85147582129836,19.3342804908752,2.36052529646234,
19.187,19.187,1,1,1,1,2.87801858480573,19.34734582901,2.38637464061799,
19.379,19.379,1,1,1,1,2.90824027343988,19.3773508071899,2.418604066397,
19.571,19.571,1,1,1,1,2.93521905770302,19.3971157073975,2.43291871888828,
19.763,19.763,1,1,1,1,2.96494113922119,19.4166660308838,2.46579664324784,
19.955,19.955,1,1,1,1,2.99122047352195,19.443154335022,2.49271410271263,
20.147,20.147,1,1,1,1,3.0199524245739,19.4610595703125,2.51925009242415,
20.339,20.339,1,1,1,1,3.05075547421575,19.479238986969,2.54526632959685,
20.532,20.532,1,1,1,1,3.07791593379378,19.499945640564,2.56664294089546,
20.73,20.73,1,1,1,1,3.10834654904008,19.5304989814758,2.60303038698506,
20.922,20.922,1,1,1,1,3.14007614278793,19.5495367050171,2.62161750071292,
21.114,21.114,1,1,1,1,3.16791788479686,19.566535949707,2.65134829960804,
21.306,21.306,1,1,1,1,3.19593221835494,19.5782899856567,2.68937606563668,
21.498,21.498,1,1,1,1,3.22596314790845,19.5978045463562,2.70398635718675,
21.69,21.69,1,1,1,1,3.25212439325452,19.6204543113709,2.74160404323063,
21.882,21.882,1,1,1,1,3.28379040064216,19.6411848068237,2.76706714926109,
22.074,22.074,1,1,1,1,3.31330355554819,19.6585536003113,2.79326935293851,
22.266,22.266,1,1,1,1,3.33879260222912,19.6746468544006,2.81468411121244,
22.458,22.458,1,1,1,1,3.36881444801688,19.6904540061951,2.84396668314748,
22.652,22.652,1,1,1,1,3.39627467186451,19.7047114372253,2.86798497248745,
22.844,22.844,1,1,1,1,3.4236077229917,19.727087020874,2.89544602635064,
23.036,23.036,1,1,1,1,3.45396566811204,19.7498559951782,2.92083760680237,
23.228,23.228,1,1,1,1,3.48338798536062,19.7684407234192,2.94820329322724,
23.42,23.42,1,1,1,1,3.51073920401931,19.7865009307861,2.9828884305429,
23.612,23.612,1,1,1,1,3.54349526329637,19.801139831543,2.99644968027148,
23.804,23.804,1,1,1,1,3.57210004162788,19.8244333267212,3.02638075078707,
23.996,23.996,1,1,1,1,3.60055039594173,19.8370218276978,3.06186220621266,
24.189,24.189,1,1,1,1,3.62806512238383,19.8422074317932,3.08985731773043,
24.381,24.381,1,1,1,1,3.65825047595501,19.865357875824,3.11582587118397,
24.573,24.573,1,1,1,1,3.68507483620048,19.8791980743408,3.14628146261029,
24.765,24.765,1,1,1,1,3.71402479763031,19.8957443237305,3.16977999941144,
24.957,24.957,1,1,1,1,3.7435288687706,19.9136137962341,3.1902363149303,
25.149,25.149,1,1,1,1,3.77065299328566,19.9249386787415,3.2224657407093,
25.341,25.341,1,1,1,1,3.79979371379614,19.9464321136475,3.25019382339978,
25.533,25.533,1,1,1,1,3.83154147507548,19.9710965156555,3.27196144119549,
25.725,25.725,1,1,1,1,3.85783897690773,19.9801325798035,3.30418609860258,
25.917,25.917,1,1,1,1,3.88574430527687,19.9880838394165,3.32546734246287,
26.109,26.109,1,1,1,1,3.91736489383578,20.0137138366699,3.35690998687577,
26.301,26.301,1,1,1,1,3.94760475000143,20.0226426124573,3.38494324536886,
26.493,26.493,1,1,1,1,3.97579167510867,20.0349926948547,3.41666722372479,
26.685,26.685,1,1,1,1,4.00508681963682,20.044207572937,3.43822980152812,
26.878,26.878,1,1,1,1,4.0336643466711,20.0646281242371,3.45708394408326,
27.07,27.07,1,1,1,1,4.06029794783592,20.0746893882751,3.48394895145698,
27.262,27.262,1,1,1,1,4.09040154751539,20.0888752937317,3.5144331531148,
27.454,27.454,1,1,1,1,4.11767101228237,20.1013922691345,3.5389139745306,
27.646,27.646,1,1,1,1,4.1468208165586,20.1184988021851,3.56939817618842,
27.838,27.838,1,1,1,1,4.17586161564589,20.1365351676941,3.58964468334298,
28.03,28.03,1,1,1,1,4.20245888174772,20.1478600502014,3.62408186531901,
28.222,28.222,1,1,1,1,4.23234447104931,20.16521692276,3.64064242098265,
28.414,28.414,1,1,1,1,4.26068582017422,20.1737642288208,3.68188406968255,
28.606,28.606,1,1,1,1,4.28951769264936,20.1829433441162,3.70119597594161,
28.798,28.798,1,1,1,1,4.32003006178737,20.1939225196838,3.72602965687919,
28.99,28.99,1,1,1,1,4.34688167333007,20.2102780342102,3.75868823613062,
29.182,29.182,1,1,1,1,4.37783006322384,20.2300190925598,3.78587749279461,
29.374,29.374,1,1,1,1,4.40648026038408,20.2409982681274,3.8125231550602,
29.567,29.567,1,1,1,1,4.43745590157509,20.259428024292,3.83020904649596,
29.759,29.759,1,1,1,1,4.46404408391118,20.2604055404663,3.86864212413745,
29.951,29.951,1,1,1,1,4.4941385998249,20.2759504318237,3.89302757811494,
30.143,30.143,1,1,1,1,4.518374086833,20.2816724777222,3.92876652562399,
30.335,30.335,1,1,1,1,4.54671543595791,20.2970743179321,3.9508059406189,
30.527,30.527,1,1,1,1,4.57910814460516,20.3126311302185,3.97683171453543,
30.719,30.719,1,1,1,1,4.60744949373007,20.324718952179,4.0058854046185,
30.911,30.911,1,1,1,1,4.63553649741411,20.3251838684082,4.03783349645448,
31.103,31.103,1,1,1,1,4.66483164194226,20.348060131073,4.05576257485795,
31.295,31.295,1,1,1,1,4.69548026756644,20.3590869903564,4.08332376453137,
31.487,31.487,1,1,1,1,4.72493891987801,20.3672885894775,4.11045580073237,
31.679,31.679,1,1,1,1,4.75350736314654,20.3741192817688,4.13664369929404,
31.871,31.871,1,1,1,1,4.77773376638889,20.3890323638916,4.1739514411634,
32.063,32.063,1,1,1,1,4.80953603026271,20.4013466835022,4.18766051042137,
32.255,32.255,1,1,1,1,4.839040101403,20.4128980636597,4.21960383388543,
32.447,32.447,1,1,1,1,4.86722702651024,20.4234004020691,4.25165206153164,
32.639,32.639,1,1,1,1,4.89316117771268,20.4205393791199,4.27860289959984,
32.831,32.831,1,1,1,1,4.92229281445742,20.4323530197144,4.30467635723553,
33.023,33.023,1,1,1,1,4.95328662317991,20.44677734375,4.33181793018036,
33.215,33.215,1,1,1,1,4.9774403562963,20.4500436782837,4.36670333911648,
33.407,33.407,1,1,1,1,5.00955146820545,20.4747319221497,4.38044101860595,
33.599,33.599,1,1,1,1,5.04041810420752,20.4829216003418,4.41122085932255,
33.791,33.791,1,1,1,1,5.06537120870948,20.4894781112671,4.44452793715453,
33.983,33.983,1,1,1,1,5.09921731987596,20.4935312271118,4.46590931682506,
34.175,34.175,1,1,1,1,5.12718623460531,20.5105185508728,4.48827298111024,
34.368,34.368,1,1,1,1,5.15772585504055,20.5196738243103,4.51516659871545,
34.56,34.56,1,1,1,1,5.1853314191401,20.5328583717346,4.54899819745817,
34.752,34.752,1,1,1,1,5.21259180014133,20.5352187156677,4.57312139098029,
34.944,34.944,1,1,1,1,5.23965233829617,20.5439805984497,4.60159810806155,
35.136,35.136,1,1,1,1,5.27032821521759,20.5637216567993,4.61900266555428,
35.33,35.33,1,1,1,1,5.30123118628263,20.5673933029175,4.65709718878975,
35.522,35.522,1,1,1,1,5.33140745608807,20.5822348594666,4.6806577144258,
35.714,35.714,1,1,1,1,5.35713268067837,20.5885648727417,4.72510370905313,
35.906,35.906,1,1,1,1,5.3866458355844,20.5962300300598,4.73543200262279,
36.098,36.098,1,1,1,1,5.4148236769259,20.6051826477051,4.75803408550377,
36.29,36.29,1,1,1,1,5.44448217208385,20.6072330474854,4.79099784055781,
36.482,36.482,1,1,1,1,5.46819988444448,20.6089735031128,4.83122859441156,
36.674,36.674,1,1,1,1,5.50170989627838,20.6258058547974,4.84846625888724,
36.866,36.866,1,1,1,1,5.53129572131038,20.6426858901978,4.86410651877112,
37.058,37.058,1,1,1,1,5.55985508081317,20.6452608108521,4.90845714596014,
37.25,37.25,1,1,1,1,5.58847802667618,20.649528503418,4.93691478955374,
37.443,37.443,1,1,1,1,5.61457568566203,20.6587076187134,4.95871101758094,
37.635,37.635,1,1,1,1,5.64377090876698,20.6677556037903,4.98544727891293,
37.827,37.827,1,1,1,1,5.67531882719994,20.6743240356445,5.01127754958091,
38.019,38.019,1,1,1,1,5.70334224452376,20.6830143928528,5.03604447331166,
38.211,38.211,1,1,1,1,5.73325508512259,20.6895351409912,5.06874596791034,
38.403,38.403,1,1,1,1,5.76347677375674,20.7059860229492,5.08369004549451,
38.595,38.595,1,1,1,1,5.7889930717349,20.7098245620728,5.11468446294732,
38.787,38.787,1,1,1,1,5.81726175073385,20.7151889801025,5.15367067173104,
38.979,38.979,1,1,1,1,5.84733809911609,20.7213521003723,5.17909563078618,
39.171,39.171,1,1,1,1,5.87548868916035,20.7249522209167,5.20607984745779,
39.368,39.368,1,1,1,1,5.90851726140976,20.7415461540222,5.22015608135328,
39.56,39.56,1,1,1,1,5.93101774916053,20.7425117492676,5.2660135140677,
39.752,39.752,1,1,1,1,5.9622477357924,20.7496285438538,5.28345145016384,
39.944,39.944,1,1,1,1,5.99148837772608,20.7651019096375,5.31507529270954,
40.136,40.136,1,1,1,1,6.01955721387863,20.7680463790894,5.34024275968122,
40.328,40.328,1,1,1,1,6.04930654669404,20.7695126533508,5.36599196802664,
40.52,40.52,1,1,1,1,6.07827467565536,20.7804441452026,5.39926089888329,
40.712,40.712,1,1,1,1,6.10703387800455,20.7887887954712,5.4236511212327,
40.904,40.904,1,1,1,1,6.13500279273391,20.788049697876,5.45411148103094,
41.096,41.096,1,1,1,1,6.16388916780353,20.7953929901123,5.4788784047617,
41.291,41.291,1,1,1,1,6.19311164220572,20.806348323822,5.51274815047975,
41.483,41.483,1,1,1,1,6.22426895871162,20.8162903785706,5.54096737547755,
41.675,41.675,1,1,1,1,6.25126591050625,20.8176732063293,5.56225815608168,
41.868,41.868,1,1,1,1,6.27976168364882,20.8225131034851,5.59005776435089,
42.06,42.06,1,1,1,1,6.31319902535677,20.8397507667542,5.61153451145973,
42.252,42.252,1,1,1,1,6.33743451236486,20.8403706550598,5.64209977544012,
42.444,42.444,1,1,1,1,6.36812855681777,20.8455920219421,5.67702809972348,
42.636,42.636,1,1,1,1,6.39359943596721,20.8477258682251,5.69973031841469,
42.828,42.828,1,1,1,1,6.42145934550762,20.8494663238525,5.73371927343063,
43.02,43.02,1,1,1,1,6.44829278951883,20.8538174629211,5.75857679622779,
43.212,43.212,1,1,1,1,6.48212981691956,20.8674669265747,5.782638000915,
43.404,43.404,1,1,1,1,6.50919035507441,20.8681225776672,5.81318895977964,
43.596,43.596,1,1,1,1,6.53999340471625,20.8799719810486,5.84063094015517,
43.788,43.788,1,1,1,1,6.5690069525063,20.8853125572205,5.86204093005719,
43.98,43.98,1,1,1,1,6.59260657591224,20.8798885345459,5.90560000750818,
44.172,44.172,1,1,1,1,6.62164737499952,20.8881020545959,5.92537444584308,
44.364,44.364,1,1,1,1,6.65384932456613,20.8985447883606,5.95618766516309,
44.557,44.557,1,1,1,1,6.68749559288621,20.9102869033813,5.97164672691417,
44.749,44.749,1,1,1,1,6.71016867218614,20.9103345870972,6.00164932300849,
44.941,44.941,1,1,1,1,6.7451593378365,20.9264397621155,6.02376026358213,
45.133,45.133,1,1,1,1,6.76866812358499,20.9192276000977,6.05577034425302,
45.33,45.33,1,1,1,1,6.79826303238273,20.9314703941345,6.07881588572216,
45.522,45.522,1,1,1,1,6.82807595155835,20.9371089935303,6.11706299685893,
45.714,45.714,1,1,1,1,6.85693507533073,20.9399342536926,6.14247365079832,
45.906,45.906,1,1,1,1,6.89167139554024,20.950448513031,6.16322560537596,
46.102,46.102,1,1,1,1,6.91528918647766,20.9434747695923,6.20354218992419,
46.294,46.294,1,1,1,1,6.94710053411722,20.9582567214966,6.21927304887447,
46.486,46.486,1,1,1,1,6.97848494476676,20.9680914878845,6.25327154063425,
46.685,46.685,1,1,1,1,7.0013215318501,20.9564208984375,6.28883882675433,
46.877,46.877,1,1,1,1,7.03608510335684,20.9756731987,6.30940958319917,
47.069,47.069,1,1,1,1,7.06094737020135,20.9691643714905,6.3381199505043,
47.261,47.261,1,1,1,1,7.08975199137926,20.9692239761353,6.3605169933929,
47.461,47.461,1,1,1,1,7.11894721448421,20.980429649353,6.39606520602531,
47.653,47.653,1,1,1,1,7.15094932120442,20.992374420166,6.41481921277022,
47.845,47.845,1,1,1,1,7.17533014846444,20.9913492202759,6.4414934852673,
48.037,48.037,1,1,1,1,7.20428919366002,20.9922194480896,6.47999808848753,
48.229,48.229,1,1,1,1,7.23620954648852,21.001672744751,6.5001587649476,
48.421,48.421,1,1,1,1,7.26411487485766,21.0012435913086,6.53440044367509,
48.613,48.613,1,1,1,1,7.29069397342801,21.0082650184631,6.56081722408872,
48.805,48.805,1,1,1,1,7.32014354197383,21.0106492042542,6.58656643243413,
48.997,48.997,1,1,1,1,7.34922975988984,21.0098624229431,6.61971615399289,
49.189,49.189,1,1,1,1,7.37744393629432,21.0246205329895,6.64454983493047,
49.381,49.381,1,1,1,1,7.40813798074722,21.0263729095459,6.6659026043695,
49.574,49.574,1,1,1,1,7.4344627338767,21.0218906402588,6.70638131356287,
49.766,49.766,1,1,1,1,7.46534753741026,21.0307598114014,6.73550176085277,
49.958,49.958,1,1,1,1,7.49539663449526,21.0352301597595,6.74213456618767,
50.15,50.15,1,1,1,1,7.52558198806643,21.0442423820496,6.77964257967749,
50.342,50.342,1,1,1,1,7.55219742169976,21.0471749305725,6.81262063984728,
50.534,50.534,1,1,1,1,7.58083853509426,21.0431337356567,6.83136987822027,
50.732,50.732,1,1,1,1,7.61031535493731,21.0488796234131,6.86387110119848,
50.924,50.924,1,1,1,1,7.63911997611523,21.0529923439026,6.88765574031458,
51.116,51.116,1,1,1,1,7.66694355059266,21.0541367530823,6.92163992695861,
51.308,51.308,1,1,1,1,7.69731966324449,21.0651159286499,6.94964934359212,
51.5,51.5,1,1,1,1,7.7264058811605,21.0643887519836,6.97775412766395,
51.692,51.692,1,1,1,1,7.75196759796739,21.0611581802368,7.00515319269223,
51.885,51.885,1,1,1,1,7.78335200861692,21.0757613182068,7.0342641032383,
52.077,52.077,1,1,1,1,7.81057605455518,21.0757255554199,7.06446220258117,
52.269,52.269,1,1,1,1,7.84117017758489,21.076226234436,7.08900501283188,
52.461,52.461,1,1,1,1,7.86881207674742,21.0880398750305,7.11151649664645,
52.653,52.653,1,1,1,1,7.89669923758507,21.0846543312073,7.14409878194723,
52.845,52.845,1,1,1,1,7.92289681799412,21.0826992988586,7.18402912837028,
53.037,53.037,1,1,1,1,7.95950439394712,21.1023211479187,7.18706181290874,
53.229,53.229,1,1,1,1,7.98512969711423,21.0916757583618,7.23064473221931,
53.421,53.421,1,1,1,1,8.01236282681823,21.0955023765564,7.25532105688367,
53.613,53.613,1,1,1,1,8.04407425303459,21.101450920105,7.28340676746783,
53.805,53.805,1,1,1,1,8.07113479118943,21.1028933525085,7.31163552920947,
53.997,53.997,1,1,1,1,8.10023009287119,21.1068630218506,7.34527639307556,
54.189,54.189,1,1,1,1,8.12507419218421,21.1100697517395,7.37280897251749,
54.381,54.381,1,1,1,1,8.15605891714096,21.1123108863831,7.39234022388468,
54.574,54.574,1,1,1,1,8.18535406166911,21.1168885231018,7.42434076781173,
54.773,54.773,1,1,1,1,8.21489446787238,21.1196184158325,7.45123438541694,
54.965,54.965,1,1,1,1,8.24474372211099,21.1182475090027,7.48010687736721,
55.157,55.157,1,1,1,1,8.27314865759611,21.1225509643555,7.50489287458563,
55.349,55.349,1,1,1,1,8.30158084437847,21.1265087127686,7.54155688624635,
55.541,55.541,1,1,1,1,8.32856871240735,21.1263656616211,7.56682448902826,
55.733,55.733,1,1,1,1,8.3574823387742,21.1299300193787,7.59030395234175,
55.925,55.925,1,1,1,1,8.38899392214417,21.1331009864807,7.62075000702424,
56.117,56.117,1,1,1,1,8.41762595177293,21.1398482322693,7.64718586092553,
56.309,56.309,1,1,1,1,8.45239860704541,21.1512804031372,7.67032200146108,
56.502,56.502,1,1,1,1,8.47547137203813,21.146285533905,7.70390564486418,
56.694,56.694,1,1,1,1,8.50713737942576,21.1491823196411,7.73223454241605,
56.886,56.886,1,1,1,1,8.52987404508591,21.1406469345093,7.7614026734251,
57.078,57.078,1,1,1,1,8.56042274928689,21.150016784668,7.7910667151134,
57.27,57.27,1,1,1,1,8.59173448981047,21.1477041244507,7.81264836640439,
57.462,57.462,1,1,1,1,8.61682385079861,21.1521744728088,7.84586961354189,
57.654,57.654,1,1,1,1,8.64676394269466,21.15638256073,7.87509973338585,
57.846,57.846,1,1,1,1,8.67606817098856,21.1556315422058,7.89665754281726,
58.038,58.038,1,1,1,1,8.70537239928245,21.1593985557556,7.93089922154474,
58.23,58.23,1,1,1,1,8.73509448080063,21.1617469787598,7.95692499546127,
58.422,58.422,1,1,1,1,8.76618821094632,21.1613774299622,7.98341806982555,
58.617,58.617,1,1,1,1,8.79185893294215,21.1615681648254,8.01312025848918,
58.809,58.809,1,1,1,1,8.8220987891078,21.1655974388123,8.04056700723662,
59.001,59.001,1,1,1,1,8.84632519235015,21.1674928665161,8.06996878846955,
59.194,59.194,1,1,1,1,8.8782546289444,21.169114112854,8.1044107388175,
59.386,59.386,1,1,1,1,8.91071092395186,21.1811065673828,8.11770019134688,
59.578,59.578,1,1,1,1,8.9368449180007,21.174955368042,8.15376338814621,
59.77,59.77,1,1,1,1,8.96408713147044,21.1738586425781,8.17962226904569,
59.962,59.962,1,1,1,1,8.98685104842782,21.1691856384277,8.22039184892592,
60.154,60.154,1,1,1,1,9.02330420036316,21.1779236793518,8.23267517498107,
60.346,60.346,1,1,1,1,9.05112777484059,21.1840391159058,8.26726017648649,
60.538,60.538,1,1,1,1,9.08057734338641,21.1906433105469,8.29627095122232,
60.733,60.733,1,1,1,1,9.11003599569797,21.1852669715881,8.32152901726041,
60.925,60.925,1,1,1,1,9.14370951531529,21.1959958076477,8.34672032609167,
61.117,61.117,1,1,1,1,9.16677319654226,21.1920738220215,8.38278829126291,
61.309,61.309,1,1,1,1,9.19323420615792,21.1887121200562,8.40713082989316,
61.501,61.501,1,1,1,1,9.22718932251334,21.1923003196716,8.43485414421172,
61.694,61.694,1,1,1,1,9.2526238665998,21.1962580680847,8.46466600542941,
61.886,61.886,1,1,1,1,9.27510618681907,21.1836338043213,8.49791109442649,
62.084,62.084,1,1,1,1,9.31010593623519,21.1924195289612,8.52716505613003,
62.276,62.276,1,1,1,1,9.34211712672114,21.2001919746399,8.5459095261311,
62.468,62.468,1,1,1,1,9.37227522899508,21.2023258209229,8.581600789921,
62.66,62.66,1,1,1,1,9.40537647137046,21.2045192718506,8.6038786235117,
62.852,62.852,1,1,1,1,9.42888525711894,21.2007284164429,8.63305629126458,
63.044,63.044,1,1,1,1,9.46100545279383,21.2056040763855,8.65419925233931,
63.236,63.236,1,1,1,1,9.48572237938642,21.204400062561,8.68807376642928,
63.428,63.428,1,1,1,1,9.51630741865039,21.2049603462219,8.71785701741547,
63.62,63.62,1,1,1,1,9.54825502277613,21.2044835090637,8.74167026676307,
63.812,63.812,1,1,1,1,9.57982110874057,21.2132692337036,8.77410473253446,
64.004,64.004,1,1,1,1,9.60011424141526,21.2148427963257,8.80126537896695,
64.194,64.194,1,1,1,1,9.62742004124522,21.212100982666,8.83034767928152,
64.384,64.384,1,1,1,1,9.65949481809139,21.2161540985107,8.86093678512149,
64.573,64.573,1,1,1,1,9.68541988552809,21.2068200111389,8.88784947621436,
64.763,64.763,1,1,1,1,9.71518738587499,21.2126731872559,8.91290250226006,
64.953,64.953,1,1,1,1,9.74508205894232,21.2155103683472,8.93830361945562,
65.143,65.143,1,1,1,1,9.7698989069581,21.2141036987305,8.96698060815735,
65.34,65.34,1,1,1,1,9.79288083429336,21.2029814720154,9.00699201690297,
65.53,65.53,1,1,1,1,9.82793508630395,21.2165594100952,9.02859751005354,
65.719,65.719,1,1,1,1,9.8588198898375,21.2178826332092,9.05363146261158,
65.909,65.909,1,1,1,1,9.88553524489403,21.2144255638123,9.08082548764749,
66.104,66.104,1,1,1,1,9.91436711736917,21.2193608283997,9.11089484094863,
66.293,66.293,1,1,1,1,9.94381668591499,21.2165594100952,9.13832251620841,
66.483,66.483,1,1,1,1,9.97213078374267,21.2244510650635,9.16532103799577,
66.673,66.673,1,1,1,1,9.9916063775003,21.2138295173645,9.20562808580017,
66.863,66.863,1,1,1,1,10.0299489527106,21.2212920188904,9.22180240333862,
67.052,67.052,1,1,1,1,10.0591986784101,21.2201476097107,9.24987380880704,
67.242,67.242,1,1,1,1,10.0853417562246,21.2189912796021,9.28029602162995,
67.432,67.432,1,1,1,1,10.1096499133587,21.2143540382385,9.31253975252471,
67.622,67.622,1,1,1,1,10.1466844263017,21.2295889854431,9.33028763279538,
67.811,67.811,1,1,1,1,10.1799582602263,21.2282299995422,9.35402458819232,
68.001,68.001,1,1,1,1,10.1974808443487,21.2237477302551,9.39421719507074,
68.191,68.191,1,1,1,1,10.2268123239398,21.2218046188354,9.41669053190999,
68.381,68.381,1,1,1,1,10.2577334625363,21.2233901023865,9.44338864626665,
68.57,68.57,1,1,1,1,10.2810333216727,21.2259650230408,9.47462625068717,
68.763,68.763,1,1,1,1,10.3145342497408,21.2249279022217,9.50266427755217,
68.953,68.953,1,1,1,1,10.343402457279,21.2294936180115,9.52725477152205,
69.143,69.143,1,1,1,1,10.3714622096658,21.2288856506348,9.55997533960838,
69.332,69.332,1,1,1,1,10.4074430057824,21.2385535240173,9.58216257413268,
69.522,69.522,1,1,1,1,10.4346488841891,21.2283611297607,9.60786886713085,
69.712,69.712,1,1,1,1,10.4573492147863,21.2257385253906,9.64158602494759,
69.902,69.902,1,1,1,1,10.4857995691001,21.2311267852783,9.67256136891274,
70.097,70.097,1,1,1,1,10.5144134311974,21.2245941162109,9.69957896418777,
70.287,70.287,1,1,1,1,10.5449530516326,21.2283968925476,9.72589560879116,
70.477,70.477,1,1,1,1,10.5656731212974,21.21502161026,9.76131507538185,
70.667,70.667,1,1,1,1,10.596448919642,21.2270855903625,9.78680679164381,
70.857,70.857,1,1,1,1,10.6328566527486,21.2343454360962,9.80527946444569,
71.046,71.046,1,1,1,1,10.6579823487997,21.226966381073,9.84048912267208,
71.236,71.236,1,1,1,1,10.6857514206827,21.22403383255,9.86605713288469,
71.429,71.429,1,1,1,1,10.7175900196195,21.2296962738037,9.88961289014883,
71.619,71.619,1,1,1,1,10.7394183087051,21.2210893630981,9.9257809911303,
71.808,71.808,1,1,1,1,10.7712205725789,21.2306380271912,9.94896958375692,
72.001,72.001,1,1,1,1,10.7999525236309,21.2340593338013,9.98267243645792,
72.18,72.18,1,1,1,1,10.8280849461436,21.231997013092,10.0107962940174,
72.37,72.37,1,1,1,1,10.8565625517547,21.2261319160461,10.034213768496,
72.56,72.56,1,1,1,1,10.8843861262321,21.2220072746277,10.0616176018962,
72.75,72.75,1,1,1,1,10.9159340446651,21.2278962135315,10.0884683041542,
72.939,72.939,1,1,1,1,10.9446478281856,21.2351560592651,10.1131398604466,
73.129,73.129,1,1,1,1,10.9695555138588,21.22962474823,10.1462180564266,
73.319,73.319,1,1,1,1,10.9984782239914,21.2261438369751,10.1744325130525,
73.509,73.509,1,1,1,1,11.0262018770456,21.2301731109619,10.1987369047074,
73.698,73.698,1,1,1,1,11.0564417332113,21.2321519851685,10.2275235659632,
73.888,73.888,1,1,1,1,11.0828391564667,21.2316870689392,10.2622993023453,
74.078,74.078,1,1,1,1,11.112452232796,21.2214231491089,10.2881915618482,
74.268,74.268,1,1,1,1,11.1416565396667,21.2294697761536,10.3157098361743,
74.457,74.457,1,1,1,1,11.1740310807824,21.2280988693237,10.3399951543416,
74.65,74.65,1,1,1,1,11.1978305470347,21.2246775627136,10.3717095959537,
74.84,74.84,1,1,1,1,11.2270530214369,21.220600605011,10.3989465363369,
75.03,75.03,1,1,1,1,11.2524966492891,21.2199807167053,10.4294736533419,
75.219,75.219,1,1,1,1,11.2879869220555,21.2245345115662,10.4490907354036,
75.409,75.409,1,1,1,1,11.3038380932808,21.2067723274231,10.4912383747675,
75.599,75.599,1,1,1,1,11.339510041362,21.2196946144104,10.512958308844,
75.789,75.789,1,1,1,1,11.3723024357021,21.2307095527649,10.5345876438542,
75.978,75.978,1,1,1,1,11.3962563259721,21.2169766426086,10.5673558956597,
76.168,76.168,1,1,1,1,11.42591482113,21.2242364883423,10.5965526369002,
76.358,76.358,1,1,1,1,11.4545559345245,21.2218761444092,10.6228311345283,
76.548,76.548,1,1,1,1,11.4807262636363,21.2130188941956,10.6504781548962,
76.738,76.738,1,1,1,1,11.5039262013495,21.2061524391174,10.6823594895254,
76.927,76.927,1,1,1,1,11.5380720767856,21.2212920188904,10.7073076113889,
77.117,77.117,1,1,1,1,11.5667041064143,21.2163925170898,10.7337100866868,
77.307,77.307,1,1,1,1,11.5956359003127,21.2203741073608,10.7659728910692,
77.497,77.497,1,1,1,1,11.6254669870198,21.2185025215149,10.7910068436273,
77.686,77.686,1,1,1,1,11.6537992523789,21.2170362472534,10.8195503179153,
77.876,77.876,1,1,1,1,11.6820951826751,21.214771270752,10.8489950144955,
78.072,78.072,1,1,1,1,11.7068575280964,21.210241317749,10.8773572906508,
78.262,78.262,1,1,1,1,11.7390503938973,21.2088108062744,10.9016569139338,
78.451,78.451,1,1,1,1,11.7686634702265,21.2088942527771,10.9348686243275,
78.65,78.65,1,1,1,1,11.8026912567079,21.2148189544678,10.9608610196406,
78.84,78.84,1,1,1,1,11.8260547022045,21.2090015411377,10.9912355487443,
79.03,79.03,1,1,1,1,11.8558857889116,21.2062001228333,11.0187061393514,
79.219,79.219,1,1,1,1,11.88189261024,21.2108492851257,11.0499675856315,
79.415,79.415,1,1,1,1,11.9106427288234,21.2073922157288,11.0765083437149,
79.605,79.605,1,1,1,1,11.9403466428101,21.199643611908,11.1032064580716,
79.795,79.795,1,1,1,1,11.9661627050579,21.2006211280823,11.1399181534514,
79.989,79.989,1,1,1,1,11.9986008325338,21.1997509002686,11.1638315386093,
80.179,80.179,1,1,1,1,12.0265697472632,21.2048053741455,11.1942251412007,
80.369,80.369,1,1,1,1,12.0546930860102,21.2016224861145,11.2163122399147,
80.558,80.558,1,1,1,1,12.0764214536726,21.1888790130615,11.252094102771,
80.748,80.748,1,1,1,1,12.1112940303683,21.1851596832275,11.2748726154129,
80.938,80.938,1,1,1,1,12.140607342428,21.1921215057373,11.3028677269307,
81.128,81.128,1,1,1,1,12.1596287478983,21.1863040924072,11.3373382875101,
81.322,81.322,1,1,1,1,12.1906043890893,21.1838126182556,11.3659628241208,
81.512,81.512,1,1,1,1,12.2267941118181,21.1911916732788,11.3890989646563,
81.701,81.701,1,1,1,1,12.2485497307777,21.1783528327942,11.4232500443174,
81.891,81.891,1,1,1,1,12.2850483015418,21.1862087249756,11.4449795151378,
82.081,82.081,1,1,1,1,12.3151064823925,21.1900115013123,11.4675291459277,
82.271,82.271,1,1,1,1,12.3469814163923,21.1891770362854,11.4967258871682,
82.46,82.46,1,1,1,1,12.3701450190425,21.1809635162354,11.5292223417745,
82.65,82.65,1,1,1,1,12.3984954519331,21.17520570755,11.5571983798046,
82.84,82.84,1,1,1,1,12.434503499347,21.1885452270508,11.5842350485673,
83.03,83.03,1,1,1,1,12.4496915556729,21.1679339408875,11.6150291943996,
83.219,83.219,1,1,1,1,12.4833105726957,21.1697220802307,11.6413982910941,
83.409,83.409,1,1,1,1,12.5098260849059,21.1728811264038,11.6699322286384,
83.599,83.599,1,1,1,1,12.5397570930362,21.168839931488,11.6997154796246,
83.789,83.789,1,1,1,1,12.5736032042026,21.1756229400635,11.7258699995828,
83.978,83.978,1,1,1,1,12.60349787727,21.1728453636169,11.750160086122,
84.168,84.168,1,1,1,1,12.6247720566452,21.1634516716003,11.7860039378132,
84.358,84.358,1,1,1,1,12.6533495836794,21.16779088974,11.8088778178934,
84.548,84.548,1,1,1,1,12.682880906117,21.1625933647156,11.8413742724997,
84.738,84.738,1,1,1,1,12.7103320461988,21.1541652679443,11.8661507329742,
84.927,84.927,1,1,1,1,12.7435241262317,21.158754825592,11.8944462519227,
85.117,85.117,1,1,1,1,12.7705574130893,21.1593151092529,11.9244536163889,
85.307,85.307,1,1,1,1,12.8024777659178,21.1610913276672,11.9492300768635,
85.497,85.497,1,1,1,1,12.824106212157,21.1484909057617,11.980186347341,
85.686,85.686,1,1,1,1,12.8574617999732,21.1604475975037,12.0069464505326,
85.876,85.876,1,1,1,1,12.8825602447271,21.1420655250549,12.0380076251922,
86.066,86.066,1,1,1,1,12.9097207043052,21.1445927619934,12.0678910119886,
86.256,86.256,1,1,1,1,12.9383890689969,21.1446762084961,12.0938261868388,
86.445,86.445,1,1,1,1,12.966794004482,21.1380958557129,12.1271380330427,
86.635,86.635,1,1,1,1,12.9940907205462,21.1397290229797,12.1496781270887,
86.825,86.825,1,1,1,1,13.0268286122918,21.1323738098145,12.1801289501431,
87.015,87.015,1,1,1,1,13.0524357479274,21.1308836936951,12.2119053805902,
87.204,87.204,1,1,1,1,13.0802229873419,21.1237788200378,12.2370156270988,
87.394,87.394,1,1,1,1,13.1075287871718,21.1248397827148,12.2676428799141,
87.584,87.584,1,1,1,1,13.1404120191693,21.1314678192139,12.2945126556598,
87.774,87.774,1,1,1,1,13.1665187619209,21.1166262626648,12.3223170323009,
87.963,87.963,1,1,1,1,13.195995581764,21.1159944534302,12.3533400599852,
88.153,88.153,1,1,1,1,13.2235284757376,21.1058735847473,12.3807486617573,
88.343,88.343,1,1,1,1,13.2516699820161,21.1065649986267,12.4060114961673,
88.533,88.533,1,1,1,1,13.2868059879184,21.1151480674744,12.4342545630247,
88.722,88.722,1,1,1,1,13.3040651428342,21.1042761802673,12.4660643720751,
88.912,88.912,1,1,1,1,13.3373117254615,21.1016893386841,12.4928435487544,
89.102,89.102,1,1,1,1,13.3746823377371,21.1095213890076,12.5170001208799,
89.292,89.292,1,1,1,1,13.394112512666,21.0960388183594,12.5473460397521,
89.481,89.481,1,1,1,1,13.4154321108699,21.0879683494568,12.5850733983501,
89.671,89.671,1,1,1,1,13.4493327246308,21.0869193077087,12.6058539631592,
89.861,89.861,1,1,1,1,13.4745583421051,21.0798859596252,12.6354417108969,
90.051,90.051,1,1,1,1,13.5083953695059,21.0844039916992,12.6608332913486,
90.241,90.241,1,1,1,1,13.5365368757844,21.0825562477112,12.6915463748584,
90.43,90.43,1,1,1,1,13.5647510521889,21.0688829421997,12.7205476128504,
90.62,90.62,1,1,1,1,13.6034842293262,21.0831522941589,12.7438840250064,
90.81,90.81,1,1,1,1,13.6313713901639,21.0730195045471,12.7741679550437,
91,91,1,1,1,1,13.6514737637579,21.0606336593628,12.8059968375818,
91.189,91.189,1,1,1,1,13.6795516836762,21.062159538269,12.8355321332284,
91.379,91.379,1,1,1,1,13.7075841847658,21.0561633110046,12.861553138773,
91.569,91.569,1,1,1,1,13.7352533352256,21.0507273674011,12.8916272604461,
91.759,91.759,1,1,1,1,13.7647483226001,21.047830581665,12.9188737375731,
91.948,91.948,1,1,1,1,13.7946611631989,21.0485577583313,12.9475125792994,
92.138,92.138,1,1,1,1,13.8193054196656,21.0411787033081,12.9782685781565,
92.328,92.328,1,1,1,1,13.8513529452145,21.0327625274658,13.0054626031924,
92.518,92.518,1,1,1,1,13.8772325938225,21.029007434845,13.0356559341633,
92.716,92.716,1,1,1,1,13.9070364292324,21.0240721702576,13.0624589527021,
92.906,92.906,1,1,1,1,13.9291644825876,21.0146903991699,13.0941114054793,
93.096,93.096,1,1,1,1,13.9703593602419,21.0139870643616,13.117352450197,
93.286,93.286,1,1,1,1,13.9944495069981,21.0180163383484,13.1493959094713,
93.475,93.475,1,1,1,1,14.0267332104564,21.0073351860046,13.1737241429858,
93.665,93.665,1,1,1,1,14.0563190354884,21.0023522377014,13.203226060029,
93.855,93.855,1,1,1,1,14.0779838167906,20.9931373596191,13.2349214281534,
94.045,94.045,1,1,1,1,14.1067975217342,20.9863901138306,13.2613000615917,
94.234,94.234,1,1,1,1,14.1376096551418,20.9814667701721,13.2902440791207,
94.424,94.424,1,1,1,1,14.1638889894426,20.9719657897949,13.3201846863801,
94.614,94.614,1,1,1,1,14.1928571184039,20.9724545478821,13.3484420583533,
94.804,94.804,1,1,1,1,14.2104432888865,20.9585785865784,13.3812293836464,
94.994,94.994,1,1,1,1,14.2440532221436,20.949375629425,13.4060821380717,
95.183,95.183,1,1,1,1,14.2798250916481,20.9520936012268,13.4355459081395,
95.373,95.373,1,1,1,1,14.3071581427753,20.9453225135803,13.4642705805604,
95.563,95.563,1,1,1,1,14.3289955156267,20.9354281425476,13.4937963394631,
95.753,95.753,1,1,1,1,14.3644040345013,20.9301590919495,13.5197696612886,
95.942,95.942,1,1,1,1,14.3936900952637,20.9198236465454,13.5496053643659,
96.132,96.132,1,1,1,1,14.4197877542496,20.9098815917969,13.5760984387301,
96.322,96.322,1,1,1,1,14.4392724317729,20.8949089050293,13.6110744467327,
96.512,96.512,1,1,1,1,14.4855360507131,20.9005355834961,13.6306629185628,
96.701,96.701,1,1,1,1,14.506746643728,20.8891868591309,13.6645040540494,
96.891,96.891,1,1,1,1,14.5340796948552,20.8800554275513,13.6916122483908,
97.081,97.081,1,1,1,1,14.5623211225569,20.8666801452637,13.7193260259655,
97.271,97.271,1,1,1,1,14.5892635717571,20.8616733551025,13.7496719448378,
97.46,97.46,1,1,1,1,14.6200757051647,20.8561182022095,13.7742767439234,
97.65,97.65,1,1,1,1,14.6472543322742,20.8446383476257,13.8050279744085,
97.84,97.84,1,1,1,1,14.6732248185396,20.8316445350647,13.8344392923853,
98.03,98.03,1,1,1,1,14.7058900401592,20.8229422569275,13.8599500821349,
98.219,98.219,1,1,1,1,14.7331776724577,20.8184361457825,13.8882456010834,
98.409,98.409,1,1,1,1,14.7529893655479,20.7941055297852,13.92129041846,
98.599,98.599,1,1,1,1,14.7906143232644,20.7932829856873,13.9468441235569,
98.789,98.789,1,1,1,1,14.8188375834346,20.7800388336182,13.9770136126682,
98.978,98.978,1,1,1,1,14.8445718917906,20.7691669464111,14.0043077735144,
99.168,99.168,1,1,1,1,14.8771916945815,20.7564115524292,14.0348968793543,
99.362,99.362,1,1,1,1,14.9060599021196,20.7465529441834,14.0607700653696,
99.552,99.552,1,1,1,1,14.9342104921639,20.730447769165,14.0910539954069,
99.742,99.742,1,1,1,1,14.961761553669,20.7158327102661,14.1187820780974,
99.932,99.932,1,1,1,1,14.9851340829313,20.7007765769959,14.1496096025331,
100.122,100.122,1,1,1,1,15.0148924995124,20.6918358802795,14.1796360404871,
100.311,100.311,1,1,1,1,15.0540707811713,20.6861853599548,14.2020998405825,
100.501,100.501,1,1,1,1,15.0754176306725,20.6589460372925,14.234868092388,
100.691,100.691,1,1,1,1,15.1047672777951,20.6437706947327,14.2644081564065,
100.881,100.881,1,1,1,1,15.1260959597647,20.6201553344727,14.2937098018291,
101.07,101.07,1,1,1,1,15.1561087217867,20.6084728240967,14.3224058640185,
101.26,101.26,1,1,1,1,15.1884560116053,20.6016898155212,14.3467674761364,
101.45,101.45,1,1,1,1,15.2164612613976,20.5795764923096,14.3758354713353,
101.64,101.64,1,1,1,1,15.2473278973997,20.5642342567444,14.4056902479002,
101.829,101.829,1,1,1,1,15.2871511264265,20.552670955658,14.4274674024397,
102.022,102.022,1,1,1,1,15.3052187364936,20.5232739448547,14.4605026830725,
102.212,102.212,1,1,1,1,15.3337962635279,20.5038547515869,14.4895229945522,
102.402,102.402,1,1,1,1,15.3623556230307,20.483386516571,14.5189247757851,
102.594,102.594,1,1,1,1,15.3915326786041,20.4642295837402,14.5486412695645,
102.784,102.784,1,1,1,1,15.4171488980055,20.4499244689941,14.576369352255,
102.974,102.974,1,1,1,1,15.4465076288939,20.4253673553467,14.6060381623152,
103.164,103.164,1,1,1,1,15.475802773422,20.4040288925171,14.6348915807778,
103.353,103.353,1,1,1,1,15.5037081017911,20.3792810440063,14.6621714365082,
103.543,103.543,1,1,1,1,15.5426683730721,20.366358757019,14.686366155609,
103.733,103.733,1,1,1,1,15.552333499825,20.3325510025024,14.7253428276489,
103.923,103.923,1,1,1,1,15.5897586146951,20.307457447052,14.7494088007081,
104.112,104.112,1,1,1,1,15.6079988163114,20.2794432640076,14.7806607102443,
104.302,104.302,1,1,1,1,15.6422991157651,20.2559590339661,14.8093472356899,
104.492,104.492,1,1,1,1,15.6766357502818,20.2341794967651,14.8349724663655,
104.682,104.682,1,1,1,1,15.7106544529974,20.2183961868286,14.8599062831133,
104.872,104.872,1,1,1,1,15.7268871423841,20.1756119728088,14.8933802539623,
105.061,105.061,1,1,1,1,15.7600156360567,20.1564908027649,14.9209652854953,
105.259,105.259,1,1,1,1,15.7894379533052,20.129120349884,14.9492798779315,
105.448,105.448,1,1,1,1,15.8187876004279,20.1020002365112,14.9820481297369,
105.638,105.638,1,1,1,1,15.8477557293892,20.0699210166931,15.0080309883062,
105.828,105.828,1,1,1,1,15.8756065551639,20.0449705123901,15.0345335994143,
106.018,106.018,1,1,1,1,15.9040024068832,20.0066328048706,15.0675450381876,
106.207,106.207,1,1,1,1,15.9435985417664,19.9849128723145,15.090628726632,
106.397,106.397,1,1,1,1,15.9610938745916,19.9497938156128,15.1247988797808,
106.559,106.559,1,1,1,1,15.9848297544837,19.917893409729,15.1488553160961,
106.716,0.156000000000006,1,1,1,1,15.9980557174087,19.8819398880005,15.1746474397887,
106.906,0.346000000000004,1,1,1,1,16.0387237366498,19.8623895645142,15.2025090368928,
107.096,0.536000000000001,1,1,1,1,16.0667017351449,19.8184728622437,15.2305899791051,
107.286,0.725999999999999,1,1,1,1,16.0948614089549,19.78999376297,15.258632774342,
107.475,0.915000000000006,1,1,1,1,16.1208863978148,19.7431087493896,15.291315195453,
107.665,1.105,1,1,1,1,16.1506084793329,19.713282585144,15.3175364726181,
107.855,1.295,1,1,1,1,16.1794948544025,19.6781396865845,15.3465043320067,
108.045,1.485,1,1,1,1,16.2063828010082,19.6417927742004,15.3748236928147,
108.234,1.67400000000001,1,1,1,1,16.2307999633312,19.5960760116577,15.4054652507458,
108.424,1.864,1,1,1,1,16.2638194518149,19.5515871047974,15.4352580384758,
108.614,2.054,1,1,1,1,16.2931327638745,19.5159196853638,15.4621945714283,
108.804,2.244,1,1,1,1,16.322237149322,19.4669365882874,15.4892550820505,
108.993,2.43300000000001,1,1,1,1,16.3478624524891,19.4310665130615,15.5188809767635,
109.183,2.623,1,1,1,1,16.3634047756791,19.3833470344543,15.5512296118404,
109.373,2.813,1,1,1,1,16.4096956459165,19.3554043769836,15.5747424537573,
109.563,3.003,1,1,1,1,16.4341218920052,19.3031191825867,15.6076728302079,
109.753,3.193,1,1,1,1,16.4635623767853,19.2537069320679,15.6345235324659,
109.942,3.38200000000001,1,1,1,1,16.4891240935922,19.2009568214417,15.6677972316945,
110.132,3.572,1,1,1,1,16.5340160639048,19.1580533981323,15.6893645778697,
110.322,3.762,1,1,1,1,16.5499217377245,19.0967798233032,15.7205401934553,
110.512,3.952,1,1,1,1,16.5775545531213,19.0543413162231,15.7496415672575,
110.709,4.149,1,1,1,1,16.6028165056586,19.004237651825,15.7802831251886,
110.899,4.339,1,1,1,1,16.6326385086,18.9496636390686,15.8086263278562,
111.088,4.52800000000001,1,1,1,1,16.6614976323724,18.9008355140686,15.8391391397455,
111.28,4.72,1,1,1,1,16.7042367502034,18.8449263572693,15.8647786755369,
111.469,4.90900000000001,1,1,1,1,16.727382185322,18.7838435173035,15.8979283970956,
111.659,5.099,1,1,1,1,16.750482201612,18.7299966812134,15.9303580944951,
111.849,5.289,1,1,1,1,16.7789234721601,18.6536192893982,15.9583341325252,
112.045,5.485,1,1,1,1,16.8074283290684,18.5842752456665,15.9871255621529,
112.234,5.67400000000001,1,1,1,1,16.8327902030289,18.5233473777771,16.0148441080996,
112.424,5.864,1,1,1,1,16.8598144061208,18.4621691703796,16.0448514725658,
112.614,6.054,1,1,1,1,16.8894910688102,18.4110283851624,16.0728561208274,
112.804,6.244,1,1,1,1,16.9213387515128,18.3348178863525,16.1037122554946,
112.993,6.43300000000001,1,1,1,1,16.9441662548304,18.2578921318054,16.1364518970686,
113.183,6.623,1,1,1,1,16.9803559775591,18.187153339386,16.1663686624685,
113.374,6.81400000000001,1,1,1,1,17.0095421168983,18.095588684082,16.1976825608396,
113.564,7.004,1,1,1,1,17.0370295920432,18.0060148239136,16.230627242406,
113.754,7.194,1,1,1,1,17.0651256794929,17.9096460342407,16.2558948451879,
113.947,7.387,1,1,1,1,17.0921862176478,17.8389668464661,16.2846719696999,
114.137,7.577,1,1,1,1,17.1221081420124,17.7520394325256,16.3105737659466,
114.326,7.76600000000001,1,1,1,1,17.1408297832131,17.6518678665161,16.3430988307844,
114.516,7.956,1,1,1,1,17.1787000026047,17.5545930862427,16.3703834548867,
114.709,8.149,1,1,1,1,17.2054335251927,17.4275875091553,16.4055835763693,
114.899,8.339,1,1,1,1,17.2483724858701,17.308235168457,16.4361536087216,
115.088,8.52800000000001,1,1,1,1,17.2635877934933,17.1498894691467,16.4720785227354,
115.28,8.72,1,1,1,1,17.292792100364,16.9982075691223,16.4981042966519,
115.469,8.90900000000001,1,1,1,1,17.3200888164282,16.907262802124,16.5229951980525,
115.659,9.099,1,1,1,1,17.3416627600729,16.7503237724304,16.5525543355586,
115.849,9.289,1,1,1,1,17.3716573545635,16.552996635437,16.5850937055121,
116.039,9.479,1,1,1,1,17.3992084160686,16.2472486495972,16.6234457208311,
116.228,9.66800000000001,1,1,1,1,17.4412390001714,15.6376719474792,16.666723464339,
116.418,9.858,1,1,1,1,17.4516671632469,14.9569630622864,16.6923153164112,
116.606,10.046,1,1,1,1,17.5009011735857,0.167238712310791,17.0493948473272,
116.796,10.236,1,1,1,1,17.5201496731997,-0.183820724487305,16.817737802913,
116.986,10.426,1,1,1,1,17.5513433247685,-0.181043148040771,16.8718445190417,
117.182,10.622,1,1,1,1,17.5810109036922,-0.179541110992432,16.8775236499935,
117.371,10.811,1,1,1,1,17.6101607079685,-0.180524587631226,16.9031631857848,
117.561,11.001,1,1,1,1,17.6382386278868,-0.182658433914185,16.9403040346371,
117.751,11.191,1,1,1,1,17.6585953469217,-0.175142288208008,16.9783079588062,
117.945,11.385,1,1,1,1,17.6934860911489,-0.169473886489868,16.9944107507659,
118.135,11.575,1,1,1,1,17.7319285877824,-0.172358751296997,17.0236599440975,
118.325,11.765,1,1,1,1,17.7513496789455,-0.176668167114258,17.0576822777169,
118.515,11.955,1,1,1,1,17.7777925210297,-0.176507234573364,17.0854580441265,
118.704,12.144,1,1,1,1,17.8112934490979,-0.170409679412842,17.1091234739447,
118.894,12.334,1,1,1,1,17.8354290146828,-0.174146890640259,17.1401274281414,
119.084,12.524,1,1,1,1,17.8644970650673,-0.178223848342896,17.1726286511196,
119.28,12.72,1,1,1,1,17.8930655083358,-0.172770023345947,17.1973669646188,
119.469,12.909,1,1,1,1,17.9139218344867,-0.176441669464111,17.2275889058213,
119.659,13.099,1,1,1,1,17.9559705861211,-0.179243087768555,17.2535336174152,
119.849,13.289,1,1,1,1,17.9921330575526,-0.170671939849854,17.2835171400219,
120.039,13.479,1,1,1,1,18.0052954341173,-0.172227621078491,17.3084795670012,
120.228,13.668,1,1,1,1,18.0357896357238,-0.177574157714844,17.3410809257896,
120.418,13.858,1,1,1,1,18.0640128958941,-0.171089172363281,17.3712456465291,
120.608,14.048,1,1,1,1,18.0915548736334,-0.172817707061768,17.3991024752613,
120.798,14.238,1,1,1,1,18.1140735289156,-0.171250104904175,17.4262774268095,
120.987,14.427,1,1,1,1,18.1380455867171,-0.170552730560303,17.4578202070327,
121.177,14.617,1,1,1,1,18.1759158061087,-0.170403718948364,17.4827683288962,
121.376,14.816,1,1,1,1,18.2063191700578,-0.173527002334595,17.5103962757765,
121.566,15.006,1,1,1,1,18.235932246387,-0.170153379440308,17.5390017388995,
121.756,15.196,1,1,1,1,18.2634378890634,-0.164252519607544,17.5683606047852,
121.945,15.385,1,1,1,1,18.2929056251407,-0.17554759979248,17.5962794223523,
122.135,15.575,1,1,1,1,18.3202205087364,-0.174331665039063,17.6261675775206,
122.325,15.765,1,1,1,1,18.3539031121194,-0.167810916900635,17.6515114742532,
122.515,15.955,1,1,1,1,18.3783021069109,-0.172054767608643,17.6838028888671,
122.706,16.146,1,1,1,1,18.4066979586303,-0.167179107666016,17.712527561288,
122.896,16.336,1,1,1,1,18.442460744369,-0.174033641815186,17.7379620570869,
123.085,16.525,1,1,1,1,18.4651065723717,-0.167125463485718,17.7668917695002,
123.275,16.715,1,1,1,1,18.4927030527055,-0.168806314468384,17.7974141181334,
123.465,16.905,1,1,1,1,18.5092809251904,-0.166541337966919,17.8257668575448,
123.655,17.095,1,1,1,1,18.5476235004008,-0.166237354278564,17.8523505309755,
123.844,17.284,1,1,1,1,18.5758285930395,-0.169098377227783,17.8809893727019,
124.034,17.474,1,1,1,1,18.6163512720287,-0.167536735534668,17.9052174704062,
124.224,17.664,1,1,1,1,18.6215290185034,-0.167375802993774,17.938076321278,
124.414,17.854,1,1,1,1,18.6497431949079,-0.171679258346558,17.9671252429892,
124.603,18.043,1,1,1,1,18.683816400218,-0.169777870178223,17.9947007377784,
124.793,18.233,1,1,1,1,18.7185890554905,-0.169187784194946,18.023158381372,
124.983,18.423,1,1,1,1,18.7461128656983,-0.17085075378418,18.0522406816865,
125.173,18.613,1,1,1,1,18.7909230821192,-0.164377689361572,18.0755723254706,
125.365,18.805,1,1,1,1,18.8048848300695,-0.165212154388428,18.1110347074086,
125.555,18.995,1,1,1,1,18.8378952347875,-0.166469812393188,18.1392634691502,
125.745,19.185,1,1,1,1,18.8634842028916,-0.16668438911438,18.1666673025504,
125.936,19.376,1,1,1,1,18.8909989293337,-0.163251161575317,18.1933844903947,
126.126,19.566,1,1,1,1,18.9156341020346,-0.169277191162109,18.2221186995594,
126.316,19.756,1,1,1,1,18.9469640100896,-0.167685747146606,18.2523454091338,
126.505,19.945,1,1,1,1,18.9764317461669,-0.176244974136353,18.28088411505,
126.7,20.14,1,1,1,1,19.0053453725338,-0.166469812393188,18.3089030684273,
126.89,20.33,1,1,1,1,19.0331871145427,-0.170761346817017,18.338261934313,
127.079,20.519,1,1,1,1,19.0637358187437,-0.169169902801514,18.3665765267491,
127.272,20.712,1,1,1,1,19.0849554955244,-0.171869993209839,18.3935655117927,
127.433,20.873,1,1,1,1,19.0861182175398,-0.172442197799683,18.389016484985,